2024-09-11 08:29:19,703 - 2024-09-11 08:29:19,703 - ERROR - Traceback (most recent call last):
  File "/home/donkami/.local/lib/python3.10/site-packages/mysql/connector/connection_cext.py", line 611, in cmd_query
    self._cmysql.query(
_mysql_connector.MySQLInterfaceError: Duplicate entry '17533' for key 'interfaces.id_prtg'

The above exception was the direct cause of the following exception:

Traceback (most recent call last):
  File "/home/donkami/Sona/devnet-candelaria/Services/InfraGeneral/db_update_devnet.py", line 38, in update_interfaces
    devnet_cursor.executemany(query, data_tuple)
  File "/home/donkami/.local/lib/python3.10/site-packages/mysql/connector/cursor_cext.py", line 465, in executemany
    self.execute(operation, params)
  File "/home/donkami/.local/lib/python3.10/site-packages/mysql/connector/cursor_cext.py", line 330, in execute
    result = self._cnx.cmd_query(
  File "/home/donkami/.local/lib/python3.10/site-packages/mysql/connector/connection_cext.py", line 619, in cmd_query
    raise get_mysql_exception(
mysql.connector.errors.IntegrityError: 1062 (23000): Duplicate entry '17533' for key 'interfaces.id_prtg'

2024-09-11 08:29:19,704 - 2024-09-11 08:29:19,704 - ERROR - 1062 (23000): Duplicate entry '17533' for key 'interfaces.id_prtg'
2024-09-11 08:29:19,704 - 2024-09-11 08:29:19,704 - ERROR - Error en la función `update_devnet_data` en el archivo `db_update_devnet`
2024-09-11 08:29:19,753 - 2024-09-11 08:29:19,753 - ERROR - Traceback (most recent call last):
  File "/home/donkami/.local/lib/python3.10/site-packages/mysql/connector/connection_cext.py", line 611, in cmd_query
    self._cmysql.query(
_mysql_connector.MySQLInterfaceError: Duplicate entry 'Not Found' for key 'system_health.id_prtg'

The above exception was the direct cause of the following exception:

Traceback (most recent call last):
  File "/home/donkami/Sona/devnet-candelaria/Services/InfraGeneral/db_update_devnet.py", line 87, in update_sysHealth
    devnet_cursor.executemany(query, data_tuple)
  File "/home/donkami/.local/lib/python3.10/site-packages/mysql/connector/cursor_cext.py", line 465, in executemany
    self.execute(operation, params)
  File "/home/donkami/.local/lib/python3.10/site-packages/mysql/connector/cursor_cext.py", line 330, in execute
    result = self._cnx.cmd_query(
  File "/home/donkami/.local/lib/python3.10/site-packages/mysql/connector/connection_cext.py", line 619, in cmd_query
    raise get_mysql_exception(
mysql.connector.errors.IntegrityError: 1062 (23000): Duplicate entry 'Not Found' for key 'system_health.id_prtg'

2024-09-11 08:29:19,753 - 2024-09-11 08:29:19,753 - ERROR - 1062 (23000): Duplicate entry 'Not Found' for key 'system_health.id_prtg'
2024-09-11 08:29:19,754 - 2024-09-11 08:29:19,754 - ERROR - Error en la función `update_devnet_data` en el archivo `db_update_devnet`
2024-09-11 08:31:59,513 - 2024-09-11 08:31:59,513 - ERROR - Traceback (most recent call last):
  File "/home/donkami/.local/lib/python3.10/site-packages/mysql/connector/connection_cext.py", line 611, in cmd_query
    self._cmysql.query(
_mysql_connector.MySQLInterfaceError: Duplicate entry 'Not Found' for key 'system_health.id_prtg'

The above exception was the direct cause of the following exception:

Traceback (most recent call last):
  File "/home/donkami/Sona/devnet-candelaria/Services/InfraGeneral/db_update_devnet.py", line 87, in update_sysHealth
    devnet_cursor.executemany(query, data_tuple)
  File "/home/donkami/.local/lib/python3.10/site-packages/mysql/connector/cursor_cext.py", line 465, in executemany
    self.execute(operation, params)
  File "/home/donkami/.local/lib/python3.10/site-packages/mysql/connector/cursor_cext.py", line 330, in execute
    result = self._cnx.cmd_query(
  File "/home/donkami/.local/lib/python3.10/site-packages/mysql/connector/connection_cext.py", line 619, in cmd_query
    raise get_mysql_exception(
mysql.connector.errors.IntegrityError: 1062 (23000): Duplicate entry 'Not Found' for key 'system_health.id_prtg'

2024-09-11 08:31:59,513 - 2024-09-11 08:31:59,513 - ERROR - 1062 (23000): Duplicate entry 'Not Found' for key 'system_health.id_prtg'
2024-09-11 08:31:59,514 - 2024-09-11 08:31:59,514 - ERROR - Error en la función `update_devnet_data` en el archivo `db_update_devnet`
2024-09-11 08:35:41,625 - 2024-09-11 08:35:41,625 - ERROR - Traceback (most recent call last):
  File "/home/donkami/Sona/devnet-candelaria/Services/InfraGeneral/neighbors.py", line 73, in status_neighbor
    if neighbor in current_neighbors:
TypeError: argument of type 'NoneType' is not iterable

2024-09-11 08:35:41,625 - 2024-09-11 08:35:41,625 - ERROR - argument of type 'NoneType' is not iterable
2024-09-11 08:35:41,625 - 2024-09-11 08:35:41,625 - ERROR - Error en la funcion `status_neighbor` en el archivo neighbors
2024-09-11 08:40:15,376 - 2024-09-11 08:40:15,376 - ERROR - Traceback (most recent call last):
  File "/home/donkami/Sona/devnet-candelaria/Services/InfraGeneral/neighbors.py", line 74, in status_neighbor
    if neighbor in current_neighbors:
TypeError: argument of type 'NoneType' is not iterable

2024-09-11 08:40:15,378 - 2024-09-11 08:40:15,378 - ERROR - argument of type 'NoneType' is not iterable
2024-09-11 08:40:15,378 - 2024-09-11 08:40:15,378 - ERROR - Error en la funcion `status_neighbor` en el archivo neighbors
2024-09-11 08:43:31,110 - 2024-09-11 08:43:31,110 - ERROR - Traceback (most recent call last):
  File "/home/donkami/Sona/devnet-candelaria/Services/InfraGeneral/neighbors.py", line 170, in set_interfaces_descriptions
    element["name_switch"] == item["name_switch"]
TypeError: list indices must be integers or slices, not str

2024-09-11 08:43:31,112 - 2024-09-11 08:43:31,112 - ERROR - list indices must be integers or slices, not str
2024-09-11 08:43:31,112 - 2024-09-11 08:43:31,112 - ERROR - Error en funcion set_interfaces_description en el archivo neighbors
2024-09-11 08:43:31,112 - 2024-09-11 08:43:31,112 - ERROR - Traceback (most recent call last):
  File "/home/donkami/Sona/devnet-candelaria/Services/InfraGeneral/main.py", line 51, in main
    update_neighbors(final_data_neighbors)
  File "/home/donkami/Sona/devnet-candelaria/Services/InfraGeneral/db_update_devnet.py", line 161, in update_neighbors
    data_tuple = [
TypeError: 'NoneType' object is not iterable

2024-09-11 08:47:30,297 - 2024-09-11 08:47:30,297 - ERROR - Traceback (most recent call last):
  File "/home/donkami/Sona/devnet-candelaria/Services/InfraGeneral/neighbors.py", line 172, in set_interfaces_descriptions
    element["name_switch"] == item["name_switch"]
TypeError: list indices must be integers or slices, not str

2024-09-11 08:47:30,298 - 2024-09-11 08:47:30,298 - ERROR - list indices must be integers or slices, not str
2024-09-11 08:47:30,298 - 2024-09-11 08:47:30,298 - ERROR - Error en funcion set_interfaces_description en el archivo neighbors
2024-09-11 08:47:30,299 - 2024-09-11 08:47:30,299 - ERROR - Traceback (most recent call last):
  File "/home/donkami/Sona/devnet-candelaria/Services/InfraGeneral/main.py", line 51, in main
    update_neighbors(final_data_neighbors)
  File "/home/donkami/Sona/devnet-candelaria/Services/InfraGeneral/db_update_devnet.py", line 161, in update_neighbors
    data_tuple = [
TypeError: 'NoneType' object is not iterable

2024-09-11 08:51:39,976 - 2024-09-11 08:51:39,976 - ERROR - Traceback (most recent call last):
  File "/home/donkami/Sona/devnet-candelaria/Services/InfraGeneral/neighbors.py", line 170, in set_interfaces_descriptions
    element["name_switch"] == item["name_switch"]
TypeError: list indices must be integers or slices, not str

2024-09-11 08:51:39,977 - 2024-09-11 08:51:39,977 - ERROR - list indices must be integers or slices, not str
2024-09-11 08:51:39,978 - 2024-09-11 08:51:39,978 - ERROR - Error en funcion set_interfaces_description en el archivo neighbors
2024-09-11 08:51:39,978 - 2024-09-11 08:51:39,978 - ERROR - Traceback (most recent call last):
  File "/home/donkami/Sona/devnet-candelaria/Services/InfraGeneral/main.py", line 51, in main
    update_neighbors(final_data_neighbors)
  File "/home/donkami/Sona/devnet-candelaria/Services/InfraGeneral/db_update_devnet.py", line 161, in update_neighbors
    data_tuple = [
TypeError: 'NoneType' object is not iterable

2024-09-11 08:55:47,088 - 2024-09-11 08:55:47,088 - ERROR - Traceback (most recent call last):
  File "/home/donkami/Sona/devnet-candelaria/Services/InfraGeneral/neighbors.py", line 170, in set_interfaces_descriptions
    element["name_switch"] == item["name_switch"]
TypeError: list indices must be integers or slices, not str

2024-09-11 08:55:47,090 - 2024-09-11 08:55:47,090 - ERROR - list indices must be integers or slices, not str
2024-09-11 08:55:47,090 - 2024-09-11 08:55:47,090 - ERROR - Error en funcion set_interfaces_description en el archivo neighbors
2024-09-11 08:55:47,091 - 2024-09-11 08:55:47,091 - ERROR - Traceback (most recent call last):
  File "/home/donkami/Sona/devnet-candelaria/Services/InfraGeneral/main.py", line 51, in main
    update_neighbors(final_data_neighbors)
  File "/home/donkami/Sona/devnet-candelaria/Services/InfraGeneral/db_update_devnet.py", line 161, in update_neighbors
    data_tuple = [
TypeError: 'NoneType' object is not iterable

2024-09-11 08:57:49,769 - 2024-09-11 08:57:49,769 - ERROR - Traceback (most recent call last):
  File "/home/donkami/Sona/devnet-candelaria/Services/InfraGeneral/neighbors.py", line 173, in set_interfaces_descriptions
    element["interface_descrip"] = item["interface_descrip"]
KeyError: 'interface_descrip'

2024-09-11 08:57:49,770 - 2024-09-11 08:57:49,770 - ERROR - 'interface_descrip'
2024-09-11 08:57:49,770 - 2024-09-11 08:57:49,770 - ERROR - Error en funcion set_interfaces_description en el archivo neighbors
2024-09-11 08:57:49,770 - 2024-09-11 08:57:49,770 - ERROR - Traceback (most recent call last):
  File "/home/donkami/Sona/devnet-candelaria/Services/InfraGeneral/main.py", line 51, in main
    update_neighbors(final_data_neighbors)
  File "/home/donkami/Sona/devnet-candelaria/Services/InfraGeneral/db_update_devnet.py", line 161, in update_neighbors
    data_tuple = [
TypeError: 'NoneType' object is not iterable

2024-09-11 08:59:20,666 - 2024-09-11 08:59:20,666 - ERROR - Traceback (most recent call last):
  File "/home/donkami/Sona/devnet-candelaria/Services/InfraGeneral/main.py", line 51, in main
    update_neighbors(final_data_neighbors)
  File "/home/donkami/Sona/devnet-candelaria/Services/InfraGeneral/db_update_devnet.py", line 161, in update_neighbors
    data_tuple = [
  File "/home/donkami/Sona/devnet-candelaria/Services/InfraGeneral/db_update_devnet.py", line 170, in <listcomp>
    neigh["interface_descrip"],
KeyError: 'interface_descrip'

2024-09-11 09:41:56,955 - 2024-09-11 09:41:56,955 - ERROR - Traceback (most recent call last):
  File "/home/donkami/Sona/devnet-candelaria/Services/InfraGeneral/main.py", line 51, in main
    update_neighbors(final_data_neighbors)
  File "/home/donkami/Sona/devnet-candelaria/Services/InfraGeneral/db_update_devnet.py", line 161, in update_neighbors
    data_tuple = [
  File "/home/donkami/Sona/devnet-candelaria/Services/InfraGeneral/db_update_devnet.py", line 170, in <listcomp>
    neigh["interface_descrip"],
KeyError: 'interface_descrip'

