2025-01-28 14:02:43,357 - ERROR - 'status'
2025-01-28 14:02:43,358 - ERROR - Traceback (most recent call last):
  File "/home/donkami/Sona/devnet-candelaria/Services/Groups_Prtg/main.py", line 46, in main
    if "Up" in group_element['status'] and "Down" in elem['status']:
KeyError: 'status'

2025-01-28 14:02:43,359 - ERROR - Error en main
Traceback (most recent call last):
  File "/home/donkami/.local/lib/python3.10/site-packages/mysql/connector/connection_cext.py", line 291, in _open_connection
    self._cmysql.connect(**cnx_kwargs)
_mysql_connector.MySQLInterfaceError: Access denied for user 'donkami'@'172.18.0.1' (using password: NO)

The above exception was the direct cause of the following exception:

Traceback (most recent call last):
  File "/home/donkami/Sona/devnet-candelaria/Services/Dragos/db_connection.py", line 30, in devnet_connection
    db_connector = mysql.connector.connect(
  File "/home/donkami/.local/lib/python3.10/site-packages/mysql/connector/pooling.py", line 293, in connect
    return CMySQLConnection(*args, **kwargs)
  File "/home/donkami/.local/lib/python3.10/site-packages/mysql/connector/connection_cext.py", line 120, in __init__
    self.connect(**kwargs)
  File "/home/donkami/.local/lib/python3.10/site-packages/mysql/connector/abstracts.py", line 1181, in connect
    self._open_connection()
  File "/home/donkami/.local/lib/python3.10/site-packages/mysql/connector/connection_cext.py", line 296, in _open_connection
    raise get_mysql_exception(
mysql.connector.errors.ProgrammingError: 1045 (28000): Access denied for user 'donkami'@'172.18.0.1' (using password: NO)

Error en la función `devnet_connection` en el archivo `db_connections`
1045 (28000): Access denied for user 'donkami'@'172.18.0.1' (using password: NO)
No se pudo establecer la conexión con la base de datos: el conector es None.
Traceback (most recent call last):
  File "/home/donkami/Sona/devnet-candelaria/Services/Dragos/get_data.py", line 31, in get_devnet_data
    raise ValueError("No se pudo establecer la conexión con la base de datos: el conector es None.")
ValueError: No se pudo establecer la conexión con la base de datos: el conector es None.

Error al obtener datos de la base de datos
Error en la funcion `get_data` en el archivo `get_data`
Traceback (most recent call last):
  File "/home/donkami/Sona/devnet-candelaria/Services/Dragos/main.py", line 21, in main
    for e in db_devnet_data:
TypeError: 'NoneType' object is not iterable

During handling of the above exception, another exception occurred:

Traceback (most recent call last):
  File "/home/donkami/.local/lib/python3.10/site-packages/mysql/connector/connection_cext.py", line 291, in _open_connection
    self._cmysql.connect(**cnx_kwargs)
_mysql_connector.MySQLInterfaceError: Access denied for user 'donkami'@'172.18.0.1' (using password: NO)

The above exception was the direct cause of the following exception:

Traceback (most recent call last):
  File "/home/donkami/Sona/devnet-candelaria/Services/Dragos/db_connection.py", line 30, in devnet_connection
    db_connector = mysql.connector.connect(
  File "/home/donkami/.local/lib/python3.10/site-packages/mysql/connector/pooling.py", line 293, in connect
    return CMySQLConnection(*args, **kwargs)
  File "/home/donkami/.local/lib/python3.10/site-packages/mysql/connector/connection_cext.py", line 120, in __init__
    self.connect(**kwargs)
  File "/home/donkami/.local/lib/python3.10/site-packages/mysql/connector/abstracts.py", line 1181, in connect
    self._open_connection()
  File "/home/donkami/.local/lib/python3.10/site-packages/mysql/connector/connection_cext.py", line 296, in _open_connection
    raise get_mysql_exception(
mysql.connector.errors.ProgrammingError: 1045 (28000): Access denied for user 'donkami'@'172.18.0.1' (using password: NO)

Error en la función `devnet_connection` en el archivo `db_connections`
1045 (28000): Access denied for user 'donkami'@'172.18.0.1' (using password: NO)
Traceback (most recent call last):
  File "/home/donkami/Sona/devnet-candelaria/Services/Dragos/main.py", line 21, in main
    for e in db_devnet_data:
TypeError: 'NoneType' object is not iterable

During handling of the above exception, another exception occurred:

Traceback (most recent call last):
  File "/home/donkami/Sona/devnet-candelaria/Services/Dragos/db_update.py", line 87, in datetime_register
    devnet_cursor = db_connector.cursor()
AttributeError: 'NoneType' object has no attribute 'cursor'

Error en la función `datetime_register` en el archivo `db_update_devnet`
'NoneType' object has no attribute 'cursor'
Traceback (most recent call last):
  File "/home/donkami/Sona/devnet-candelaria/Services/Dragos/main.py", line 21, in main
    for e in db_devnet_data:
TypeError: 'NoneType' object is not iterable

'NoneType' object is not iterable
Error en la funcion `main` del archivo `main`
Traceback (most recent call last):
  File "/home/donkami/.local/lib/python3.10/site-packages/mysql/connector/connection_cext.py", line 291, in _open_connection
    self._cmysql.connect(**cnx_kwargs)
_mysql_connector.MySQLInterfaceError: Access denied for user 'donkami'@'172.18.0.1' (using password: NO)

The above exception was the direct cause of the following exception:

Traceback (most recent call last):
  File "/home/donkami/Sona/devnet-candelaria/Services/Dragos/db_connection.py", line 30, in devnet_connection
    db_connector = mysql.connector.connect(
  File "/home/donkami/.local/lib/python3.10/site-packages/mysql/connector/pooling.py", line 293, in connect
    return CMySQLConnection(*args, **kwargs)
  File "/home/donkami/.local/lib/python3.10/site-packages/mysql/connector/connection_cext.py", line 120, in __init__
    self.connect(**kwargs)
  File "/home/donkami/.local/lib/python3.10/site-packages/mysql/connector/abstracts.py", line 1181, in connect
    self._open_connection()
  File "/home/donkami/.local/lib/python3.10/site-packages/mysql/connector/connection_cext.py", line 296, in _open_connection
    raise get_mysql_exception(
mysql.connector.errors.ProgrammingError: 1045 (28000): Access denied for user 'donkami'@'172.18.0.1' (using password: NO)

Error en la función `devnet_connection` en el archivo `db_connections`
1045 (28000): Access denied for user 'donkami'@'172.18.0.1' (using password: NO)
No se pudo establecer la conexión con la base de datos: el conector es None.
Traceback (most recent call last):
  File "/home/donkami/Sona/devnet-candelaria/Services/Dragos/get_data.py", line 31, in get_devnet_data
    raise ValueError("No se pudo establecer la conexión con la base de datos: el conector es None.")
ValueError: No se pudo establecer la conexión con la base de datos: el conector es None.

Error al obtener datos de la base de datos
Error en la funcion `get_data` en el archivo `get_data`
Traceback (most recent call last):
  File "/home/donkami/Sona/devnet-candelaria/Services/Dragos/main.py", line 22, in main
    for e in db_devnet_data:
TypeError: 'NoneType' object is not iterable

During handling of the above exception, another exception occurred:

Traceback (most recent call last):
  File "/home/donkami/.local/lib/python3.10/site-packages/mysql/connector/connection_cext.py", line 291, in _open_connection
    self._cmysql.connect(**cnx_kwargs)
_mysql_connector.MySQLInterfaceError: Access denied for user 'donkami'@'172.18.0.1' (using password: NO)

The above exception was the direct cause of the following exception:

Traceback (most recent call last):
  File "/home/donkami/Sona/devnet-candelaria/Services/Dragos/db_connection.py", line 30, in devnet_connection
    db_connector = mysql.connector.connect(
  File "/home/donkami/.local/lib/python3.10/site-packages/mysql/connector/pooling.py", line 293, in connect
    return CMySQLConnection(*args, **kwargs)
  File "/home/donkami/.local/lib/python3.10/site-packages/mysql/connector/connection_cext.py", line 120, in __init__
    self.connect(**kwargs)
  File "/home/donkami/.local/lib/python3.10/site-packages/mysql/connector/abstracts.py", line 1181, in connect
    self._open_connection()
  File "/home/donkami/.local/lib/python3.10/site-packages/mysql/connector/connection_cext.py", line 296, in _open_connection
    raise get_mysql_exception(
mysql.connector.errors.ProgrammingError: 1045 (28000): Access denied for user 'donkami'@'172.18.0.1' (using password: NO)

Error en la función `devnet_connection` en el archivo `db_connections`
1045 (28000): Access denied for user 'donkami'@'172.18.0.1' (using password: NO)
Traceback (most recent call last):
  File "/home/donkami/Sona/devnet-candelaria/Services/Dragos/main.py", line 22, in main
    for e in db_devnet_data:
TypeError: 'NoneType' object is not iterable

During handling of the above exception, another exception occurred:

Traceback (most recent call last):
  File "/home/donkami/Sona/devnet-candelaria/Services/Dragos/db_update.py", line 87, in datetime_register
    devnet_cursor = db_connector.cursor()
AttributeError: 'NoneType' object has no attribute 'cursor'

Error en la función `datetime_register` en el archivo `db_update_devnet`
'NoneType' object has no attribute 'cursor'
Traceback (most recent call last):
  File "/home/donkami/Sona/devnet-candelaria/Services/Dragos/main.py", line 22, in main
    for e in db_devnet_data:
TypeError: 'NoneType' object is not iterable

'NoneType' object is not iterable
Error en la funcion `main` del archivo `main`
Traceback (most recent call last):
  File "/home/donkami/Sona/devnet-candelaria/Services/Dragos/main.py", line 23, in main
    api_endpoint = os.getenv("AAA").format( id_device=e['ip'], username=PRTG_USERNAME, password=PRTG_PASSWORD )
KeyError: 'ip'

'ip'
Error en la funcion `main` del archivo `main`
Traceback (most recent call last):
  File "/home/donkami/Sona/devnet-candelaria/Services/Dragos/main.py", line 24, in main
    api_endpoint = os.getenv("AAA").format( id_device=e['ip'], username=PRTG_USERNAME, password=PRTG_PASSWORD )
KeyError: 'ip'

'ip'
Error en la funcion `main` del archivo `main`
