2024-02-20 12:13:54,677 - ERROR: Error Controladora Device 10.117.115.111
2024-02-20 12:13:54,677 - ERROR: Error Controladora Device 10.117.115.111
2024-02-20 12:13:54,678 - ERROR: Traceback (most recent call last):
  File "/home/donkami/Sona/devnet-candelaria/Services/Mesh/controladora.py", line 35, in get_data_controladora
    data_pala = net_connect.send_command(f"sh wireless client summary detail ipv4 | inc {device_ip}") #! Ip Pala
  File "/home/donkami/.local/lib/python3.10/site-packages/netmiko/utilities.py", line 592, in wrapper_decorator
    return func(self, *args, **kwargs)
  File "/home/donkami/.local/lib/python3.10/site-packages/netmiko/base_connection.py", line 1721, in send_command
    raise ReadTimeout(msg)
netmiko.exceptions.ReadTimeout: 
Pattern not detected: 'WLC\\-9800\\-MESH\\-CD>' in output.

Things you might try to fix this:
1. Explicitly set your pattern using the expect_string argument.
2. Increase the read_timeout to a larger value.

You can also look at the Netmiko session_log or debug log for more information.



2024-02-20 12:13:54,678 - ERROR: Traceback (most recent call last):
  File "/home/donkami/Sona/devnet-candelaria/Services/Mesh/controladora.py", line 35, in get_data_controladora
    data_pala = net_connect.send_command(f"sh wireless client summary detail ipv4 | inc {device_ip}") #! Ip Pala
  File "/home/donkami/.local/lib/python3.10/site-packages/netmiko/utilities.py", line 592, in wrapper_decorator
    return func(self, *args, **kwargs)
  File "/home/donkami/.local/lib/python3.10/site-packages/netmiko/base_connection.py", line 1721, in send_command
    raise ReadTimeout(msg)
netmiko.exceptions.ReadTimeout: 
Pattern not detected: 'WLC\\-9800\\-MESH\\-CD>' in output.

Things you might try to fix this:
1. Explicitly set your pattern using the expect_string argument.
2. Increase the read_timeout to a larger value.

You can also look at the Netmiko session_log or debug log for more information.



2024-02-20 12:16:02,765 - ERROR: Error Controladora Device 10.117.115.121
2024-02-20 12:16:02,765 - ERROR: Error Controladora Device 10.117.115.121
2024-02-20 12:16:02,766 - ERROR: Traceback (most recent call last):
  File "/home/donkami/Sona/devnet-candelaria/Services/Mesh/controladora.py", line 35, in get_data_controladora
    data_pala = net_connect.send_command(f"sh wireless client summary detail ipv4 | inc {device_ip}") #! Ip Pala
  File "/home/donkami/.local/lib/python3.10/site-packages/netmiko/utilities.py", line 592, in wrapper_decorator
    return func(self, *args, **kwargs)
  File "/home/donkami/.local/lib/python3.10/site-packages/netmiko/base_connection.py", line 1721, in send_command
    raise ReadTimeout(msg)
netmiko.exceptions.ReadTimeout: 
Pattern not detected: 'WLC\\-9800\\-MESH\\-CD>' in output.

Things you might try to fix this:
1. Explicitly set your pattern using the expect_string argument.
2. Increase the read_timeout to a larger value.

You can also look at the Netmiko session_log or debug log for more information.



2024-02-20 12:16:02,766 - ERROR: Traceback (most recent call last):
  File "/home/donkami/Sona/devnet-candelaria/Services/Mesh/controladora.py", line 35, in get_data_controladora
    data_pala = net_connect.send_command(f"sh wireless client summary detail ipv4 | inc {device_ip}") #! Ip Pala
  File "/home/donkami/.local/lib/python3.10/site-packages/netmiko/utilities.py", line 592, in wrapper_decorator
    return func(self, *args, **kwargs)
  File "/home/donkami/.local/lib/python3.10/site-packages/netmiko/base_connection.py", line 1721, in send_command
    raise ReadTimeout(msg)
netmiko.exceptions.ReadTimeout: 
Pattern not detected: 'WLC\\-9800\\-MESH\\-CD>' in output.

Things you might try to fix this:
1. Explicitly set your pattern using the expect_string argument.
2. Increase the read_timeout to a larger value.

You can also look at the Netmiko session_log or debug log for more information.



2024-02-20 12:18:15,482 - ERROR: Error Controladora Device 10.117.115.183
2024-02-20 12:18:15,482 - ERROR: Error Controladora Device 10.117.115.183
2024-02-20 12:18:15,483 - ERROR: Traceback (most recent call last):
  File "/home/donkami/Sona/devnet-candelaria/Services/Mesh/controladora.py", line 38, in get_data_controladora
    output = net_connect.send_command("sh wireless client mac-address " + data_pala.split()[0] + " detail")
IndexError: list index out of range

2024-02-20 12:18:15,483 - ERROR: Traceback (most recent call last):
  File "/home/donkami/Sona/devnet-candelaria/Services/Mesh/controladora.py", line 38, in get_data_controladora
    output = net_connect.send_command("sh wireless client mac-address " + data_pala.split()[0] + " detail")
IndexError: list index out of range

2024-02-28 15:45:48,905 - ERROR - Error en funcion Reset_Base
2024-02-28 15:45:48,914 - ERROR - [Errno 110] Connection timed out
2024-02-28 15:45:48,914 - ERROR - Traceback (most recent call last):
  File "/home/donkami/Sona/devnet-candelaria/Services/FiM/reset_base.py", line 27, in reset_base
    client.connect(
  File "/home/donkami/.local/lib/python3.10/site-packages/paramiko/client.py", line 386, in connect
    sock.connect(addr)
TimeoutError: [Errno 110] Connection timed out

2024-02-29 12:42:39,018 - ERROR - Error al conectarse a la base de datos
2024-02-29 12:42:39,018 - ERROR - Error al conectarse a la base de datos
Error al conectarse a la base de datos
2024-02-29 12:42:39,019 - ERROR - Traceback (most recent call last):
  File "/home/donkami/.local/lib/python3.10/site-packages/mysql/connector/connection_cext.py", line 291, in _open_connection
    self._cmysql.connect(**cnx_kwargs)
_mysql_connector.MySQLInterfaceError: Unknown MySQL server host 'db' (-2)

The above exception was the direct cause of the following exception:

Traceback (most recent call last):
  File "/home/donkami/Sona/devnet-candelaria/Services/FiM/save_register.py", line 32, in database_connection
    mydb = mysql.connector.connect(
  File "/home/donkami/.local/lib/python3.10/site-packages/mysql/connector/pooling.py", line 293, in connect
    return CMySQLConnection(*args, **kwargs)
  File "/home/donkami/.local/lib/python3.10/site-packages/mysql/connector/connection_cext.py", line 120, in __init__
    self.connect(**kwargs)
  File "/home/donkami/.local/lib/python3.10/site-packages/mysql/connector/abstracts.py", line 1181, in connect
    self._open_connection()
  File "/home/donkami/.local/lib/python3.10/site-packages/mysql/connector/connection_cext.py", line 296, in _open_connection
    raise get_mysql_exception(
mysql.connector.errors.DatabaseError: 2005 (HY000): Unknown MySQL server host 'db' (-2)

2024-02-29 12:42:39,019 - ERROR - Traceback (most recent call last):
  File "/home/donkami/.local/lib/python3.10/site-packages/mysql/connector/connection_cext.py", line 291, in _open_connection
    self._cmysql.connect(**cnx_kwargs)
_mysql_connector.MySQLInterfaceError: Unknown MySQL server host 'db' (-2)

The above exception was the direct cause of the following exception:

Traceback (most recent call last):
  File "/home/donkami/Sona/devnet-candelaria/Services/FiM/save_register.py", line 32, in database_connection
    mydb = mysql.connector.connect(
  File "/home/donkami/.local/lib/python3.10/site-packages/mysql/connector/pooling.py", line 293, in connect
    return CMySQLConnection(*args, **kwargs)
  File "/home/donkami/.local/lib/python3.10/site-packages/mysql/connector/connection_cext.py", line 120, in __init__
    self.connect(**kwargs)
  File "/home/donkami/.local/lib/python3.10/site-packages/mysql/connector/abstracts.py", line 1181, in connect
    self._open_connection()
  File "/home/donkami/.local/lib/python3.10/site-packages/mysql/connector/connection_cext.py", line 296, in _open_connection
    raise get_mysql_exception(
mysql.connector.errors.DatabaseError: 2005 (HY000): Unknown MySQL server host 'db' (-2)

Traceback (most recent call last):
  File "/home/donkami/.local/lib/python3.10/site-packages/mysql/connector/connection_cext.py", line 291, in _open_connection
    self._cmysql.connect(**cnx_kwargs)
_mysql_connector.MySQLInterfaceError: Unknown MySQL server host 'db' (-2)

The above exception was the direct cause of the following exception:

Traceback (most recent call last):
  File "/home/donkami/Sona/devnet-candelaria/Services/FiM/save_register.py", line 32, in database_connection
    mydb = mysql.connector.connect(
  File "/home/donkami/.local/lib/python3.10/site-packages/mysql/connector/pooling.py", line 293, in connect
    return CMySQLConnection(*args, **kwargs)
  File "/home/donkami/.local/lib/python3.10/site-packages/mysql/connector/connection_cext.py", line 120, in __init__
    self.connect(**kwargs)
  File "/home/donkami/.local/lib/python3.10/site-packages/mysql/connector/abstracts.py", line 1181, in connect
    self._open_connection()
  File "/home/donkami/.local/lib/python3.10/site-packages/mysql/connector/connection_cext.py", line 296, in _open_connection
    raise get_mysql_exception(
mysql.connector.errors.DatabaseError: 2005 (HY000): Unknown MySQL server host 'db' (-2)

2024-02-29 12:42:39,019 - ERROR - 2005 (HY000): Unknown MySQL server host 'db' (-2)
2024-02-29 12:42:39,019 - ERROR - 2005 (HY000): Unknown MySQL server host 'db' (-2)
2005 (HY000): Unknown MySQL server host 'db' (-2)
2024-03-04 12:59:33,703 - ERROR - Error en funcion BGP
2024-03-04 12:59:33,703 - ERROR - Error en funcion BGP
2024-03-04 12:59:33,703 - ERROR - Error en funcion BGP
2024-03-04 12:59:33,703 - ERROR - Error en funcion BGP
2024-03-04 12:59:33,703 - ERROR - Error en funcion BGP
2024-03-04 12:59:33,703 - ERROR - Error en funcion BGP
2024-03-04 12:59:33,703 - ERROR - Error en funcion BGP
2024-03-04 12:59:33,703 - ERROR - Error en funcion BGP
2024-03-04 12:59:33,713 - ERROR - [Errno 110] Connection timed out
2024-03-04 12:59:33,713 - ERROR - [Errno 110] Connection timed out
2024-03-04 12:59:33,713 - ERROR - [Errno 110] Connection timed out
2024-03-04 12:59:33,713 - ERROR - [Errno 110] Connection timed out
2024-03-04 12:59:33,713 - ERROR - [Errno 110] Connection timed out
2024-03-04 12:59:33,713 - ERROR - [Errno 110] Connection timed out
2024-03-04 12:59:33,713 - ERROR - [Errno 110] Connection timed out
2024-03-04 12:59:33,713 - ERROR - [Errno 110] Connection timed out
2024-03-04 12:59:33,714 - ERROR - Traceback (most recent call last):
  File "/home/donkami/Sona/devnet-candelaria/Services/InfraGeneral/command_bgp.py", line 19, in bgp_function
    client.connect(hostname=ip_switch, port=22, username='roadmin', password='C4nd3*2023')
  File "/home/donkami/.local/lib/python3.10/site-packages/paramiko/client.py", line 386, in connect
    sock.connect(addr)
TimeoutError: [Errno 110] Connection timed out

2024-03-04 12:59:33,714 - ERROR - Traceback (most recent call last):
  File "/home/donkami/Sona/devnet-candelaria/Services/InfraGeneral/command_bgp.py", line 19, in bgp_function
    client.connect(hostname=ip_switch, port=22, username='roadmin', password='C4nd3*2023')
  File "/home/donkami/.local/lib/python3.10/site-packages/paramiko/client.py", line 386, in connect
    sock.connect(addr)
TimeoutError: [Errno 110] Connection timed out

2024-03-04 12:59:33,714 - ERROR - Traceback (most recent call last):
  File "/home/donkami/Sona/devnet-candelaria/Services/InfraGeneral/command_bgp.py", line 19, in bgp_function
    client.connect(hostname=ip_switch, port=22, username='roadmin', password='C4nd3*2023')
  File "/home/donkami/.local/lib/python3.10/site-packages/paramiko/client.py", line 386, in connect
    sock.connect(addr)
TimeoutError: [Errno 110] Connection timed out

2024-03-04 12:59:33,714 - ERROR - Traceback (most recent call last):
  File "/home/donkami/Sona/devnet-candelaria/Services/InfraGeneral/command_bgp.py", line 19, in bgp_function
    client.connect(hostname=ip_switch, port=22, username='roadmin', password='C4nd3*2023')
  File "/home/donkami/.local/lib/python3.10/site-packages/paramiko/client.py", line 386, in connect
    sock.connect(addr)
TimeoutError: [Errno 110] Connection timed out

2024-03-04 12:59:33,714 - ERROR - Traceback (most recent call last):
  File "/home/donkami/Sona/devnet-candelaria/Services/InfraGeneral/command_bgp.py", line 19, in bgp_function
    client.connect(hostname=ip_switch, port=22, username='roadmin', password='C4nd3*2023')
  File "/home/donkami/.local/lib/python3.10/site-packages/paramiko/client.py", line 386, in connect
    sock.connect(addr)
TimeoutError: [Errno 110] Connection timed out

2024-03-04 12:59:33,714 - ERROR - Traceback (most recent call last):
  File "/home/donkami/Sona/devnet-candelaria/Services/InfraGeneral/command_bgp.py", line 19, in bgp_function
    client.connect(hostname=ip_switch, port=22, username='roadmin', password='C4nd3*2023')
  File "/home/donkami/.local/lib/python3.10/site-packages/paramiko/client.py", line 386, in connect
    sock.connect(addr)
TimeoutError: [Errno 110] Connection timed out

2024-03-04 12:59:33,714 - ERROR - Traceback (most recent call last):
  File "/home/donkami/Sona/devnet-candelaria/Services/InfraGeneral/command_bgp.py", line 19, in bgp_function
    client.connect(hostname=ip_switch, port=22, username='roadmin', password='C4nd3*2023')
  File "/home/donkami/.local/lib/python3.10/site-packages/paramiko/client.py", line 386, in connect
    sock.connect(addr)
TimeoutError: [Errno 110] Connection timed out

2024-03-04 12:59:33,714 - ERROR - Traceback (most recent call last):
  File "/home/donkami/Sona/devnet-candelaria/Services/InfraGeneral/command_bgp.py", line 19, in bgp_function
    client.connect(hostname=ip_switch, port=22, username='roadmin', password='C4nd3*2023')
  File "/home/donkami/.local/lib/python3.10/site-packages/paramiko/client.py", line 386, in connect
    sock.connect(addr)
TimeoutError: [Errno 110] Connection timed out

2024-03-04 13:37:17,202 - ERROR - Traceback (most recent call last):
  File "/home/donkami/Sona/devnet-candelaria/Services/InfraGeneral/main.py", line 95, in core1
    data_neighbors = data_bgp + data_eigrp + data_ospf + data_clcanot_dcs + data_clcanot_ug + data_clcanot_ugmine
TypeError: unsupported operand type(s) for +: 'NoneType' and 'NoneType'

2024-03-04 13:37:17,202 - ERROR - Traceback (most recent call last):
  File "/home/donkami/Sona/devnet-candelaria/Services/InfraGeneral/main.py", line 95, in core1
    data_neighbors = data_bgp + data_eigrp + data_ospf + data_clcanot_dcs + data_clcanot_ug + data_clcanot_ugmine
TypeError: unsupported operand type(s) for +: 'NoneType' and 'NoneType'

2024-03-04 13:37:17,202 - ERROR - Traceback (most recent call last):
  File "/home/donkami/Sona/devnet-candelaria/Services/InfraGeneral/main.py", line 95, in core1
    data_neighbors = data_bgp + data_eigrp + data_ospf + data_clcanot_dcs + data_clcanot_ug + data_clcanot_ugmine
TypeError: unsupported operand type(s) for +: 'NoneType' and 'NoneType'

2024-03-04 13:37:17,202 - ERROR - Traceback (most recent call last):
  File "/home/donkami/Sona/devnet-candelaria/Services/InfraGeneral/main.py", line 95, in core1
    data_neighbors = data_bgp + data_eigrp + data_ospf + data_clcanot_dcs + data_clcanot_ug + data_clcanot_ugmine
TypeError: unsupported operand type(s) for +: 'NoneType' and 'NoneType'

2024-03-04 13:37:17,202 - ERROR - Traceback (most recent call last):
  File "/home/donkami/Sona/devnet-candelaria/Services/InfraGeneral/main.py", line 95, in core1
    data_neighbors = data_bgp + data_eigrp + data_ospf + data_clcanot_dcs + data_clcanot_ug + data_clcanot_ugmine
TypeError: unsupported operand type(s) for +: 'NoneType' and 'NoneType'

2024-03-04 13:37:17,202 - ERROR - Traceback (most recent call last):
  File "/home/donkami/Sona/devnet-candelaria/Services/InfraGeneral/main.py", line 95, in core1
    data_neighbors = data_bgp + data_eigrp + data_ospf + data_clcanot_dcs + data_clcanot_ug + data_clcanot_ugmine
TypeError: unsupported operand type(s) for +: 'NoneType' and 'NoneType'

2024-03-04 13:37:17,202 - ERROR - Traceback (most recent call last):
  File "/home/donkami/Sona/devnet-candelaria/Services/InfraGeneral/main.py", line 95, in core1
    data_neighbors = data_bgp + data_eigrp + data_ospf + data_clcanot_dcs + data_clcanot_ug + data_clcanot_ugmine
TypeError: unsupported operand type(s) for +: 'NoneType' and 'NoneType'

2024-03-04 13:37:17,202 - ERROR - Traceback (most recent call last):
  File "/home/donkami/Sona/devnet-candelaria/Services/InfraGeneral/main.py", line 95, in core1
    data_neighbors = data_bgp + data_eigrp + data_ospf + data_clcanot_dcs + data_clcanot_ug + data_clcanot_ugmine
TypeError: unsupported operand type(s) for +: 'NoneType' and 'NoneType'

2024-03-04 13:37:45,281 - ERROR - Traceback (most recent call last):
  File "/home/donkami/Sona/devnet-candelaria/Services/InfraGeneral/main.py", line 95, in core1
    data_neighbors = data_bgp + data_eigrp + data_ospf + data_clcanot_dcs + data_clcanot_ug + data_clcanot_ugmine
TypeError: can only concatenate list (not "NoneType") to list

2024-03-04 13:37:45,281 - ERROR - Traceback (most recent call last):
  File "/home/donkami/Sona/devnet-candelaria/Services/InfraGeneral/main.py", line 95, in core1
    data_neighbors = data_bgp + data_eigrp + data_ospf + data_clcanot_dcs + data_clcanot_ug + data_clcanot_ugmine
TypeError: can only concatenate list (not "NoneType") to list

2024-03-04 13:37:45,281 - ERROR - Traceback (most recent call last):
  File "/home/donkami/Sona/devnet-candelaria/Services/InfraGeneral/main.py", line 95, in core1
    data_neighbors = data_bgp + data_eigrp + data_ospf + data_clcanot_dcs + data_clcanot_ug + data_clcanot_ugmine
TypeError: can only concatenate list (not "NoneType") to list

2024-03-04 13:37:45,281 - ERROR - Traceback (most recent call last):
  File "/home/donkami/Sona/devnet-candelaria/Services/InfraGeneral/main.py", line 95, in core1
    data_neighbors = data_bgp + data_eigrp + data_ospf + data_clcanot_dcs + data_clcanot_ug + data_clcanot_ugmine
TypeError: can only concatenate list (not "NoneType") to list

2024-03-04 13:37:45,281 - ERROR - Traceback (most recent call last):
  File "/home/donkami/Sona/devnet-candelaria/Services/InfraGeneral/main.py", line 95, in core1
    data_neighbors = data_bgp + data_eigrp + data_ospf + data_clcanot_dcs + data_clcanot_ug + data_clcanot_ugmine
TypeError: can only concatenate list (not "NoneType") to list

2024-03-04 13:37:45,281 - ERROR - Traceback (most recent call last):
  File "/home/donkami/Sona/devnet-candelaria/Services/InfraGeneral/main.py", line 95, in core1
    data_neighbors = data_bgp + data_eigrp + data_ospf + data_clcanot_dcs + data_clcanot_ug + data_clcanot_ugmine
TypeError: can only concatenate list (not "NoneType") to list

2024-03-04 13:37:45,281 - ERROR - Traceback (most recent call last):
  File "/home/donkami/Sona/devnet-candelaria/Services/InfraGeneral/main.py", line 95, in core1
    data_neighbors = data_bgp + data_eigrp + data_ospf + data_clcanot_dcs + data_clcanot_ug + data_clcanot_ugmine
TypeError: can only concatenate list (not "NoneType") to list

2024-03-04 13:37:45,281 - ERROR - Traceback (most recent call last):
  File "/home/donkami/Sona/devnet-candelaria/Services/InfraGeneral/main.py", line 95, in core1
    data_neighbors = data_bgp + data_eigrp + data_ospf + data_clcanot_dcs + data_clcanot_ug + data_clcanot_ugmine
TypeError: can only concatenate list (not "NoneType") to list

2024-03-04 13:40:35,196 - ERROR - Traceback (most recent call last):
  File "/home/donkami/Sona/devnet-candelaria/Services/InfraGeneral/main.py", line 114, in core1
    route_via_bgp = data_route['via_bgp']
TypeError: list indices must be integers or slices, not str

2024-03-04 13:40:35,196 - ERROR - Traceback (most recent call last):
  File "/home/donkami/Sona/devnet-candelaria/Services/InfraGeneral/main.py", line 114, in core1
    route_via_bgp = data_route['via_bgp']
TypeError: list indices must be integers or slices, not str

2024-03-04 13:40:35,196 - ERROR - Traceback (most recent call last):
  File "/home/donkami/Sona/devnet-candelaria/Services/InfraGeneral/main.py", line 114, in core1
    route_via_bgp = data_route['via_bgp']
TypeError: list indices must be integers or slices, not str

2024-03-04 13:40:35,196 - ERROR - Traceback (most recent call last):
  File "/home/donkami/Sona/devnet-candelaria/Services/InfraGeneral/main.py", line 114, in core1
    route_via_bgp = data_route['via_bgp']
TypeError: list indices must be integers or slices, not str

2024-03-04 13:40:35,196 - ERROR - Traceback (most recent call last):
  File "/home/donkami/Sona/devnet-candelaria/Services/InfraGeneral/main.py", line 114, in core1
    route_via_bgp = data_route['via_bgp']
TypeError: list indices must be integers or slices, not str

2024-03-04 13:40:35,196 - ERROR - Traceback (most recent call last):
  File "/home/donkami/Sona/devnet-candelaria/Services/InfraGeneral/main.py", line 114, in core1
    route_via_bgp = data_route['via_bgp']
TypeError: list indices must be integers or slices, not str

2024-03-04 13:40:35,196 - ERROR - Traceback (most recent call last):
  File "/home/donkami/Sona/devnet-candelaria/Services/InfraGeneral/main.py", line 114, in core1
    route_via_bgp = data_route['via_bgp']
TypeError: list indices must be integers or slices, not str

2024-03-04 13:40:35,196 - ERROR - Traceback (most recent call last):
  File "/home/donkami/Sona/devnet-candelaria/Services/InfraGeneral/main.py", line 114, in core1
    route_via_bgp = data_route['via_bgp']
TypeError: list indices must be integers or slices, not str

