2024-09-11 16:27:51,871 - ERROR - Traceback (most recent call last):
  File "/home/donkami/.local/lib/python3.10/site-packages/mysql/connector/connection_cext.py", line 291, in _open_connection
    self._cmysql.connect(**cnx_kwargs)
_mysql_connector.MySQLInterfaceError: Unknown MySQL server host 'db' (-3)

The above exception was the direct cause of the following exception:

Traceback (most recent call last):
  File "/home/donkami/Sona/devnet-candelaria/Services/Ups/db_connections.py", line 21, in devnet_connection
    db_connector = mysql.connector.connect(
  File "/home/donkami/.local/lib/python3.10/site-packages/mysql/connector/pooling.py", line 293, in connect
    return CMySQLConnection(*args, **kwargs)
  File "/home/donkami/.local/lib/python3.10/site-packages/mysql/connector/connection_cext.py", line 120, in __init__
    self.connect(**kwargs)
  File "/home/donkami/.local/lib/python3.10/site-packages/mysql/connector/abstracts.py", line 1181, in connect
    self._open_connection()
  File "/home/donkami/.local/lib/python3.10/site-packages/mysql/connector/connection_cext.py", line 296, in _open_connection
    raise get_mysql_exception(
mysql.connector.errors.DatabaseError: 2005 (HY000): Unknown MySQL server host 'db' (-3)

2024-09-11 16:27:51,872 - ERROR - Error en la función `devnet_connection` en el archivo `db_connections`
2024-09-11 16:27:51,872 - ERROR - 2005 (HY000): Unknown MySQL server host 'db' (-3)
2024-09-11 16:27:51,872 - ERROR - Traceback (most recent call last):
  File "/home/donkami/Sona/devnet-candelaria/Services/Ups/db_get_data.py", line 32, in get_data
    raise ValueError("No se pudo establecer la conexión con la base de datos: el conector es None.")
ValueError: No se pudo establecer la conexión con la base de datos: el conector es None.

2024-09-11 16:27:51,872 - ERROR - No se pudo establecer la conexión con la base de datos: el conector es None.
2024-09-11 16:27:51,872 - ERROR - Error al obtener datos de la base de datos
2024-09-11 16:27:51,873 - ERROR - Traceback (most recent call last):
  File "/home/donkami/Sona/devnet-candelaria/Services/Ups/main.py", line 40, in main
    raise ValueError(
ValueError: No se pudo establecer la conexión con la base de datos: el conector es None.

2024-09-12 14:51:30,429 - ERROR - Traceback (most recent call last):
  File "/home/donkami/Sona/devnet-candelaria/Services/Devices/api_cisco.py", line 95, in get_cisco_data
    prtg_device_ip_url = os.getenv("URL_PRTG_IP").format(
KeyError: 'username'

2024-09-12 14:51:30,438 - ERROR - 'username'
2024-09-12 14:51:30,438 - ERROR - Error en la funcion `get_cisco_data` del archivo `api_cisco`
2024-09-12 14:51:30,438 - ERROR - Ip del emento que causo el error 10.225.8.21
2024-09-12 14:51:57,558 - ERROR - Traceback (most recent call last):
  File "/home/donkami/Sona/devnet-candelaria/Services/Devices/api_cisco.py", line 110, in get_cisco_data
    prtg_device_id_url = os.getenv("URL_PRTG_ID").format(
KeyError: 'username'

2024-09-12 14:51:57,559 - ERROR - 'username'
2024-09-12 14:51:57,559 - ERROR - Error en la funcion `get_cisco_data` del archivo `api_cisco`
2024-09-12 14:51:57,559 - ERROR - Ip del emento que causo el error 10.225.8.21
2024-09-12 14:52:50,577 - WARNING - Python-dotenv could not parse statement starting at line 8
2024-09-12 14:52:50,578 - WARNING - Python-dotenv could not parse statement starting at line 13
2024-09-12 14:52:50,578 - WARNING - Python-dotenv could not parse statement starting at line 15
2024-09-12 14:52:50,578 - WARNING - Python-dotenv could not parse statement starting at line 18
2024-09-12 14:52:50,578 - WARNING - Python-dotenv could not parse statement starting at line 19
2024-09-12 14:52:50,578 - WARNING - Python-dotenv could not parse statement starting at line 20
2024-09-12 14:52:50,578 - WARNING - Python-dotenv could not parse statement starting at line 21
2024-09-12 14:52:50,578 - WARNING - Python-dotenv could not parse statement starting at line 22
2024-09-12 14:52:50,578 - WARNING - Python-dotenv could not parse statement starting at line 23
2024-09-12 14:52:50,578 - WARNING - Python-dotenv could not parse statement starting at line 24
2024-09-12 14:52:50,578 - WARNING - Python-dotenv could not parse statement starting at line 28
2024-09-12 14:52:50,578 - WARNING - Python-dotenv could not parse statement starting at line 29
2024-09-12 14:52:50,579 - WARNING - Python-dotenv could not parse statement starting at line 30
2024-09-12 14:52:50,579 - WARNING - Python-dotenv could not parse statement starting at line 31
2024-09-12 14:52:50,581 - WARNING - Python-dotenv could not parse statement starting at line 8
2024-09-12 14:52:50,581 - WARNING - Python-dotenv could not parse statement starting at line 13
2024-09-12 14:52:50,581 - WARNING - Python-dotenv could not parse statement starting at line 15
2024-09-12 14:52:50,581 - WARNING - Python-dotenv could not parse statement starting at line 18
2024-09-12 14:52:50,581 - WARNING - Python-dotenv could not parse statement starting at line 19
2024-09-12 14:52:50,581 - WARNING - Python-dotenv could not parse statement starting at line 20
2024-09-12 14:52:50,581 - WARNING - Python-dotenv could not parse statement starting at line 21
2024-09-12 14:52:50,581 - WARNING - Python-dotenv could not parse statement starting at line 22
2024-09-12 14:52:50,581 - WARNING - Python-dotenv could not parse statement starting at line 23
2024-09-12 14:52:50,582 - WARNING - Python-dotenv could not parse statement starting at line 24
2024-09-12 14:52:50,582 - WARNING - Python-dotenv could not parse statement starting at line 28
2024-09-12 14:52:50,582 - WARNING - Python-dotenv could not parse statement starting at line 29
2024-09-12 14:52:50,582 - WARNING - Python-dotenv could not parse statement starting at line 30
2024-09-12 14:52:50,582 - WARNING - Python-dotenv could not parse statement starting at line 31
2024-09-12 14:52:55,662 - WARNING - Python-dotenv could not parse statement starting at line 8
2024-09-12 14:52:55,662 - WARNING - Python-dotenv could not parse statement starting at line 13
2024-09-12 14:52:55,662 - WARNING - Python-dotenv could not parse statement starting at line 15
2024-09-12 14:52:55,662 - WARNING - Python-dotenv could not parse statement starting at line 18
2024-09-12 14:52:55,662 - WARNING - Python-dotenv could not parse statement starting at line 19
2024-09-12 14:52:55,662 - WARNING - Python-dotenv could not parse statement starting at line 20
2024-09-12 14:52:55,663 - WARNING - Python-dotenv could not parse statement starting at line 21
2024-09-12 14:52:55,663 - WARNING - Python-dotenv could not parse statement starting at line 22
2024-09-12 14:52:55,663 - WARNING - Python-dotenv could not parse statement starting at line 23
2024-09-12 14:52:55,663 - WARNING - Python-dotenv could not parse statement starting at line 24
2024-09-12 14:52:55,663 - WARNING - Python-dotenv could not parse statement starting at line 28
2024-09-12 14:52:55,663 - WARNING - Python-dotenv could not parse statement starting at line 29
2024-09-12 14:52:55,663 - WARNING - Python-dotenv could not parse statement starting at line 30
2024-09-12 14:52:55,664 - WARNING - Python-dotenv could not parse statement starting at line 31
2024-09-12 14:52:55,665 - WARNING - Python-dotenv could not parse statement starting at line 8
2024-09-12 14:52:55,665 - WARNING - Python-dotenv could not parse statement starting at line 13
2024-09-12 14:52:55,665 - WARNING - Python-dotenv could not parse statement starting at line 15
2024-09-12 14:52:55,666 - WARNING - Python-dotenv could not parse statement starting at line 18
2024-09-12 14:52:55,666 - WARNING - Python-dotenv could not parse statement starting at line 19
2024-09-12 14:52:55,666 - WARNING - Python-dotenv could not parse statement starting at line 20
2024-09-12 14:52:55,666 - WARNING - Python-dotenv could not parse statement starting at line 21
2024-09-12 14:52:55,666 - WARNING - Python-dotenv could not parse statement starting at line 22
2024-09-12 14:52:55,666 - WARNING - Python-dotenv could not parse statement starting at line 23
2024-09-12 14:52:55,666 - WARNING - Python-dotenv could not parse statement starting at line 24
2024-09-12 14:52:55,666 - WARNING - Python-dotenv could not parse statement starting at line 28
2024-09-12 14:52:55,666 - WARNING - Python-dotenv could not parse statement starting at line 29
2024-09-12 14:52:55,666 - WARNING - Python-dotenv could not parse statement starting at line 30
2024-09-12 14:52:55,666 - WARNING - Python-dotenv could not parse statement starting at line 31
2024-09-12 14:58:16,988 - ERROR - Traceback (most recent call last):
  File "/home/donkami/.local/lib/python3.10/site-packages/requests/models.py", line 971, in json
    return complexjson.loads(self.text, **kwargs)
  File "/usr/lib/python3.10/json/__init__.py", line 346, in loads
    return _default_decoder.decode(s)
  File "/usr/lib/python3.10/json/decoder.py", line 337, in decode
    obj, end = self.raw_decode(s, idx=_w(s, 0).end())
  File "/usr/lib/python3.10/json/decoder.py", line 355, in raw_decode
    raise JSONDecodeError("Expecting value", s, err.value) from None
json.decoder.JSONDecodeError: Expecting value: line 1 column 1 (char 0)

During handling of the above exception, another exception occurred:

Traceback (most recent call last):
  File "/home/donkami/Sona/devnet-candelaria/Services/Devices/api_cisco.py", line 59, in get_cisco_data
    response_cisco_get_id = requests.get(URL_CISCO_GET_ID, verify=False).json()
  File "/home/donkami/.local/lib/python3.10/site-packages/requests/models.py", line 975, in json
    raise RequestsJSONDecodeError(e.msg, e.doc, e.pos)
requests.exceptions.JSONDecodeError: Expecting value: line 1 column 1 (char 0)

2024-09-12 14:58:16,989 - ERROR - Expecting value: line 1 column 1 (char 0)
2024-09-12 14:58:16,989 - ERROR - Error en la funcion `get_cisco_data` del archivo `api_cisco`
2024-09-12 14:58:16,989 - ERROR - Ip del emento que causo el error 10.225.8.21
2024-09-12 14:58:32,227 - ERROR - Traceback (most recent call last):
  File "/home/donkami/.local/lib/python3.10/site-packages/requests/models.py", line 971, in json
    return complexjson.loads(self.text, **kwargs)
  File "/usr/lib/python3.10/json/__init__.py", line 346, in loads
    return _default_decoder.decode(s)
  File "/usr/lib/python3.10/json/decoder.py", line 337, in decode
    obj, end = self.raw_decode(s, idx=_w(s, 0).end())
  File "/usr/lib/python3.10/json/decoder.py", line 355, in raw_decode
    raise JSONDecodeError("Expecting value", s, err.value) from None
json.decoder.JSONDecodeError: Expecting value: line 1 column 1 (char 0)

During handling of the above exception, another exception occurred:

Traceback (most recent call last):
  File "/home/donkami/Sona/devnet-candelaria/Services/Devices/api_cisco.py", line 59, in get_cisco_data
    response_cisco_get_id = requests.get(URL_CISCO_GET_ID, verify=False).json()
  File "/home/donkami/.local/lib/python3.10/site-packages/requests/models.py", line 975, in json
    raise RequestsJSONDecodeError(e.msg, e.doc, e.pos)
requests.exceptions.JSONDecodeError: Expecting value: line 1 column 1 (char 0)

2024-09-12 14:58:32,228 - ERROR - Expecting value: line 1 column 1 (char 0)
2024-09-12 14:58:32,228 - ERROR - Error en la funcion `get_cisco_data` del archivo `api_cisco`
2024-09-12 14:58:32,228 - ERROR - Ip del emento que causo el error 10.225.8.21
2024-09-12 16:23:57,382 - ERROR - Traceback (most recent call last):
  File "/home/donkami/Sona/devnet-candelaria/Services/Devices/api_cisco.py", line 59, in get_cisco_data
    URL_CISCO_GET_ID = os.getenv("URL_CISCO_IP").format(
KeyError: 'cisco_password'

2024-09-12 16:23:57,382 - ERROR - 'cisco_password'
2024-09-12 16:23:57,383 - ERROR - Error en la funcion `get_cisco_data` del archivo `api_cisco`
2024-09-12 16:23:57,383 - ERROR - Ip del emento que causo el error 10.225.8.21
2024-09-12 16:26:02,281 - ERROR - Traceback (most recent call last):
  File "/home/donkami/.local/lib/python3.10/site-packages/requests/models.py", line 971, in json
    return complexjson.loads(self.text, **kwargs)
  File "/usr/lib/python3.10/json/__init__.py", line 346, in loads
    return _default_decoder.decode(s)
  File "/usr/lib/python3.10/json/decoder.py", line 337, in decode
    obj, end = self.raw_decode(s, idx=_w(s, 0).end())
  File "/usr/lib/python3.10/json/decoder.py", line 355, in raw_decode
    raise JSONDecodeError("Expecting value", s, err.value) from None
json.decoder.JSONDecodeError: Expecting value: line 1 column 1 (char 0)

During handling of the above exception, another exception occurred:

Traceback (most recent call last):
  File "/home/donkami/Sona/devnet-candelaria/Services/Devices/api_cisco.py", line 83, in get_cisco_data
    cisco_client_response = requests.get(URL_CISCO_ID, verify=False).json()
  File "/home/donkami/.local/lib/python3.10/site-packages/requests/models.py", line 975, in json
    raise RequestsJSONDecodeError(e.msg, e.doc, e.pos)
requests.exceptions.JSONDecodeError: Expecting value: line 1 column 1 (char 0)

2024-09-12 16:26:02,281 - ERROR - Expecting value: line 1 column 1 (char 0)
2024-09-12 16:26:02,281 - ERROR - Error en la funcion `get_cisco_data` del archivo `api_cisco`
2024-09-12 16:26:02,281 - ERROR - Ip del emento que causo el error 10.225.8.21
Traceback (most recent call last):
  File "/home/donkami/.local/lib/python3.10/site-packages/mysql/connector/connection_cext.py", line 291, in _open_connection
    self._cmysql.connect(**cnx_kwargs)
_mysql_connector.MySQLInterfaceError: Access denied for user 'donkami'@'172.18.0.1' (using password: NO)

The above exception was the direct cause of the following exception:

Traceback (most recent call last):
  File "/home/donkami/Sona/devnet-candelaria/Services/Anillo_Opit/db_connection.py", line 29, in devnet_connection
    db_connector = mysql.connector.connect(
  File "/home/donkami/.local/lib/python3.10/site-packages/mysql/connector/pooling.py", line 293, in connect
    return CMySQLConnection(*args, **kwargs)
  File "/home/donkami/.local/lib/python3.10/site-packages/mysql/connector/connection_cext.py", line 120, in __init__
    self.connect(**kwargs)
  File "/home/donkami/.local/lib/python3.10/site-packages/mysql/connector/abstracts.py", line 1181, in connect
    self._open_connection()
  File "/home/donkami/.local/lib/python3.10/site-packages/mysql/connector/connection_cext.py", line 296, in _open_connection
    raise get_mysql_exception(
mysql.connector.errors.ProgrammingError: 1045 (28000): Access denied for user 'donkami'@'172.18.0.1' (using password: NO)

Error en la función `devnet_connection` en el archivo `db_connections`
1045 (28000): Access denied for user 'donkami'@'172.18.0.1' (using password: NO)
No se pudo establecer la conexión con la base de datos: el conector es None.
Traceback (most recent call last):
  File "/home/donkami/Sona/devnet-candelaria/Services/Anillo_Opit/db_get_data.py", line 31, in get_devnet_data
    raise ValueError("No se pudo establecer la conexión con la base de datos: el conector es None.")
ValueError: No se pudo establecer la conexión con la base de datos: el conector es None.

Error al obtener datos de la base de datos
Error en la funcion `get_data` en el archivo `get_data`
Traceback (most recent call last):
  File "/home/donkami/Sona/devnet-candelaria/Services/Anillo_Opit/main.py", line 29, in main
    id_device_set = {item['id_device'] for item in db_devnet_data}
TypeError: 'NoneType' object is not iterable

During handling of the above exception, another exception occurred:

Traceback (most recent call last):
  File "/home/donkami/.local/lib/python3.10/site-packages/mysql/connector/connection_cext.py", line 291, in _open_connection
    self._cmysql.connect(**cnx_kwargs)
_mysql_connector.MySQLInterfaceError: Access denied for user 'donkami'@'172.18.0.1' (using password: NO)

The above exception was the direct cause of the following exception:

Traceback (most recent call last):
  File "/home/donkami/Sona/devnet-candelaria/Services/Anillo_Opit/db_connection.py", line 29, in devnet_connection
    db_connector = mysql.connector.connect(
  File "/home/donkami/.local/lib/python3.10/site-packages/mysql/connector/pooling.py", line 293, in connect
    return CMySQLConnection(*args, **kwargs)
  File "/home/donkami/.local/lib/python3.10/site-packages/mysql/connector/connection_cext.py", line 120, in __init__
    self.connect(**kwargs)
  File "/home/donkami/.local/lib/python3.10/site-packages/mysql/connector/abstracts.py", line 1181, in connect
    self._open_connection()
  File "/home/donkami/.local/lib/python3.10/site-packages/mysql/connector/connection_cext.py", line 296, in _open_connection
    raise get_mysql_exception(
mysql.connector.errors.ProgrammingError: 1045 (28000): Access denied for user 'donkami'@'172.18.0.1' (using password: NO)

Error en la función `devnet_connection` en el archivo `db_connections`
1045 (28000): Access denied for user 'donkami'@'172.18.0.1' (using password: NO)
Traceback (most recent call last):
  File "/home/donkami/Sona/devnet-candelaria/Services/Anillo_Opit/main.py", line 29, in main
    id_device_set = {item['id_device'] for item in db_devnet_data}
TypeError: 'NoneType' object is not iterable

During handling of the above exception, another exception occurred:

Traceback (most recent call last):
  File "/home/donkami/Sona/devnet-candelaria/Services/Anillo_Opit/db_update.py", line 87, in datetime_register
    devnet_cursor = db_connector.cursor()
AttributeError: 'NoneType' object has no attribute 'cursor'

Error en la función `datetime_register` en el archivo `db_update_devnet`
'NoneType' object has no attribute 'cursor'
Traceback (most recent call last):
  File "/home/donkami/Sona/devnet-candelaria/Services/Anillo_Opit/main.py", line 29, in main
    id_device_set = {item['id_device'] for item in db_devnet_data}
TypeError: 'NoneType' object is not iterable

'NoneType' object is not iterable
Error en la funcion `main` del archivo `main`
Traceback (most recent call last):
  File "/home/donkami/.local/lib/python3.10/site-packages/mysql/connector/connection_cext.py", line 291, in _open_connection
    self._cmysql.connect(**cnx_kwargs)
_mysql_connector.MySQLInterfaceError: Access denied for user 'donkami'@'172.18.0.1' (using password: NO)

The above exception was the direct cause of the following exception:

Traceback (most recent call last):
  File "/home/donkami/Sona/devnet-candelaria/Services/Anillo_Opit/db_connection.py", line 29, in devnet_connection
    db_connector = mysql.connector.connect(
  File "/home/donkami/.local/lib/python3.10/site-packages/mysql/connector/pooling.py", line 293, in connect
    return CMySQLConnection(*args, **kwargs)
  File "/home/donkami/.local/lib/python3.10/site-packages/mysql/connector/connection_cext.py", line 120, in __init__
    self.connect(**kwargs)
  File "/home/donkami/.local/lib/python3.10/site-packages/mysql/connector/abstracts.py", line 1181, in connect
    self._open_connection()
  File "/home/donkami/.local/lib/python3.10/site-packages/mysql/connector/connection_cext.py", line 296, in _open_connection
    raise get_mysql_exception(
mysql.connector.errors.ProgrammingError: 1045 (28000): Access denied for user 'donkami'@'172.18.0.1' (using password: NO)

Error en la función `devnet_connection` en el archivo `db_connections`
1045 (28000): Access denied for user 'donkami'@'172.18.0.1' (using password: NO)
No se pudo establecer la conexión con la base de datos: el conector es None.
Traceback (most recent call last):
  File "/home/donkami/Sona/devnet-candelaria/Services/Anillo_Opit/db_get_data.py", line 31, in get_devnet_data
    raise ValueError("No se pudo establecer la conexión con la base de datos: el conector es None.")
ValueError: No se pudo establecer la conexión con la base de datos: el conector es None.

Error al obtener datos de la base de datos
Error en la funcion `get_data` en el archivo `get_data`
Traceback (most recent call last):
  File "/home/donkami/Sona/devnet-candelaria/Services/Anillo_Opit/main.py", line 22, in main
    id_device_set = {item['id_device'] for item in db_devnet_data}
TypeError: 'NoneType' object is not iterable

During handling of the above exception, another exception occurred:

Traceback (most recent call last):
  File "/home/donkami/.local/lib/python3.10/site-packages/mysql/connector/connection_cext.py", line 291, in _open_connection
    self._cmysql.connect(**cnx_kwargs)
_mysql_connector.MySQLInterfaceError: Access denied for user 'donkami'@'172.18.0.1' (using password: NO)

The above exception was the direct cause of the following exception:

Traceback (most recent call last):
  File "/home/donkami/Sona/devnet-candelaria/Services/Anillo_Opit/db_connection.py", line 29, in devnet_connection
    db_connector = mysql.connector.connect(
  File "/home/donkami/.local/lib/python3.10/site-packages/mysql/connector/pooling.py", line 293, in connect
    return CMySQLConnection(*args, **kwargs)
  File "/home/donkami/.local/lib/python3.10/site-packages/mysql/connector/connection_cext.py", line 120, in __init__
    self.connect(**kwargs)
  File "/home/donkami/.local/lib/python3.10/site-packages/mysql/connector/abstracts.py", line 1181, in connect
    self._open_connection()
  File "/home/donkami/.local/lib/python3.10/site-packages/mysql/connector/connection_cext.py", line 296, in _open_connection
    raise get_mysql_exception(
mysql.connector.errors.ProgrammingError: 1045 (28000): Access denied for user 'donkami'@'172.18.0.1' (using password: NO)

Error en la función `devnet_connection` en el archivo `db_connections`
1045 (28000): Access denied for user 'donkami'@'172.18.0.1' (using password: NO)
Traceback (most recent call last):
  File "/home/donkami/Sona/devnet-candelaria/Services/Anillo_Opit/main.py", line 22, in main
    id_device_set = {item['id_device'] for item in db_devnet_data}
TypeError: 'NoneType' object is not iterable

During handling of the above exception, another exception occurred:

Traceback (most recent call last):
  File "/home/donkami/Sona/devnet-candelaria/Services/Anillo_Opit/db_update.py", line 87, in datetime_register
    devnet_cursor = db_connector.cursor()
AttributeError: 'NoneType' object has no attribute 'cursor'

Error en la función `datetime_register` en el archivo `db_update_devnet`
'NoneType' object has no attribute 'cursor'
Traceback (most recent call last):
  File "/home/donkami/Sona/devnet-candelaria/Services/Anillo_Opit/main.py", line 22, in main
    id_device_set = {item['id_device'] for item in db_devnet_data}
TypeError: 'NoneType' object is not iterable

'NoneType' object is not iterable
Error en la funcion `main` del archivo `main`
2024-09-13 12:58:57,254 - ERROR - Traceback (most recent call last):
  File "/home/donkami/.local/lib/python3.10/site-packages/mysql/connector/connection_cext.py", line 291, in _open_connection
    self._cmysql.connect(**cnx_kwargs)
_mysql_connector.MySQLInterfaceError: Access denied for user 'devnet'@'10.225.21.2' (using password: YES)

The above exception was the direct cause of the following exception:

Traceback (most recent call last):
  File "/home/donkami/Sona/devnet-candelaria/Services/Wan/db_connections.py", line 54, in historic_connection
    db_connector = mysql.connector.connect(
  File "/home/donkami/.local/lib/python3.10/site-packages/mysql/connector/pooling.py", line 293, in connect
    return CMySQLConnection(*args, **kwargs)
  File "/home/donkami/.local/lib/python3.10/site-packages/mysql/connector/connection_cext.py", line 120, in __init__
    self.connect(**kwargs)
  File "/home/donkami/.local/lib/python3.10/site-packages/mysql/connector/abstracts.py", line 1181, in connect
    self._open_connection()
  File "/home/donkami/.local/lib/python3.10/site-packages/mysql/connector/connection_cext.py", line 296, in _open_connection
    raise get_mysql_exception(
mysql.connector.errors.ProgrammingError: 1045 (28000): Access denied for user 'devnet'@'10.225.21.2' (using password: YES)

2024-09-13 12:58:57,255 - ERROR - Error en la función `historic_connection` en el archivo `db_connections`
2024-09-13 12:58:57,255 - ERROR - 1045 (28000): Access denied for user 'devnet'@'10.225.21.2' (using password: YES)
2024-09-13 12:58:57,265 - ERROR - Traceback (most recent call last):
  File "/home/donkami/.local/lib/python3.10/site-packages/mysql/connector/connection_cext.py", line 291, in _open_connection
    self._cmysql.connect(**cnx_kwargs)
_mysql_connector.MySQLInterfaceError: Unknown database 'devnet'

The above exception was the direct cause of the following exception:

Traceback (most recent call last):
  File "/home/donkami/Sona/devnet-candelaria/Services/Wan/db_connections.py", line 28, in devnet_connection
    db_connector = mysql.connector.connect(
  File "/home/donkami/.local/lib/python3.10/site-packages/mysql/connector/pooling.py", line 293, in connect
    return CMySQLConnection(*args, **kwargs)
  File "/home/donkami/.local/lib/python3.10/site-packages/mysql/connector/connection_cext.py", line 120, in __init__
    self.connect(**kwargs)
  File "/home/donkami/.local/lib/python3.10/site-packages/mysql/connector/abstracts.py", line 1181, in connect
    self._open_connection()
  File "/home/donkami/.local/lib/python3.10/site-packages/mysql/connector/connection_cext.py", line 296, in _open_connection
    raise get_mysql_exception(
mysql.connector.errors.ProgrammingError: 1049 (42000): Unknown database 'devnet'

2024-09-13 12:58:57,265 - ERROR - Error en la función `devnet_connection` en el archivo `db_connections`
2024-09-13 12:58:57,265 - ERROR - 1049 (42000): Unknown database 'devnet'
2024-09-13 12:58:57,265 - ERROR - Traceback (most recent call last):
  File "/home/donkami/Sona/devnet-candelaria/Services/Wan/db_get_data.py", line 32, in get_data
    raise ValueError("No se pudo establecer la conexión con la base de datos: el conector es None.")
ValueError: No se pudo establecer la conexión con la base de datos: el conector es None.

2024-09-13 12:58:57,265 - ERROR - No se pudo establecer la conexión con la base de datos: el conector es None.
2024-09-13 12:58:57,265 - ERROR - Error al obtener datos de la base de datos
2024-09-13 12:58:57,266 - ERROR - TRAZABILIDAD: Traceback (most recent call last):
  File "/home/donkami/Sona/devnet-candelaria/Services/Wan/main.py", line 31, in main
    for wan in wanList:
TypeError: 'NoneType' object is not iterable

2024-09-13 12:58:57,266 - ERROR - Error: 'NoneType' object is not iterable
2024-09-13 13:01:12,876 - ERROR - Traceback (most recent call last):
  File "/home/donkami/.local/lib/python3.10/site-packages/mysql/connector/connection_cext.py", line 291, in _open_connection
    self._cmysql.connect(**cnx_kwargs)
_mysql_connector.MySQLInterfaceError: Access denied for user 'devnet'@'10.225.21.2' (using password: YES)

The above exception was the direct cause of the following exception:

Traceback (most recent call last):
  File "/home/donkami/Sona/devnet-candelaria/Services/Wan/db_connections.py", line 54, in historic_connection
    db_connector = mysql.connector.connect(
  File "/home/donkami/.local/lib/python3.10/site-packages/mysql/connector/pooling.py", line 293, in connect
    return CMySQLConnection(*args, **kwargs)
  File "/home/donkami/.local/lib/python3.10/site-packages/mysql/connector/connection_cext.py", line 120, in __init__
    self.connect(**kwargs)
  File "/home/donkami/.local/lib/python3.10/site-packages/mysql/connector/abstracts.py", line 1181, in connect
    self._open_connection()
  File "/home/donkami/.local/lib/python3.10/site-packages/mysql/connector/connection_cext.py", line 296, in _open_connection
    raise get_mysql_exception(
mysql.connector.errors.ProgrammingError: 1045 (28000): Access denied for user 'devnet'@'10.225.21.2' (using password: YES)

2024-09-13 13:01:12,876 - ERROR - Error en la función `historic_connection` en el archivo `db_connections`
2024-09-13 13:01:12,877 - ERROR - 1045 (28000): Access denied for user 'devnet'@'10.225.21.2' (using password: YES)
2024-09-13 13:01:12,886 - ERROR - Traceback (most recent call last):
  File "/home/donkami/Sona/devnet-candelaria/Services/Wan/api_prtg.py", line 62, in get_prtg_data
    device_id_url = os.getenv("URL_PRTG_GET_ID_WITH_IP").format(ip=ip_wan)
KeyError: 'username'

2024-09-13 13:01:12,886 - ERROR - 'username'
2024-09-13 13:01:12,886 - ERROR - Error en la funcion get_prtg_data en el archivo api_prtg 10.224.126.89
2024-09-13 13:01:12,887 - ERROR - Traceback (most recent call last):
  File "/home/donkami/Sona/devnet-candelaria/Services/Wan/api_prtg.py", line 62, in get_prtg_data
    device_id_url = os.getenv("URL_PRTG_GET_ID_WITH_IP").format(ip=ip_wan)
KeyError: 'username'

2024-09-13 13:01:12,887 - ERROR - 'username'
2024-09-13 13:01:12,887 - ERROR - Error en la funcion get_prtg_data en el archivo api_prtg 10.224.126.93
2024-09-13 13:01:12,887 - ERROR - Traceback (most recent call last):
  File "/home/donkami/Sona/devnet-candelaria/Services/Wan/api_prtg.py", line 62, in get_prtg_data
    device_id_url = os.getenv("URL_PRTG_GET_ID_WITH_IP").format(ip=ip_wan)
KeyError: 'username'

2024-09-13 13:01:12,887 - ERROR - 'username'
2024-09-13 13:01:12,887 - ERROR - Error en la funcion get_prtg_data en el archivo api_prtg 10.224.126.97
2024-09-13 13:01:12,887 - ERROR - Traceback (most recent call last):
  File "/home/donkami/Sona/devnet-candelaria/Services/Wan/api_prtg.py", line 62, in get_prtg_data
    device_id_url = os.getenv("URL_PRTG_GET_ID_WITH_IP").format(ip=ip_wan)
KeyError: 'username'

2024-09-13 13:01:12,887 - ERROR - 'username'
2024-09-13 13:01:12,887 - ERROR - Error en la funcion get_prtg_data en el archivo api_prtg 10.220.15.1
2024-09-13 13:01:12,887 - ERROR - Traceback (most recent call last):
  File "/home/donkami/Sona/devnet-candelaria/Services/Wan/api_prtg.py", line 62, in get_prtg_data
    device_id_url = os.getenv("URL_PRTG_GET_ID_WITH_IP").format(ip=ip_wan)
KeyError: 'username'

2024-09-13 13:01:12,888 - ERROR - 'username'
2024-09-13 13:01:12,888 - ERROR - Error en la funcion get_prtg_data en el archivo api_prtg 10.224.15.1
2024-09-13 13:01:12,888 - ERROR - Traceback (most recent call last):
  File "/home/donkami/Sona/devnet-candelaria/Services/Wan/api_prtg.py", line 62, in get_prtg_data
    device_id_url = os.getenv("URL_PRTG_GET_ID_WITH_IP").format(ip=ip_wan)
KeyError: 'username'

2024-09-13 13:01:12,888 - ERROR - 'username'
2024-09-13 13:01:12,888 - ERROR - Error en la funcion get_prtg_data en el archivo api_prtg 10.224.17.1
2024-09-13 13:01:12,888 - ERROR - Traceback (most recent call last):
  File "/home/donkami/Sona/devnet-candelaria/Services/Wan/api_prtg.py", line 62, in get_prtg_data
    device_id_url = os.getenv("URL_PRTG_GET_ID_WITH_IP").format(ip=ip_wan)
KeyError: 'username'

2024-09-13 13:01:12,888 - ERROR - 'username'
2024-09-13 13:01:12,888 - ERROR - Error en la funcion get_prtg_data en el archivo api_prtg 10.224.23.1
2024-09-13 13:01:12,888 - ERROR - Traceback (most recent call last):
  File "/home/donkami/Sona/devnet-candelaria/Services/Wan/api_prtg.py", line 62, in get_prtg_data
    device_id_url = os.getenv("URL_PRTG_GET_ID_WITH_IP").format(ip=ip_wan)
KeyError: 'username'

2024-09-13 13:01:12,888 - ERROR - 'username'
2024-09-13 13:01:12,888 - ERROR - Error en la funcion get_prtg_data en el archivo api_prtg 10.232.0.12
2024-09-13 13:01:12,888 - ERROR - Traceback (most recent call last):
  File "/home/donkami/Sona/devnet-candelaria/Services/Wan/api_prtg.py", line 62, in get_prtg_data
    device_id_url = os.getenv("URL_PRTG_GET_ID_WITH_IP").format(ip=ip_wan)
KeyError: 'username'

2024-09-13 13:01:12,889 - ERROR - 'username'
2024-09-13 13:01:12,889 - ERROR - Error en la funcion get_prtg_data en el archivo api_prtg 10.224.21.1
2024-09-13 13:01:12,889 - ERROR - Traceback (most recent call last):
  File "/home/donkami/Sona/devnet-candelaria/Services/Wan/api_prtg.py", line 62, in get_prtg_data
    device_id_url = os.getenv("URL_PRTG_GET_ID_WITH_IP").format(ip=ip_wan)
KeyError: 'username'

2024-09-13 13:01:12,889 - ERROR - 'username'
2024-09-13 13:01:12,889 - ERROR - Error en la funcion get_prtg_data en el archivo api_prtg 10.224.127.11
2024-09-13 13:01:43,911 - ERROR - Traceback (most recent call last):
  File "/home/donkami/.local/lib/python3.10/site-packages/mysql/connector/connection_cext.py", line 291, in _open_connection
    self._cmysql.connect(**cnx_kwargs)
_mysql_connector.MySQLInterfaceError: Access denied for user 'devnet'@'10.225.21.2' (using password: YES)

The above exception was the direct cause of the following exception:

Traceback (most recent call last):
  File "/home/donkami/Sona/devnet-candelaria/Services/Wan/db_connections.py", line 54, in historic_connection
    db_connector = mysql.connector.connect(
  File "/home/donkami/.local/lib/python3.10/site-packages/mysql/connector/pooling.py", line 293, in connect
    return CMySQLConnection(*args, **kwargs)
  File "/home/donkami/.local/lib/python3.10/site-packages/mysql/connector/connection_cext.py", line 120, in __init__
    self.connect(**kwargs)
  File "/home/donkami/.local/lib/python3.10/site-packages/mysql/connector/abstracts.py", line 1181, in connect
    self._open_connection()
  File "/home/donkami/.local/lib/python3.10/site-packages/mysql/connector/connection_cext.py", line 296, in _open_connection
    raise get_mysql_exception(
mysql.connector.errors.ProgrammingError: 1045 (28000): Access denied for user 'devnet'@'10.225.21.2' (using password: YES)

2024-09-13 13:01:43,912 - ERROR - Error en la función `historic_connection` en el archivo `db_connections`
2024-09-13 13:01:43,912 - ERROR - 1045 (28000): Access denied for user 'devnet'@'10.225.21.2' (using password: YES)
2024-09-13 13:01:43,922 - ERROR - Traceback (most recent call last):
  File "/home/donkami/Sona/devnet-candelaria/Services/Wan/api_prtg.py", line 62, in get_prtg_data
    device_id_url = os.getenv("URL_PRTG_GET_ID_WITH_IP").format(ip=ip_wan)
KeyError: 'username'

2024-09-13 13:01:43,922 - ERROR - 'username'
2024-09-13 13:01:43,922 - ERROR - Error en la funcion get_prtg_data en el archivo api_prtg 10.224.126.89
2024-09-13 13:01:43,922 - ERROR - Traceback (most recent call last):
  File "/home/donkami/Sona/devnet-candelaria/Services/Wan/api_prtg.py", line 62, in get_prtg_data
    device_id_url = os.getenv("URL_PRTG_GET_ID_WITH_IP").format(ip=ip_wan)
KeyError: 'username'

2024-09-13 13:01:43,922 - ERROR - 'username'
2024-09-13 13:01:43,923 - ERROR - Error en la funcion get_prtg_data en el archivo api_prtg 10.224.126.93
2024-09-13 13:01:43,923 - ERROR - Traceback (most recent call last):
  File "/home/donkami/Sona/devnet-candelaria/Services/Wan/api_prtg.py", line 62, in get_prtg_data
    device_id_url = os.getenv("URL_PRTG_GET_ID_WITH_IP").format(ip=ip_wan)
KeyError: 'username'

2024-09-13 13:01:43,923 - ERROR - 'username'
2024-09-13 13:01:43,923 - ERROR - Error en la funcion get_prtg_data en el archivo api_prtg 10.224.126.97
2024-09-13 13:01:43,923 - ERROR - Traceback (most recent call last):
  File "/home/donkami/Sona/devnet-candelaria/Services/Wan/api_prtg.py", line 62, in get_prtg_data
    device_id_url = os.getenv("URL_PRTG_GET_ID_WITH_IP").format(ip=ip_wan)
KeyError: 'username'

2024-09-13 13:01:43,923 - ERROR - 'username'
2024-09-13 13:01:43,923 - ERROR - Error en la funcion get_prtg_data en el archivo api_prtg 10.220.15.1
2024-09-13 13:01:43,923 - ERROR - Traceback (most recent call last):
  File "/home/donkami/Sona/devnet-candelaria/Services/Wan/api_prtg.py", line 62, in get_prtg_data
    device_id_url = os.getenv("URL_PRTG_GET_ID_WITH_IP").format(ip=ip_wan)
KeyError: 'username'

2024-09-13 13:01:43,923 - ERROR - 'username'
2024-09-13 13:01:43,923 - ERROR - Error en la funcion get_prtg_data en el archivo api_prtg 10.224.15.1
2024-09-13 13:01:43,924 - ERROR - Traceback (most recent call last):
  File "/home/donkami/Sona/devnet-candelaria/Services/Wan/api_prtg.py", line 62, in get_prtg_data
    device_id_url = os.getenv("URL_PRTG_GET_ID_WITH_IP").format(ip=ip_wan)
KeyError: 'username'

2024-09-13 13:01:43,924 - ERROR - 'username'
2024-09-13 13:01:43,924 - ERROR - Error en la funcion get_prtg_data en el archivo api_prtg 10.224.17.1
2024-09-13 13:01:43,924 - ERROR - Traceback (most recent call last):
  File "/home/donkami/Sona/devnet-candelaria/Services/Wan/api_prtg.py", line 62, in get_prtg_data
    device_id_url = os.getenv("URL_PRTG_GET_ID_WITH_IP").format(ip=ip_wan)
KeyError: 'username'

2024-09-13 13:01:43,924 - ERROR - 'username'
2024-09-13 13:01:43,924 - ERROR - Error en la funcion get_prtg_data en el archivo api_prtg 10.224.23.1
2024-09-13 13:01:43,924 - ERROR - Traceback (most recent call last):
  File "/home/donkami/Sona/devnet-candelaria/Services/Wan/api_prtg.py", line 62, in get_prtg_data
    device_id_url = os.getenv("URL_PRTG_GET_ID_WITH_IP").format(ip=ip_wan)
KeyError: 'username'

2024-09-13 13:01:43,924 - ERROR - 'username'
2024-09-13 13:01:43,924 - ERROR - Error en la funcion get_prtg_data en el archivo api_prtg 10.232.0.12
2024-09-13 13:01:43,924 - ERROR - Traceback (most recent call last):
  File "/home/donkami/Sona/devnet-candelaria/Services/Wan/api_prtg.py", line 62, in get_prtg_data
    device_id_url = os.getenv("URL_PRTG_GET_ID_WITH_IP").format(ip=ip_wan)
KeyError: 'username'

2024-09-13 13:01:43,924 - ERROR - 'username'
2024-09-13 13:01:43,925 - ERROR - Error en la funcion get_prtg_data en el archivo api_prtg 10.224.21.1
2024-09-13 13:01:43,925 - ERROR - Traceback (most recent call last):
  File "/home/donkami/Sona/devnet-candelaria/Services/Wan/api_prtg.py", line 62, in get_prtg_data
    device_id_url = os.getenv("URL_PRTG_GET_ID_WITH_IP").format(ip=ip_wan)
KeyError: 'username'

2024-09-13 13:01:43,925 - ERROR - 'username'
2024-09-13 13:01:43,925 - ERROR - Error en la funcion get_prtg_data en el archivo api_prtg 10.224.127.11
2024-09-13 13:02:53,467 - ERROR - Traceback (most recent call last):
  File "/home/donkami/Sona/devnet-candelaria/Services/Wan/api_prtg.py", line 62, in get_prtg_data
    device_id_url = os.getenv("URL_PRTG_GET_ID_WITH_IP").format(ip=ip_wan)
KeyError: 'username'

2024-09-13 13:02:53,468 - ERROR - 'username'
2024-09-13 13:02:53,468 - ERROR - Error en la funcion get_prtg_data en el archivo api_prtg 10.224.126.89
2024-09-13 13:02:53,468 - ERROR - Traceback (most recent call last):
  File "/home/donkami/Sona/devnet-candelaria/Services/Wan/api_prtg.py", line 62, in get_prtg_data
    device_id_url = os.getenv("URL_PRTG_GET_ID_WITH_IP").format(ip=ip_wan)
KeyError: 'username'

2024-09-13 13:02:53,468 - ERROR - 'username'
2024-09-13 13:02:53,468 - ERROR - Error en la funcion get_prtg_data en el archivo api_prtg 10.224.126.93
2024-09-13 13:02:53,468 - ERROR - Traceback (most recent call last):
  File "/home/donkami/Sona/devnet-candelaria/Services/Wan/api_prtg.py", line 62, in get_prtg_data
    device_id_url = os.getenv("URL_PRTG_GET_ID_WITH_IP").format(ip=ip_wan)
KeyError: 'username'

2024-09-13 13:02:53,468 - ERROR - 'username'
2024-09-13 13:02:53,468 - ERROR - Error en la funcion get_prtg_data en el archivo api_prtg 10.224.126.97
2024-09-13 13:02:53,469 - ERROR - Traceback (most recent call last):
  File "/home/donkami/Sona/devnet-candelaria/Services/Wan/api_prtg.py", line 62, in get_prtg_data
    device_id_url = os.getenv("URL_PRTG_GET_ID_WITH_IP").format(ip=ip_wan)
KeyError: 'username'

2024-09-13 13:02:53,469 - ERROR - 'username'
2024-09-13 13:02:53,469 - ERROR - Error en la funcion get_prtg_data en el archivo api_prtg 10.220.15.1
2024-09-13 13:02:53,469 - ERROR - Traceback (most recent call last):
  File "/home/donkami/Sona/devnet-candelaria/Services/Wan/api_prtg.py", line 62, in get_prtg_data
    device_id_url = os.getenv("URL_PRTG_GET_ID_WITH_IP").format(ip=ip_wan)
KeyError: 'username'

2024-09-13 13:02:53,469 - ERROR - 'username'
2024-09-13 13:02:53,469 - ERROR - Error en la funcion get_prtg_data en el archivo api_prtg 10.224.15.1
2024-09-13 13:02:53,469 - ERROR - Traceback (most recent call last):
  File "/home/donkami/Sona/devnet-candelaria/Services/Wan/api_prtg.py", line 62, in get_prtg_data
    device_id_url = os.getenv("URL_PRTG_GET_ID_WITH_IP").format(ip=ip_wan)
KeyError: 'username'

2024-09-13 13:02:53,469 - ERROR - 'username'
2024-09-13 13:02:53,469 - ERROR - Error en la funcion get_prtg_data en el archivo api_prtg 10.224.17.1
2024-09-13 13:02:53,469 - ERROR - Traceback (most recent call last):
  File "/home/donkami/Sona/devnet-candelaria/Services/Wan/api_prtg.py", line 62, in get_prtg_data
    device_id_url = os.getenv("URL_PRTG_GET_ID_WITH_IP").format(ip=ip_wan)
KeyError: 'username'

2024-09-13 13:02:53,469 - ERROR - 'username'
2024-09-13 13:02:53,469 - ERROR - Error en la funcion get_prtg_data en el archivo api_prtg 10.224.23.1
2024-09-13 13:02:53,470 - ERROR - Traceback (most recent call last):
  File "/home/donkami/Sona/devnet-candelaria/Services/Wan/api_prtg.py", line 62, in get_prtg_data
    device_id_url = os.getenv("URL_PRTG_GET_ID_WITH_IP").format(ip=ip_wan)
KeyError: 'username'

2024-09-13 13:02:53,470 - ERROR - 'username'
2024-09-13 13:02:53,470 - ERROR - Error en la funcion get_prtg_data en el archivo api_prtg 10.232.0.12
2024-09-13 13:02:53,470 - ERROR - Traceback (most recent call last):
  File "/home/donkami/Sona/devnet-candelaria/Services/Wan/api_prtg.py", line 62, in get_prtg_data
    device_id_url = os.getenv("URL_PRTG_GET_ID_WITH_IP").format(ip=ip_wan)
KeyError: 'username'

2024-09-13 13:02:53,470 - ERROR - 'username'
2024-09-13 13:02:53,470 - ERROR - Error en la funcion get_prtg_data en el archivo api_prtg 10.224.21.1
2024-09-13 13:02:53,470 - ERROR - Traceback (most recent call last):
  File "/home/donkami/Sona/devnet-candelaria/Services/Wan/api_prtg.py", line 62, in get_prtg_data
    device_id_url = os.getenv("URL_PRTG_GET_ID_WITH_IP").format(ip=ip_wan)
KeyError: 'username'

2024-09-13 13:02:53,470 - ERROR - 'username'
2024-09-13 13:02:53,470 - ERROR - Error en la funcion get_prtg_data en el archivo api_prtg 10.224.127.11
2024-09-13 13:03:40,576 - ERROR - Traceback (most recent call last):
  File "/home/donkami/Sona/devnet-candelaria/Services/Wan/api_prtg.py", line 114, in get_prtg_data
    last_month = get_wan_data(
  File "/home/donkami/Sona/devnet-candelaria/Services/Wan/api_prtg.py", line 156, in get_wan_data
    get_historicdata = os.getenv("URL_HISTORICDATA").format(
KeyError: 'username'

2024-09-13 13:03:40,577 - ERROR - 'username'
2024-09-13 13:03:40,577 - ERROR - Error en la funcion get_prtg_data en el archivo api_prtg 10.224.126.89
2024-09-13 13:03:41,549 - ERROR - Traceback (most recent call last):
  File "/home/donkami/Sona/devnet-candelaria/Services/Wan/api_prtg.py", line 114, in get_prtg_data
    last_month = get_wan_data(
  File "/home/donkami/Sona/devnet-candelaria/Services/Wan/api_prtg.py", line 156, in get_wan_data
    get_historicdata = os.getenv("URL_HISTORICDATA").format(
KeyError: 'username'

2024-09-13 13:03:41,549 - ERROR - 'username'
2024-09-13 13:03:41,549 - ERROR - Error en la funcion get_prtg_data en el archivo api_prtg 10.224.126.93
2024-09-13 13:03:42,582 - ERROR - Traceback (most recent call last):
  File "/home/donkami/Sona/devnet-candelaria/Services/Wan/api_prtg.py", line 114, in get_prtg_data
    last_month = get_wan_data(
  File "/home/donkami/Sona/devnet-candelaria/Services/Wan/api_prtg.py", line 156, in get_wan_data
    get_historicdata = os.getenv("URL_HISTORICDATA").format(
KeyError: 'username'

2024-09-13 13:03:42,582 - ERROR - 'username'
2024-09-13 13:03:42,582 - ERROR - Error en la funcion get_prtg_data en el archivo api_prtg 10.224.126.97
2024-09-13 13:03:43,675 - ERROR - Traceback (most recent call last):
  File "/home/donkami/Sona/devnet-candelaria/Services/Wan/api_prtg.py", line 114, in get_prtg_data
    last_month = get_wan_data(
  File "/home/donkami/Sona/devnet-candelaria/Services/Wan/api_prtg.py", line 156, in get_wan_data
    get_historicdata = os.getenv("URL_HISTORICDATA").format(
KeyError: 'username'

2024-09-13 13:03:43,675 - ERROR - 'username'
2024-09-13 13:03:43,675 - ERROR - Error en la funcion get_prtg_data en el archivo api_prtg 10.220.15.1
2024-09-13 13:03:44,667 - ERROR - Traceback (most recent call last):
  File "/home/donkami/Sona/devnet-candelaria/Services/Wan/api_prtg.py", line 114, in get_prtg_data
    last_month = get_wan_data(
  File "/home/donkami/Sona/devnet-candelaria/Services/Wan/api_prtg.py", line 156, in get_wan_data
    get_historicdata = os.getenv("URL_HISTORICDATA").format(
KeyError: 'username'

2024-09-13 13:03:44,667 - ERROR - 'username'
2024-09-13 13:03:44,667 - ERROR - Error en la funcion get_prtg_data en el archivo api_prtg 10.224.15.1
2024-09-13 13:03:45,648 - ERROR - Traceback (most recent call last):
  File "/home/donkami/Sona/devnet-candelaria/Services/Wan/api_prtg.py", line 114, in get_prtg_data
    last_month = get_wan_data(
  File "/home/donkami/Sona/devnet-candelaria/Services/Wan/api_prtg.py", line 156, in get_wan_data
    get_historicdata = os.getenv("URL_HISTORICDATA").format(
KeyError: 'username'

2024-09-13 13:03:45,648 - ERROR - 'username'
2024-09-13 13:03:45,648 - ERROR - Error en la funcion get_prtg_data en el archivo api_prtg 10.224.17.1
2024-09-13 13:03:46,682 - ERROR - Traceback (most recent call last):
  File "/home/donkami/Sona/devnet-candelaria/Services/Wan/api_prtg.py", line 114, in get_prtg_data
    last_month = get_wan_data(
  File "/home/donkami/Sona/devnet-candelaria/Services/Wan/api_prtg.py", line 156, in get_wan_data
    get_historicdata = os.getenv("URL_HISTORICDATA").format(
KeyError: 'username'

2024-09-13 13:03:46,682 - ERROR - 'username'
2024-09-13 13:03:46,682 - ERROR - Error en la funcion get_prtg_data en el archivo api_prtg 10.224.23.1
2024-09-13 16:05:46,891 - ERROR - Traceback (most recent call last):
  File "/home/donkami/.local/lib/python3.10/site-packages/mysql/connector/connection_cext.py", line 291, in _open_connection
    self._cmysql.connect(**cnx_kwargs)
_mysql_connector.MySQLInterfaceError: Access denied for user 'donkami'@'172.18.0.1' (using password: NO)

The above exception was the direct cause of the following exception:

Traceback (most recent call last):
  File "/home/donkami/Sona/devnet-candelaria/Services/Switches/db_connections.py", line 21, in devnet_connection
    db_connector = mysql.connector.connect(
  File "/home/donkami/.local/lib/python3.10/site-packages/mysql/connector/pooling.py", line 293, in connect
    return CMySQLConnection(*args, **kwargs)
  File "/home/donkami/.local/lib/python3.10/site-packages/mysql/connector/connection_cext.py", line 120, in __init__
    self.connect(**kwargs)
  File "/home/donkami/.local/lib/python3.10/site-packages/mysql/connector/abstracts.py", line 1181, in connect
    self._open_connection()
  File "/home/donkami/.local/lib/python3.10/site-packages/mysql/connector/connection_cext.py", line 296, in _open_connection
    raise get_mysql_exception(
mysql.connector.errors.ProgrammingError: 1045 (28000): Access denied for user 'donkami'@'172.18.0.1' (using password: NO)

2024-09-13 16:05:46,891 - ERROR - Error en la función `devnet_connection` en el archivo `db_connections`
2024-09-13 16:05:46,891 - ERROR - 1045 (28000): Access denied for user 'donkami'@'172.18.0.1' (using password: NO)
2024-09-13 16:05:46,891 - ERROR - Traceback (most recent call last):
  File "/home/donkami/Sona/devnet-candelaria/Services/Switches/db_get_data.py", line 37, in get_data
    raise ValueError("No se pudo establecer la conexión con la base de datos: el conector es None.")
ValueError: No se pudo establecer la conexión con la base de datos: el conector es None.

2024-09-13 16:05:46,891 - ERROR - No se pudo establecer la conexión con la base de datos: el conector es None.
2024-09-13 16:05:46,892 - ERROR - Error al obtener datos de la base de datos
2024-09-13 16:07:10,563 - ERROR - Error con el IP en Funcion 'get_cisco_data' 10.224.236.5
2024-09-13 16:07:10,564 - ERROR - Traceback (most recent call last):
  File "/home/donkami/Sona/devnet-candelaria/Services/Switches/api_cisco.py", line 36, in get_cisco_data
    URL_CISCO_ID_DEVICE = os.getenv("URL_CISCO_ID_DEVICE").format(
KeyError: 'cisco_username_2'

2024-09-13 16:07:10,564 - ERROR - 'cisco_username_2'
2024-09-13 16:07:12,243 - ERROR - Error con el IP en Funcion 'get_cisco_data' 10.224.236.6
2024-09-13 16:07:12,243 - ERROR - Traceback (most recent call last):
  File "/home/donkami/Sona/devnet-candelaria/Services/Switches/api_cisco.py", line 36, in get_cisco_data
    URL_CISCO_ID_DEVICE = os.getenv("URL_CISCO_ID_DEVICE").format(
KeyError: 'cisco_username_2'

2024-09-13 16:07:12,243 - ERROR - 'cisco_username_2'
2024-09-13 16:07:13,776 - ERROR - Error con el IP en Funcion 'get_cisco_data' 10.224.236.7
2024-09-13 16:07:13,776 - ERROR - Traceback (most recent call last):
  File "/home/donkami/Sona/devnet-candelaria/Services/Switches/api_cisco.py", line 36, in get_cisco_data
    URL_CISCO_ID_DEVICE = os.getenv("URL_CISCO_ID_DEVICE").format(
KeyError: 'cisco_username_2'

2024-09-13 16:07:13,776 - ERROR - 'cisco_username_2'
2024-09-13 16:07:15,406 - ERROR - Error con el IP en Funcion 'get_cisco_data' 10.224.236.8
2024-09-13 16:07:15,406 - ERROR - Traceback (most recent call last):
  File "/home/donkami/Sona/devnet-candelaria/Services/Switches/api_cisco.py", line 36, in get_cisco_data
    URL_CISCO_ID_DEVICE = os.getenv("URL_CISCO_ID_DEVICE").format(
KeyError: 'cisco_username_2'

2024-09-13 16:07:15,406 - ERROR - 'cisco_username_2'
2024-09-13 16:07:17,105 - ERROR - Error con el IP en Funcion 'get_cisco_data' 10.224.236.9
2024-09-13 16:07:17,106 - ERROR - Traceback (most recent call last):
  File "/home/donkami/Sona/devnet-candelaria/Services/Switches/api_cisco.py", line 36, in get_cisco_data
    URL_CISCO_ID_DEVICE = os.getenv("URL_CISCO_ID_DEVICE").format(
KeyError: 'cisco_username_2'

2024-09-13 16:07:17,106 - ERROR - 'cisco_username_2'
2024-09-13 16:07:18,733 - ERROR - Error con el IP en Funcion 'get_cisco_data' 10.224.236.10
2024-09-13 16:07:18,733 - ERROR - Traceback (most recent call last):
  File "/home/donkami/Sona/devnet-candelaria/Services/Switches/api_cisco.py", line 36, in get_cisco_data
    URL_CISCO_ID_DEVICE = os.getenv("URL_CISCO_ID_DEVICE").format(
KeyError: 'cisco_username_2'

2024-09-13 16:07:18,733 - ERROR - 'cisco_username_2'
2024-09-13 16:07:20,305 - ERROR - Error con el IP en Funcion 'get_cisco_data' 10.224.236.11
2024-09-13 16:07:20,306 - ERROR - Traceback (most recent call last):
  File "/home/donkami/Sona/devnet-candelaria/Services/Switches/api_cisco.py", line 36, in get_cisco_data
    URL_CISCO_ID_DEVICE = os.getenv("URL_CISCO_ID_DEVICE").format(
KeyError: 'cisco_username_2'

2024-09-13 16:07:20,306 - ERROR - 'cisco_username_2'
2024-09-13 16:07:21,841 - ERROR - Error con el IP en Funcion 'get_cisco_data' 10.224.236.12
2024-09-13 16:07:21,841 - ERROR - Traceback (most recent call last):
  File "/home/donkami/Sona/devnet-candelaria/Services/Switches/api_cisco.py", line 36, in get_cisco_data
    URL_CISCO_ID_DEVICE = os.getenv("URL_CISCO_ID_DEVICE").format(
KeyError: 'cisco_username_2'

2024-09-13 16:07:21,841 - ERROR - 'cisco_username_2'
2024-09-13 16:07:23,376 - ERROR - Error con el IP en Funcion 'get_cisco_data' 10.224.236.13
2024-09-13 16:07:23,377 - ERROR - Traceback (most recent call last):
  File "/home/donkami/Sona/devnet-candelaria/Services/Switches/api_cisco.py", line 36, in get_cisco_data
    URL_CISCO_ID_DEVICE = os.getenv("URL_CISCO_ID_DEVICE").format(
KeyError: 'cisco_username_2'

2024-09-13 16:07:23,377 - ERROR - 'cisco_username_2'
2024-09-13 16:07:24,957 - ERROR - Error con el IP en Funcion 'get_cisco_data' 10.224.236.16
2024-09-13 16:07:24,957 - ERROR - Traceback (most recent call last):
  File "/home/donkami/Sona/devnet-candelaria/Services/Switches/api_cisco.py", line 36, in get_cisco_data
    URL_CISCO_ID_DEVICE = os.getenv("URL_CISCO_ID_DEVICE").format(
KeyError: 'cisco_username_2'

2024-09-13 16:07:24,957 - ERROR - 'cisco_username_2'
2024-09-13 16:29:51,334 - ERROR - Traceback (most recent call last):
  File "/home/donkami/.local/lib/python3.10/site-packages/mysql/connector/connection_cext.py", line 611, in cmd_query
    self._cmysql.query(
_mysql_connector.MySQLInterfaceError: You have an error in your SQL syntax; check the manual that corresponds to your MySQL server version for the right syntax to use near 'WHERE ip = '10.224.238.8'' at line 6

The above exception was the direct cause of the following exception:

Traceback (most recent call last):
  File "/home/donkami/Sona/devnet-candelaria/Services/Switches/db_update_devnet.py", line 57, in update_devnet_data
    devnet_cursor.executemany(query, data_tuple)
  File "/home/donkami/.local/lib/python3.10/site-packages/mysql/connector/cursor_cext.py", line 465, in executemany
    self.execute(operation, params)
  File "/home/donkami/.local/lib/python3.10/site-packages/mysql/connector/cursor_cext.py", line 330, in execute
    result = self._cnx.cmd_query(
  File "/home/donkami/.local/lib/python3.10/site-packages/mysql/connector/connection_cext.py", line 619, in cmd_query
    raise get_mysql_exception(
mysql.connector.errors.ProgrammingError: 1064 (42000): You have an error in your SQL syntax; check the manual that corresponds to your MySQL server version for the right syntax to use near 'WHERE ip = '10.224.238.8'' at line 6

2024-09-13 16:29:51,334 - ERROR - 1064 (42000): You have an error in your SQL syntax; check the manual that corresponds to your MySQL server version for the right syntax to use near 'WHERE ip = '10.224.238.8'' at line 6
2024-09-13 16:29:51,334 - ERROR - Error en la función `update_devnet_data` en el archivo `db_update_devnet`
2024-09-13 16:32:51,086 - ERROR - Traceback (most recent call last):
  File "/home/donkami/.local/lib/python3.10/site-packages/mysql/connector/connection_cext.py", line 611, in cmd_query
    self._cmysql.query(
_mysql_connector.MySQLInterfaceError: Table 'dcs.switches' doesn't exist

The above exception was the direct cause of the following exception:

Traceback (most recent call last):
  File "/home/donkami/Sona/devnet-candelaria/Services/Switches/db_get_data.py", line 43, in get_data
    devnet_cursor.execute(query)
  File "/home/donkami/.local/lib/python3.10/site-packages/mysql/connector/cursor_cext.py", line 330, in execute
    result = self._cnx.cmd_query(
  File "/home/donkami/.local/lib/python3.10/site-packages/mysql/connector/connection_cext.py", line 619, in cmd_query
    raise get_mysql_exception(
mysql.connector.errors.ProgrammingError: 1146 (42S02): Table 'dcs.switches' doesn't exist

2024-09-13 16:32:51,086 - ERROR - 1146 (42S02): Table 'dcs.switches' doesn't exist
2024-09-13 16:32:51,086 - ERROR - Error al obtener datos de la base de datos
2024-09-13 16:32:51,091 - ERROR - Traceback (most recent call last):
  File "/home/donkami/Sona/devnet-candelaria/Services/Switches/main.py", line 30, in main
    for switch in allSwitches:
TypeError: 'NoneType' object is not iterable

2024-09-13 16:32:51,091 - ERROR - 'NoneType' object is not iterable
2024-09-13 16:32:51,091 - ERROR - Error en la funcion `main` del archivo `main`
2024-09-13 16:39:45,994 - ERROR - Traceback (most recent call last):
  File "/home/donkami/.local/lib/python3.10/site-packages/mysql/connector/connection_cext.py", line 611, in cmd_query
    self._cmysql.query(
_mysql_connector.MySQLInterfaceError: Table 'dcs.switches' doesn't exist

The above exception was the direct cause of the following exception:

Traceback (most recent call last):
  File "/home/donkami/Sona/devnet-candelaria/Services/Switches/db_get_data.py", line 43, in get_data
    devnet_cursor.execute(query)
  File "/home/donkami/.local/lib/python3.10/site-packages/mysql/connector/cursor_cext.py", line 330, in execute
    result = self._cnx.cmd_query(
  File "/home/donkami/.local/lib/python3.10/site-packages/mysql/connector/connection_cext.py", line 619, in cmd_query
    raise get_mysql_exception(
mysql.connector.errors.ProgrammingError: 1146 (42S02): Table 'dcs.switches' doesn't exist

2024-09-13 16:39:45,995 - ERROR - 1146 (42S02): Table 'dcs.switches' doesn't exist
2024-09-13 16:39:45,995 - ERROR - Error al obtener datos de la base de datos
2024-09-13 16:39:45,999 - ERROR - Traceback (most recent call last):
  File "/home/donkami/Sona/devnet-candelaria/Services/Switches/main.py", line 30, in main
    for switch in allSwitches:
TypeError: 'NoneType' object is not iterable

2024-09-13 16:39:45,999 - ERROR - 'NoneType' object is not iterable
2024-09-13 16:39:45,999 - ERROR - Error en la funcion `main` del archivo `main`
2024-09-13 16:44:39,701 - ERROR - Traceback (most recent call last):
  File "/home/donkami/.local/lib/python3.10/site-packages/mysql/connector/connection_cext.py", line 291, in _open_connection
    self._cmysql.connect(**cnx_kwargs)
_mysql_connector.MySQLInterfaceError: Can't connect to MySQL server on '10.230.116.17:33061' (110)

The above exception was the direct cause of the following exception:

Traceback (most recent call last):
  File "/home/donkami/Sona/devnet-candelaria/Services/Switches/db_connections.py", line 55, in historic_connection
    db_connector = mysql.connector.connect(
  File "/home/donkami/.local/lib/python3.10/site-packages/mysql/connector/pooling.py", line 293, in connect
    return CMySQLConnection(*args, **kwargs)
  File "/home/donkami/.local/lib/python3.10/site-packages/mysql/connector/connection_cext.py", line 120, in __init__
    self.connect(**kwargs)
  File "/home/donkami/.local/lib/python3.10/site-packages/mysql/connector/abstracts.py", line 1181, in connect
    self._open_connection()
  File "/home/donkami/.local/lib/python3.10/site-packages/mysql/connector/connection_cext.py", line 296, in _open_connection
    raise get_mysql_exception(
mysql.connector.errors.DatabaseError: 2003 (HY000): Can't connect to MySQL server on '10.230.116.17:33061' (110)

2024-09-13 16:44:39,701 - ERROR - Error en la función `historic_connection` en el archivo `db_connections`
2024-09-13 16:44:39,701 - ERROR - 2003 (HY000): Can't connect to MySQL server on '10.230.116.17:33061' (110)
2024-09-13 16:44:39,702 - ERROR - Traceback (most recent call last):
  File "/home/donkami/Sona/devnet-candelaria/Services/Switches/db_insert_historic.py", line 92, in save_historic_data
    historic_cursor = db_connector.cursor()
AttributeError: 'NoneType' object has no attribute 'cursor'

2024-09-13 16:44:39,702 - ERROR - Error en la función `save_historic_data` en el archivo `db_insert_historic`
2024-09-13 16:44:39,702 - ERROR - 'NoneType' object has no attribute 'cursor'
2024-09-17 17:37:25,141 - ERROR - Error al obtener la informacion de las UPS desde la API
2024-09-17 17:37:25,141 - ERROR: Error al obtener la informacion de las UPS desde la API
2024-09-17 17:37:25,147 - ERROR - Traceback (most recent call last):
  File "/home/donkami/.local/lib/python3.10/site-packages/urllib3/connection.py", line 200, in _new_conn
    sock = connection.create_connection(
  File "/home/donkami/.local/lib/python3.10/site-packages/urllib3/util/connection.py", line 85, in create_connection
    raise err
  File "/home/donkami/.local/lib/python3.10/site-packages/urllib3/util/connection.py", line 73, in create_connection
    sock.connect(sa)
ConnectionRefusedError: [Errno 111] Connection refused

The above exception was the direct cause of the following exception:

Traceback (most recent call last):
  File "/home/donkami/.local/lib/python3.10/site-packages/urllib3/connectionpool.py", line 790, in urlopen
    response = self._make_request(
  File "/home/donkami/.local/lib/python3.10/site-packages/urllib3/connectionpool.py", line 496, in _make_request
    conn.request(
  File "/home/donkami/.local/lib/python3.10/site-packages/urllib3/connection.py", line 388, in request
    self.endheaders()
  File "/usr/lib/python3.10/http/client.py", line 1278, in endheaders
    self._send_output(message_body, encode_chunked=encode_chunked)
  File "/usr/lib/python3.10/http/client.py", line 1038, in _send_output
    self.send(msg)
  File "/usr/lib/python3.10/http/client.py", line 976, in send
    self.connect()
  File "/home/donkami/.local/lib/python3.10/site-packages/urllib3/connection.py", line 236, in connect
    self.sock = self._new_conn()
  File "/home/donkami/.local/lib/python3.10/site-packages/urllib3/connection.py", line 215, in _new_conn
    raise NewConnectionError(
urllib3.exceptions.NewConnectionError: <urllib3.connection.HTTPConnection object at 0x7f3f0fd9dd80>: Failed to establish a new connection: [Errno 111] Connection refused

The above exception was the direct cause of the following exception:

Traceback (most recent call last):
  File "/home/donkami/.local/lib/python3.10/site-packages/requests/adapters.py", line 486, in send
    resp = conn.urlopen(
  File "/home/donkami/.local/lib/python3.10/site-packages/urllib3/connectionpool.py", line 844, in urlopen
    retries = retries.increment(
  File "/home/donkami/.local/lib/python3.10/site-packages/urllib3/util/retry.py", line 515, in increment
    raise MaxRetryError(_pool, url, reason) from reason  # type: ignore[arg-type]
urllib3.exceptions.MaxRetryError: HTTPConnectionPool(host='localhost', port=3001): Max retries exceeded with url: /api/v1/candelaria/ups (Caused by NewConnectionError('<urllib3.connection.HTTPConnection object at 0x7f3f0fd9dd80>: Failed to establish a new connection: [Errno 111] Connection refused'))

During handling of the above exception, another exception occurred:

Traceback (most recent call last):
  File "/home/donkami/Sona/devnet-candelaria/Services/Devices/ups.py", line 61, in get_api_ups_data
    data_ups = requests.get(API_UPS, verify=False).json()
  File "/home/donkami/.local/lib/python3.10/site-packages/requests/api.py", line 73, in get
    return request("get", url, params=params, **kwargs)
  File "/home/donkami/.local/lib/python3.10/site-packages/requests/api.py", line 59, in request
    return session.request(method=method, url=url, **kwargs)
  File "/home/donkami/.local/lib/python3.10/site-packages/requests/sessions.py", line 589, in request
    resp = self.send(prep, **send_kwargs)
  File "/home/donkami/.local/lib/python3.10/site-packages/requests/sessions.py", line 703, in send
    r = adapter.send(request, **kwargs)
  File "/home/donkami/.local/lib/python3.10/site-packages/requests/adapters.py", line 519, in send
    raise ConnectionError(e, request=request)
requests.exceptions.ConnectionError: HTTPConnectionPool(host='localhost', port=3001): Max retries exceeded with url: /api/v1/candelaria/ups (Caused by NewConnectionError('<urllib3.connection.HTTPConnection object at 0x7f3f0fd9dd80>: Failed to establish a new connection: [Errno 111] Connection refused'))

2024-09-17 17:37:25,147 - ERROR: Traceback (most recent call last):
  File "/home/donkami/.local/lib/python3.10/site-packages/urllib3/connection.py", line 200, in _new_conn
    sock = connection.create_connection(
  File "/home/donkami/.local/lib/python3.10/site-packages/urllib3/util/connection.py", line 85, in create_connection
    raise err
  File "/home/donkami/.local/lib/python3.10/site-packages/urllib3/util/connection.py", line 73, in create_connection
    sock.connect(sa)
ConnectionRefusedError: [Errno 111] Connection refused

The above exception was the direct cause of the following exception:

Traceback (most recent call last):
  File "/home/donkami/.local/lib/python3.10/site-packages/urllib3/connectionpool.py", line 790, in urlopen
    response = self._make_request(
  File "/home/donkami/.local/lib/python3.10/site-packages/urllib3/connectionpool.py", line 496, in _make_request
    conn.request(
  File "/home/donkami/.local/lib/python3.10/site-packages/urllib3/connection.py", line 388, in request
    self.endheaders()
  File "/usr/lib/python3.10/http/client.py", line 1278, in endheaders
    self._send_output(message_body, encode_chunked=encode_chunked)
  File "/usr/lib/python3.10/http/client.py", line 1038, in _send_output
    self.send(msg)
  File "/usr/lib/python3.10/http/client.py", line 976, in send
    self.connect()
  File "/home/donkami/.local/lib/python3.10/site-packages/urllib3/connection.py", line 236, in connect
    self.sock = self._new_conn()
  File "/home/donkami/.local/lib/python3.10/site-packages/urllib3/connection.py", line 215, in _new_conn
    raise NewConnectionError(
urllib3.exceptions.NewConnectionError: <urllib3.connection.HTTPConnection object at 0x7f3f0fd9dd80>: Failed to establish a new connection: [Errno 111] Connection refused

The above exception was the direct cause of the following exception:

Traceback (most recent call last):
  File "/home/donkami/.local/lib/python3.10/site-packages/requests/adapters.py", line 486, in send
    resp = conn.urlopen(
  File "/home/donkami/.local/lib/python3.10/site-packages/urllib3/connectionpool.py", line 844, in urlopen
    retries = retries.increment(
  File "/home/donkami/.local/lib/python3.10/site-packages/urllib3/util/retry.py", line 515, in increment
    raise MaxRetryError(_pool, url, reason) from reason  # type: ignore[arg-type]
urllib3.exceptions.MaxRetryError: HTTPConnectionPool(host='localhost', port=3001): Max retries exceeded with url: /api/v1/candelaria/ups (Caused by NewConnectionError('<urllib3.connection.HTTPConnection object at 0x7f3f0fd9dd80>: Failed to establish a new connection: [Errno 111] Connection refused'))

During handling of the above exception, another exception occurred:

Traceback (most recent call last):
  File "/home/donkami/Sona/devnet-candelaria/Services/Devices/ups.py", line 61, in get_api_ups_data
    data_ups = requests.get(API_UPS, verify=False).json()
  File "/home/donkami/.local/lib/python3.10/site-packages/requests/api.py", line 73, in get
    return request("get", url, params=params, **kwargs)
  File "/home/donkami/.local/lib/python3.10/site-packages/requests/api.py", line 59, in request
    return session.request(method=method, url=url, **kwargs)
  File "/home/donkami/.local/lib/python3.10/site-packages/requests/sessions.py", line 589, in request
    resp = self.send(prep, **send_kwargs)
  File "/home/donkami/.local/lib/python3.10/site-packages/requests/sessions.py", line 703, in send
    r = adapter.send(request, **kwargs)
  File "/home/donkami/.local/lib/python3.10/site-packages/requests/adapters.py", line 519, in send
    raise ConnectionError(e, request=request)
requests.exceptions.ConnectionError: HTTPConnectionPool(host='localhost', port=3001): Max retries exceeded with url: /api/v1/candelaria/ups (Caused by NewConnectionError('<urllib3.connection.HTTPConnection object at 0x7f3f0fd9dd80>: Failed to establish a new connection: [Errno 111] Connection refused'))

2024-09-17 17:37:25,147 - ERROR - Error detallado:
2024-09-17 17:37:25,147 - ERROR: Error detallado:
2024-09-17 17:37:25,147 - ERROR - HTTPConnectionPool(host='localhost', port=3001): Max retries exceeded with url: /api/v1/candelaria/ups (Caused by NewConnectionError('<urllib3.connection.HTTPConnection object at 0x7f3f0fd9dd80>: Failed to establish a new connection: [Errno 111] Connection refused'))
2024-09-17 17:37:25,147 - ERROR: HTTPConnectionPool(host='localhost', port=3001): Max retries exceeded with url: /api/v1/candelaria/ups (Caused by NewConnectionError('<urllib3.connection.HTTPConnection object at 0x7f3f0fd9dd80>: Failed to establish a new connection: [Errno 111] Connection refused'))
2024-09-17 17:37:25,147 - ERROR - Hubo un error en la funcion `define_ups_status`: Error al obtener la información de la API
2024-09-17 17:37:25,147 - ERROR: Hubo un error en la funcion `define_ups_status`: Error al obtener la información de la API
2024-09-17 17:37:27,699 - ERROR - Traceback (most recent call last):
  File "/home/donkami/Sona/devnet-candelaria/Services/Devices/api_prtg.py", line 52, in get_prtg_data
    URL_PRTG_GET_ID = os.getenv("URL_PRTG_IP").format(ip=ip)
KeyError: 'username'

2024-09-17 17:37:27,699 - ERROR: Traceback (most recent call last):
  File "/home/donkami/Sona/devnet-candelaria/Services/Devices/api_prtg.py", line 52, in get_prtg_data
    URL_PRTG_GET_ID = os.getenv("URL_PRTG_IP").format(ip=ip)
KeyError: 'username'

2024-09-17 17:37:27,699 - ERROR - Traceback (most recent call last):
  File "/home/donkami/Sona/devnet-candelaria/Services/Devices/api_prtg.py", line 52, in get_prtg_data
    URL_PRTG_GET_ID = os.getenv("URL_PRTG_IP").format(ip=ip)
KeyError: 'username'

2024-09-17 17:37:27,699 - ERROR - Traceback (most recent call last):
  File "/home/donkami/Sona/devnet-candelaria/Services/Devices/api_prtg.py", line 52, in get_prtg_data
    URL_PRTG_GET_ID = os.getenv("URL_PRTG_IP").format(ip=ip)
KeyError: 'username'

2024-09-17 17:37:27,699 - ERROR: Traceback (most recent call last):
  File "/home/donkami/Sona/devnet-candelaria/Services/Devices/api_prtg.py", line 52, in get_prtg_data
    URL_PRTG_GET_ID = os.getenv("URL_PRTG_IP").format(ip=ip)
KeyError: 'username'

2024-09-17 17:37:27,699 - ERROR - 'username'
2024-09-17 17:37:27,699 - ERROR: Traceback (most recent call last):
  File "/home/donkami/Sona/devnet-candelaria/Services/Devices/api_prtg.py", line 52, in get_prtg_data
    URL_PRTG_GET_ID = os.getenv("URL_PRTG_IP").format(ip=ip)
KeyError: 'username'

2024-09-17 17:37:27,700 - ERROR - 'username'
2024-09-17 17:37:27,699 - ERROR: 'username'
2024-09-17 17:37:27,700 - ERROR - 'username'
2024-09-17 17:37:27,700 - ERROR: 'username'
2024-09-17 17:37:27,700 - ERROR - Error en la funcion get_prtg_data en el archivo api_prtg10.225.4.43
2024-09-17 17:37:27,700 - ERROR: 'username'
2024-09-17 17:37:27,700 - ERROR - Error en la funcion get_prtg_data en el archivo api_prtg10.231.0.97
2024-09-17 17:37:27,700 - ERROR: Error en la funcion get_prtg_data en el archivo api_prtg10.225.4.43
2024-09-17 17:37:27,700 - ERROR - Error en la funcion get_prtg_data en el archivo api_prtg10.224.21.6
2024-09-17 17:37:27,700 - ERROR: Error en la funcion get_prtg_data en el archivo api_prtg10.231.0.97
2024-09-17 17:37:27,700 - ERROR: Error en la funcion get_prtg_data en el archivo api_prtg10.224.21.6
2024-09-17 17:37:30,007 - ERROR - Error al obtener la informacion de las UPS desde la API
2024-09-17 17:37:30,007 - ERROR: Error al obtener la informacion de las UPS desde la API
2024-09-17 17:37:30,007 - ERROR - Traceback (most recent call last):
  File "/home/donkami/.local/lib/python3.10/site-packages/urllib3/connection.py", line 200, in _new_conn
    sock = connection.create_connection(
  File "/home/donkami/.local/lib/python3.10/site-packages/urllib3/util/connection.py", line 85, in create_connection
    raise err
  File "/home/donkami/.local/lib/python3.10/site-packages/urllib3/util/connection.py", line 73, in create_connection
    sock.connect(sa)
ConnectionRefusedError: [Errno 111] Connection refused

The above exception was the direct cause of the following exception:

Traceback (most recent call last):
  File "/home/donkami/.local/lib/python3.10/site-packages/urllib3/connectionpool.py", line 790, in urlopen
    response = self._make_request(
  File "/home/donkami/.local/lib/python3.10/site-packages/urllib3/connectionpool.py", line 496, in _make_request
    conn.request(
  File "/home/donkami/.local/lib/python3.10/site-packages/urllib3/connection.py", line 388, in request
    self.endheaders()
  File "/usr/lib/python3.10/http/client.py", line 1278, in endheaders
    self._send_output(message_body, encode_chunked=encode_chunked)
  File "/usr/lib/python3.10/http/client.py", line 1038, in _send_output
    self.send(msg)
  File "/usr/lib/python3.10/http/client.py", line 976, in send
    self.connect()
  File "/home/donkami/.local/lib/python3.10/site-packages/urllib3/connection.py", line 236, in connect
    self.sock = self._new_conn()
  File "/home/donkami/.local/lib/python3.10/site-packages/urllib3/connection.py", line 215, in _new_conn
    raise NewConnectionError(
urllib3.exceptions.NewConnectionError: <urllib3.connection.HTTPConnection object at 0x7f3f10c2c520>: Failed to establish a new connection: [Errno 111] Connection refused

The above exception was the direct cause of the following exception:

Traceback (most recent call last):
  File "/home/donkami/.local/lib/python3.10/site-packages/requests/adapters.py", line 486, in send
    resp = conn.urlopen(
  File "/home/donkami/.local/lib/python3.10/site-packages/urllib3/connectionpool.py", line 844, in urlopen
    retries = retries.increment(
  File "/home/donkami/.local/lib/python3.10/site-packages/urllib3/util/retry.py", line 515, in increment
    raise MaxRetryError(_pool, url, reason) from reason  # type: ignore[arg-type]
urllib3.exceptions.MaxRetryError: HTTPConnectionPool(host='localhost', port=3001): Max retries exceeded with url: /api/v1/candelaria/ups (Caused by NewConnectionError('<urllib3.connection.HTTPConnection object at 0x7f3f10c2c520>: Failed to establish a new connection: [Errno 111] Connection refused'))

During handling of the above exception, another exception occurred:

Traceback (most recent call last):
  File "/home/donkami/Sona/devnet-candelaria/Services/Devices/ups.py", line 61, in get_api_ups_data
    data_ups = requests.get(API_UPS, verify=False).json()
  File "/home/donkami/.local/lib/python3.10/site-packages/requests/api.py", line 73, in get
    return request("get", url, params=params, **kwargs)
  File "/home/donkami/.local/lib/python3.10/site-packages/requests/api.py", line 59, in request
    return session.request(method=method, url=url, **kwargs)
  File "/home/donkami/.local/lib/python3.10/site-packages/requests/sessions.py", line 589, in request
    resp = self.send(prep, **send_kwargs)
  File "/home/donkami/.local/lib/python3.10/site-packages/requests/sessions.py", line 703, in send
    r = adapter.send(request, **kwargs)
  File "/home/donkami/.local/lib/python3.10/site-packages/requests/adapters.py", line 519, in send
    raise ConnectionError(e, request=request)
requests.exceptions.ConnectionError: HTTPConnectionPool(host='localhost', port=3001): Max retries exceeded with url: /api/v1/candelaria/ups (Caused by NewConnectionError('<urllib3.connection.HTTPConnection object at 0x7f3f10c2c520>: Failed to establish a new connection: [Errno 111] Connection refused'))

2024-09-17 17:37:30,007 - ERROR: Traceback (most recent call last):
  File "/home/donkami/.local/lib/python3.10/site-packages/urllib3/connection.py", line 200, in _new_conn
    sock = connection.create_connection(
  File "/home/donkami/.local/lib/python3.10/site-packages/urllib3/util/connection.py", line 85, in create_connection
    raise err
  File "/home/donkami/.local/lib/python3.10/site-packages/urllib3/util/connection.py", line 73, in create_connection
    sock.connect(sa)
ConnectionRefusedError: [Errno 111] Connection refused

The above exception was the direct cause of the following exception:

Traceback (most recent call last):
  File "/home/donkami/.local/lib/python3.10/site-packages/urllib3/connectionpool.py", line 790, in urlopen
    response = self._make_request(
  File "/home/donkami/.local/lib/python3.10/site-packages/urllib3/connectionpool.py", line 496, in _make_request
    conn.request(
  File "/home/donkami/.local/lib/python3.10/site-packages/urllib3/connection.py", line 388, in request
    self.endheaders()
  File "/usr/lib/python3.10/http/client.py", line 1278, in endheaders
    self._send_output(message_body, encode_chunked=encode_chunked)
  File "/usr/lib/python3.10/http/client.py", line 1038, in _send_output
    self.send(msg)
  File "/usr/lib/python3.10/http/client.py", line 976, in send
    self.connect()
  File "/home/donkami/.local/lib/python3.10/site-packages/urllib3/connection.py", line 236, in connect
    self.sock = self._new_conn()
  File "/home/donkami/.local/lib/python3.10/site-packages/urllib3/connection.py", line 215, in _new_conn
    raise NewConnectionError(
urllib3.exceptions.NewConnectionError: <urllib3.connection.HTTPConnection object at 0x7f3f10c2c520>: Failed to establish a new connection: [Errno 111] Connection refused

The above exception was the direct cause of the following exception:

Traceback (most recent call last):
  File "/home/donkami/.local/lib/python3.10/site-packages/requests/adapters.py", line 486, in send
    resp = conn.urlopen(
  File "/home/donkami/.local/lib/python3.10/site-packages/urllib3/connectionpool.py", line 844, in urlopen
    retries = retries.increment(
  File "/home/donkami/.local/lib/python3.10/site-packages/urllib3/util/retry.py", line 515, in increment
    raise MaxRetryError(_pool, url, reason) from reason  # type: ignore[arg-type]
urllib3.exceptions.MaxRetryError: HTTPConnectionPool(host='localhost', port=3001): Max retries exceeded with url: /api/v1/candelaria/ups (Caused by NewConnectionError('<urllib3.connection.HTTPConnection object at 0x7f3f10c2c520>: Failed to establish a new connection: [Errno 111] Connection refused'))

During handling of the above exception, another exception occurred:

Traceback (most recent call last):
  File "/home/donkami/Sona/devnet-candelaria/Services/Devices/ups.py", line 61, in get_api_ups_data
    data_ups = requests.get(API_UPS, verify=False).json()
  File "/home/donkami/.local/lib/python3.10/site-packages/requests/api.py", line 73, in get
    return request("get", url, params=params, **kwargs)
  File "/home/donkami/.local/lib/python3.10/site-packages/requests/api.py", line 59, in request
    return session.request(method=method, url=url, **kwargs)
  File "/home/donkami/.local/lib/python3.10/site-packages/requests/sessions.py", line 589, in request
    resp = self.send(prep, **send_kwargs)
  File "/home/donkami/.local/lib/python3.10/site-packages/requests/sessions.py", line 703, in send
    r = adapter.send(request, **kwargs)
  File "/home/donkami/.local/lib/python3.10/site-packages/requests/adapters.py", line 519, in send
    raise ConnectionError(e, request=request)
requests.exceptions.ConnectionError: HTTPConnectionPool(host='localhost', port=3001): Max retries exceeded with url: /api/v1/candelaria/ups (Caused by NewConnectionError('<urllib3.connection.HTTPConnection object at 0x7f3f10c2c520>: Failed to establish a new connection: [Errno 111] Connection refused'))

2024-09-17 17:37:30,007 - ERROR - Error detallado:
2024-09-17 17:37:30,007 - ERROR: Error detallado:
2024-09-17 17:37:30,007 - ERROR - HTTPConnectionPool(host='localhost', port=3001): Max retries exceeded with url: /api/v1/candelaria/ups (Caused by NewConnectionError('<urllib3.connection.HTTPConnection object at 0x7f3f10c2c520>: Failed to establish a new connection: [Errno 111] Connection refused'))
2024-09-17 17:37:30,007 - ERROR: HTTPConnectionPool(host='localhost', port=3001): Max retries exceeded with url: /api/v1/candelaria/ups (Caused by NewConnectionError('<urllib3.connection.HTTPConnection object at 0x7f3f10c2c520>: Failed to establish a new connection: [Errno 111] Connection refused'))
2024-09-17 17:37:30,007 - ERROR - Hubo un error en la funcion `define_ups_status`: Error al obtener la información de la API
2024-09-17 17:37:30,007 - ERROR: Hubo un error en la funcion `define_ups_status`: Error al obtener la información de la API
2024-09-17 17:37:30,007 - ERROR - Traceback (most recent call last):
  File "/home/donkami/Sona/devnet-candelaria/Services/Devices/api_prtg.py", line 52, in get_prtg_data
    URL_PRTG_GET_ID = os.getenv("URL_PRTG_IP").format(ip=ip)
KeyError: 'username'

2024-09-17 17:37:30,007 - ERROR: Traceback (most recent call last):
  File "/home/donkami/Sona/devnet-candelaria/Services/Devices/api_prtg.py", line 52, in get_prtg_data
    URL_PRTG_GET_ID = os.getenv("URL_PRTG_IP").format(ip=ip)
KeyError: 'username'

2024-09-17 17:37:30,008 - ERROR - 'username'
2024-09-17 17:37:30,008 - ERROR: 'username'
2024-09-17 17:37:30,008 - ERROR - Error en la funcion get_prtg_data en el archivo api_prtg10.224.1.138
2024-09-17 17:37:30,008 - ERROR: Error en la funcion get_prtg_data en el archivo api_prtg10.224.1.138
2024-09-17 17:37:30,040 - ERROR - Error al obtener la informacion de las UPS desde la API
2024-09-17 17:37:30,040 - ERROR: Error al obtener la informacion de las UPS desde la API
2024-09-17 17:37:30,040 - ERROR - Traceback (most recent call last):
  File "/home/donkami/.local/lib/python3.10/site-packages/urllib3/connection.py", line 200, in _new_conn
    sock = connection.create_connection(
  File "/home/donkami/.local/lib/python3.10/site-packages/urllib3/util/connection.py", line 85, in create_connection
    raise err
  File "/home/donkami/.local/lib/python3.10/site-packages/urllib3/util/connection.py", line 73, in create_connection
    sock.connect(sa)
ConnectionRefusedError: [Errno 111] Connection refused

The above exception was the direct cause of the following exception:

Traceback (most recent call last):
  File "/home/donkami/.local/lib/python3.10/site-packages/urllib3/connectionpool.py", line 790, in urlopen
    response = self._make_request(
  File "/home/donkami/.local/lib/python3.10/site-packages/urllib3/connectionpool.py", line 496, in _make_request
    conn.request(
  File "/home/donkami/.local/lib/python3.10/site-packages/urllib3/connection.py", line 388, in request
    self.endheaders()
  File "/usr/lib/python3.10/http/client.py", line 1278, in endheaders
    self._send_output(message_body, encode_chunked=encode_chunked)
  File "/usr/lib/python3.10/http/client.py", line 1038, in _send_output
    self.send(msg)
  File "/usr/lib/python3.10/http/client.py", line 976, in send
    self.connect()
  File "/home/donkami/.local/lib/python3.10/site-packages/urllib3/connection.py", line 236, in connect
    self.sock = self._new_conn()
  File "/home/donkami/.local/lib/python3.10/site-packages/urllib3/connection.py", line 215, in _new_conn
    raise NewConnectionError(
urllib3.exceptions.NewConnectionError: <urllib3.connection.HTTPConnection object at 0x7f3f0f1984f0>: Failed to establish a new connection: [Errno 111] Connection refused

The above exception was the direct cause of the following exception:

Traceback (most recent call last):
  File "/home/donkami/.local/lib/python3.10/site-packages/requests/adapters.py", line 486, in send
    resp = conn.urlopen(
  File "/home/donkami/.local/lib/python3.10/site-packages/urllib3/connectionpool.py", line 844, in urlopen
    retries = retries.increment(
  File "/home/donkami/.local/lib/python3.10/site-packages/urllib3/util/retry.py", line 515, in increment
    raise MaxRetryError(_pool, url, reason) from reason  # type: ignore[arg-type]
urllib3.exceptions.MaxRetryError: HTTPConnectionPool(host='localhost', port=3001): Max retries exceeded with url: /api/v1/candelaria/ups (Caused by NewConnectionError('<urllib3.connection.HTTPConnection object at 0x7f3f0f1984f0>: Failed to establish a new connection: [Errno 111] Connection refused'))

During handling of the above exception, another exception occurred:

Traceback (most recent call last):
  File "/home/donkami/Sona/devnet-candelaria/Services/Devices/ups.py", line 61, in get_api_ups_data
    data_ups = requests.get(API_UPS, verify=False).json()
  File "/home/donkami/.local/lib/python3.10/site-packages/requests/api.py", line 73, in get
    return request("get", url, params=params, **kwargs)
  File "/home/donkami/.local/lib/python3.10/site-packages/requests/api.py", line 59, in request
    return session.request(method=method, url=url, **kwargs)
  File "/home/donkami/.local/lib/python3.10/site-packages/requests/sessions.py", line 589, in request
    resp = self.send(prep, **send_kwargs)
  File "/home/donkami/.local/lib/python3.10/site-packages/requests/sessions.py", line 703, in send
    r = adapter.send(request, **kwargs)
  File "/home/donkami/.local/lib/python3.10/site-packages/requests/adapters.py", line 519, in send
    raise ConnectionError(e, request=request)
requests.exceptions.ConnectionError: HTTPConnectionPool(host='localhost', port=3001): Max retries exceeded with url: /api/v1/candelaria/ups (Caused by NewConnectionError('<urllib3.connection.HTTPConnection object at 0x7f3f0f1984f0>: Failed to establish a new connection: [Errno 111] Connection refused'))

2024-09-17 17:37:30,040 - ERROR: Traceback (most recent call last):
  File "/home/donkami/.local/lib/python3.10/site-packages/urllib3/connection.py", line 200, in _new_conn
    sock = connection.create_connection(
  File "/home/donkami/.local/lib/python3.10/site-packages/urllib3/util/connection.py", line 85, in create_connection
    raise err
  File "/home/donkami/.local/lib/python3.10/site-packages/urllib3/util/connection.py", line 73, in create_connection
    sock.connect(sa)
ConnectionRefusedError: [Errno 111] Connection refused

The above exception was the direct cause of the following exception:

Traceback (most recent call last):
  File "/home/donkami/.local/lib/python3.10/site-packages/urllib3/connectionpool.py", line 790, in urlopen
    response = self._make_request(
  File "/home/donkami/.local/lib/python3.10/site-packages/urllib3/connectionpool.py", line 496, in _make_request
    conn.request(
  File "/home/donkami/.local/lib/python3.10/site-packages/urllib3/connection.py", line 388, in request
    self.endheaders()
  File "/usr/lib/python3.10/http/client.py", line 1278, in endheaders
    self._send_output(message_body, encode_chunked=encode_chunked)
  File "/usr/lib/python3.10/http/client.py", line 1038, in _send_output
    self.send(msg)
  File "/usr/lib/python3.10/http/client.py", line 976, in send
    self.connect()
  File "/home/donkami/.local/lib/python3.10/site-packages/urllib3/connection.py", line 236, in connect
    self.sock = self._new_conn()
  File "/home/donkami/.local/lib/python3.10/site-packages/urllib3/connection.py", line 215, in _new_conn
    raise NewConnectionError(
urllib3.exceptions.NewConnectionError: <urllib3.connection.HTTPConnection object at 0x7f3f0f1984f0>: Failed to establish a new connection: [Errno 111] Connection refused

The above exception was the direct cause of the following exception:

Traceback (most recent call last):
  File "/home/donkami/.local/lib/python3.10/site-packages/requests/adapters.py", line 486, in send
    resp = conn.urlopen(
  File "/home/donkami/.local/lib/python3.10/site-packages/urllib3/connectionpool.py", line 844, in urlopen
    retries = retries.increment(
  File "/home/donkami/.local/lib/python3.10/site-packages/urllib3/util/retry.py", line 515, in increment
    raise MaxRetryError(_pool, url, reason) from reason  # type: ignore[arg-type]
urllib3.exceptions.MaxRetryError: HTTPConnectionPool(host='localhost', port=3001): Max retries exceeded with url: /api/v1/candelaria/ups (Caused by NewConnectionError('<urllib3.connection.HTTPConnection object at 0x7f3f0f1984f0>: Failed to establish a new connection: [Errno 111] Connection refused'))

During handling of the above exception, another exception occurred:

Traceback (most recent call last):
  File "/home/donkami/Sona/devnet-candelaria/Services/Devices/ups.py", line 61, in get_api_ups_data
    data_ups = requests.get(API_UPS, verify=False).json()
  File "/home/donkami/.local/lib/python3.10/site-packages/requests/api.py", line 73, in get
    return request("get", url, params=params, **kwargs)
  File "/home/donkami/.local/lib/python3.10/site-packages/requests/api.py", line 59, in request
    return session.request(method=method, url=url, **kwargs)
  File "/home/donkami/.local/lib/python3.10/site-packages/requests/sessions.py", line 589, in request
    resp = self.send(prep, **send_kwargs)
  File "/home/donkami/.local/lib/python3.10/site-packages/requests/sessions.py", line 703, in send
    r = adapter.send(request, **kwargs)
  File "/home/donkami/.local/lib/python3.10/site-packages/requests/adapters.py", line 519, in send
    raise ConnectionError(e, request=request)
requests.exceptions.ConnectionError: HTTPConnectionPool(host='localhost', port=3001): Max retries exceeded with url: /api/v1/candelaria/ups (Caused by NewConnectionError('<urllib3.connection.HTTPConnection object at 0x7f3f0f1984f0>: Failed to establish a new connection: [Errno 111] Connection refused'))

2024-09-17 17:37:30,040 - ERROR - Error detallado:
2024-09-17 17:37:30,040 - ERROR: Error detallado:
2024-09-17 17:37:30,040 - ERROR - HTTPConnectionPool(host='localhost', port=3001): Max retries exceeded with url: /api/v1/candelaria/ups (Caused by NewConnectionError('<urllib3.connection.HTTPConnection object at 0x7f3f0f1984f0>: Failed to establish a new connection: [Errno 111] Connection refused'))
2024-09-17 17:37:30,040 - ERROR: HTTPConnectionPool(host='localhost', port=3001): Max retries exceeded with url: /api/v1/candelaria/ups (Caused by NewConnectionError('<urllib3.connection.HTTPConnection object at 0x7f3f0f1984f0>: Failed to establish a new connection: [Errno 111] Connection refused'))
2024-09-17 17:37:30,040 - ERROR - Hubo un error en la funcion `define_ups_status`: Error al obtener la información de la API
2024-09-17 17:37:30,040 - ERROR: Hubo un error en la funcion `define_ups_status`: Error al obtener la información de la API
2024-09-17 17:37:30,041 - ERROR - Traceback (most recent call last):
  File "/home/donkami/Sona/devnet-candelaria/Services/Devices/api_prtg.py", line 52, in get_prtg_data
    URL_PRTG_GET_ID = os.getenv("URL_PRTG_IP").format(ip=ip)
KeyError: 'username'

2024-09-17 17:37:30,041 - ERROR: Traceback (most recent call last):
  File "/home/donkami/Sona/devnet-candelaria/Services/Devices/api_prtg.py", line 52, in get_prtg_data
    URL_PRTG_GET_ID = os.getenv("URL_PRTG_IP").format(ip=ip)
KeyError: 'username'

2024-09-17 17:37:30,041 - ERROR - 'username'
2024-09-17 17:37:30,041 - ERROR: 'username'
2024-09-17 17:37:30,041 - ERROR - Error en la funcion get_prtg_data en el archivo api_prtg10.225.0.10
2024-09-17 17:37:30,041 - ERROR: Error en la funcion get_prtg_data en el archivo api_prtg10.225.0.10
2024-09-17 17:37:30,052 - ERROR - Error al obtener la informacion de las UPS desde la API
2024-09-17 17:37:30,052 - ERROR: Error al obtener la informacion de las UPS desde la API
2024-09-17 17:37:30,053 - ERROR - Traceback (most recent call last):
  File "/home/donkami/.local/lib/python3.10/site-packages/urllib3/connection.py", line 200, in _new_conn
    sock = connection.create_connection(
  File "/home/donkami/.local/lib/python3.10/site-packages/urllib3/util/connection.py", line 85, in create_connection
    raise err
  File "/home/donkami/.local/lib/python3.10/site-packages/urllib3/util/connection.py", line 73, in create_connection
    sock.connect(sa)
ConnectionRefusedError: [Errno 111] Connection refused

The above exception was the direct cause of the following exception:

Traceback (most recent call last):
  File "/home/donkami/.local/lib/python3.10/site-packages/urllib3/connectionpool.py", line 790, in urlopen
    response = self._make_request(
  File "/home/donkami/.local/lib/python3.10/site-packages/urllib3/connectionpool.py", line 496, in _make_request
    conn.request(
  File "/home/donkami/.local/lib/python3.10/site-packages/urllib3/connection.py", line 388, in request
    self.endheaders()
  File "/usr/lib/python3.10/http/client.py", line 1278, in endheaders
    self._send_output(message_body, encode_chunked=encode_chunked)
  File "/usr/lib/python3.10/http/client.py", line 1038, in _send_output
    self.send(msg)
  File "/usr/lib/python3.10/http/client.py", line 976, in send
    self.connect()
  File "/home/donkami/.local/lib/python3.10/site-packages/urllib3/connection.py", line 236, in connect
    self.sock = self._new_conn()
  File "/home/donkami/.local/lib/python3.10/site-packages/urllib3/connection.py", line 215, in _new_conn
    raise NewConnectionError(
urllib3.exceptions.NewConnectionError: <urllib3.connection.HTTPConnection object at 0x7f3f0f199fc0>: Failed to establish a new connection: [Errno 111] Connection refused

The above exception was the direct cause of the following exception:

Traceback (most recent call last):
  File "/home/donkami/.local/lib/python3.10/site-packages/requests/adapters.py", line 486, in send
    resp = conn.urlopen(
  File "/home/donkami/.local/lib/python3.10/site-packages/urllib3/connectionpool.py", line 844, in urlopen
    retries = retries.increment(
  File "/home/donkami/.local/lib/python3.10/site-packages/urllib3/util/retry.py", line 515, in increment
    raise MaxRetryError(_pool, url, reason) from reason  # type: ignore[arg-type]
urllib3.exceptions.MaxRetryError: HTTPConnectionPool(host='localhost', port=3001): Max retries exceeded with url: /api/v1/candelaria/ups (Caused by NewConnectionError('<urllib3.connection.HTTPConnection object at 0x7f3f0f199fc0>: Failed to establish a new connection: [Errno 111] Connection refused'))

During handling of the above exception, another exception occurred:

Traceback (most recent call last):
  File "/home/donkami/Sona/devnet-candelaria/Services/Devices/ups.py", line 61, in get_api_ups_data
    data_ups = requests.get(API_UPS, verify=False).json()
  File "/home/donkami/.local/lib/python3.10/site-packages/requests/api.py", line 73, in get
    return request("get", url, params=params, **kwargs)
  File "/home/donkami/.local/lib/python3.10/site-packages/requests/api.py", line 59, in request
    return session.request(method=method, url=url, **kwargs)
  File "/home/donkami/.local/lib/python3.10/site-packages/requests/sessions.py", line 589, in request
    resp = self.send(prep, **send_kwargs)
  File "/home/donkami/.local/lib/python3.10/site-packages/requests/sessions.py", line 703, in send
    r = adapter.send(request, **kwargs)
  File "/home/donkami/.local/lib/python3.10/site-packages/requests/adapters.py", line 519, in send
    raise ConnectionError(e, request=request)
requests.exceptions.ConnectionError: HTTPConnectionPool(host='localhost', port=3001): Max retries exceeded with url: /api/v1/candelaria/ups (Caused by NewConnectionError('<urllib3.connection.HTTPConnection object at 0x7f3f0f199fc0>: Failed to establish a new connection: [Errno 111] Connection refused'))

2024-09-17 17:37:30,053 - ERROR: Traceback (most recent call last):
  File "/home/donkami/.local/lib/python3.10/site-packages/urllib3/connection.py", line 200, in _new_conn
    sock = connection.create_connection(
  File "/home/donkami/.local/lib/python3.10/site-packages/urllib3/util/connection.py", line 85, in create_connection
    raise err
  File "/home/donkami/.local/lib/python3.10/site-packages/urllib3/util/connection.py", line 73, in create_connection
    sock.connect(sa)
ConnectionRefusedError: [Errno 111] Connection refused

The above exception was the direct cause of the following exception:

Traceback (most recent call last):
  File "/home/donkami/.local/lib/python3.10/site-packages/urllib3/connectionpool.py", line 790, in urlopen
    response = self._make_request(
  File "/home/donkami/.local/lib/python3.10/site-packages/urllib3/connectionpool.py", line 496, in _make_request
    conn.request(
  File "/home/donkami/.local/lib/python3.10/site-packages/urllib3/connection.py", line 388, in request
    self.endheaders()
  File "/usr/lib/python3.10/http/client.py", line 1278, in endheaders
    self._send_output(message_body, encode_chunked=encode_chunked)
  File "/usr/lib/python3.10/http/client.py", line 1038, in _send_output
    self.send(msg)
  File "/usr/lib/python3.10/http/client.py", line 976, in send
    self.connect()
  File "/home/donkami/.local/lib/python3.10/site-packages/urllib3/connection.py", line 236, in connect
    self.sock = self._new_conn()
  File "/home/donkami/.local/lib/python3.10/site-packages/urllib3/connection.py", line 215, in _new_conn
    raise NewConnectionError(
urllib3.exceptions.NewConnectionError: <urllib3.connection.HTTPConnection object at 0x7f3f0f199fc0>: Failed to establish a new connection: [Errno 111] Connection refused

The above exception was the direct cause of the following exception:

Traceback (most recent call last):
  File "/home/donkami/.local/lib/python3.10/site-packages/requests/adapters.py", line 486, in send
    resp = conn.urlopen(
  File "/home/donkami/.local/lib/python3.10/site-packages/urllib3/connectionpool.py", line 844, in urlopen
    retries = retries.increment(
  File "/home/donkami/.local/lib/python3.10/site-packages/urllib3/util/retry.py", line 515, in increment
    raise MaxRetryError(_pool, url, reason) from reason  # type: ignore[arg-type]
urllib3.exceptions.MaxRetryError: HTTPConnectionPool(host='localhost', port=3001): Max retries exceeded with url: /api/v1/candelaria/ups (Caused by NewConnectionError('<urllib3.connection.HTTPConnection object at 0x7f3f0f199fc0>: Failed to establish a new connection: [Errno 111] Connection refused'))

During handling of the above exception, another exception occurred:

Traceback (most recent call last):
  File "/home/donkami/Sona/devnet-candelaria/Services/Devices/ups.py", line 61, in get_api_ups_data
    data_ups = requests.get(API_UPS, verify=False).json()
  File "/home/donkami/.local/lib/python3.10/site-packages/requests/api.py", line 73, in get
    return request("get", url, params=params, **kwargs)
  File "/home/donkami/.local/lib/python3.10/site-packages/requests/api.py", line 59, in request
    return session.request(method=method, url=url, **kwargs)
  File "/home/donkami/.local/lib/python3.10/site-packages/requests/sessions.py", line 589, in request
    resp = self.send(prep, **send_kwargs)
  File "/home/donkami/.local/lib/python3.10/site-packages/requests/sessions.py", line 703, in send
    r = adapter.send(request, **kwargs)
  File "/home/donkami/.local/lib/python3.10/site-packages/requests/adapters.py", line 519, in send
    raise ConnectionError(e, request=request)
requests.exceptions.ConnectionError: HTTPConnectionPool(host='localhost', port=3001): Max retries exceeded with url: /api/v1/candelaria/ups (Caused by NewConnectionError('<urllib3.connection.HTTPConnection object at 0x7f3f0f199fc0>: Failed to establish a new connection: [Errno 111] Connection refused'))

2024-09-17 17:37:30,053 - ERROR - Error detallado:
2024-09-17 17:37:30,053 - ERROR: Error detallado:
2024-09-17 17:37:30,053 - ERROR - HTTPConnectionPool(host='localhost', port=3001): Max retries exceeded with url: /api/v1/candelaria/ups (Caused by NewConnectionError('<urllib3.connection.HTTPConnection object at 0x7f3f0f199fc0>: Failed to establish a new connection: [Errno 111] Connection refused'))
2024-09-17 17:37:30,053 - ERROR: HTTPConnectionPool(host='localhost', port=3001): Max retries exceeded with url: /api/v1/candelaria/ups (Caused by NewConnectionError('<urllib3.connection.HTTPConnection object at 0x7f3f0f199fc0>: Failed to establish a new connection: [Errno 111] Connection refused'))
2024-09-17 17:37:30,053 - ERROR - Hubo un error en la funcion `define_ups_status`: Error al obtener la información de la API
2024-09-17 17:37:30,053 - ERROR: Hubo un error en la funcion `define_ups_status`: Error al obtener la información de la API
2024-09-17 17:37:30,053 - ERROR - Traceback (most recent call last):
  File "/home/donkami/Sona/devnet-candelaria/Services/Devices/api_prtg.py", line 52, in get_prtg_data
    URL_PRTG_GET_ID = os.getenv("URL_PRTG_IP").format(ip=ip)
KeyError: 'username'

2024-09-17 17:37:30,053 - ERROR: Traceback (most recent call last):
  File "/home/donkami/Sona/devnet-candelaria/Services/Devices/api_prtg.py", line 52, in get_prtg_data
    URL_PRTG_GET_ID = os.getenv("URL_PRTG_IP").format(ip=ip)
KeyError: 'username'

2024-09-17 17:37:30,054 - ERROR - 'username'
2024-09-17 17:37:30,054 - ERROR: 'username'
2024-09-17 17:37:30,054 - ERROR - Error en la funcion get_prtg_data en el archivo api_prtg10.225.5.84
2024-09-17 17:37:30,054 - ERROR: Error en la funcion get_prtg_data en el archivo api_prtg10.225.5.84
2024-09-17 17:37:41,536 - ERROR - Traceback (most recent call last):
  File "/home/donkami/Sona/devnet-candelaria/Services/Devices/api_prtg.py", line 52, in get_prtg_data
    URL_PRTG_GET_ID = os.getenv("URL_PRTG_IP").format(ip=ip)
KeyError: 'username'

2024-09-17 17:37:41,536 - ERROR: Traceback (most recent call last):
  File "/home/donkami/Sona/devnet-candelaria/Services/Devices/api_prtg.py", line 52, in get_prtg_data
    URL_PRTG_GET_ID = os.getenv("URL_PRTG_IP").format(ip=ip)
KeyError: 'username'

2024-09-17 17:37:41,536 - ERROR - Traceback (most recent call last):
  File "/home/donkami/Sona/devnet-candelaria/Services/Devices/api_prtg.py", line 52, in get_prtg_data
    URL_PRTG_GET_ID = os.getenv("URL_PRTG_IP").format(ip=ip)
KeyError: 'username'

2024-09-17 17:37:41,536 - ERROR: Traceback (most recent call last):
  File "/home/donkami/Sona/devnet-candelaria/Services/Devices/api_prtg.py", line 52, in get_prtg_data
    URL_PRTG_GET_ID = os.getenv("URL_PRTG_IP").format(ip=ip)
KeyError: 'username'

2024-09-17 17:37:41,536 - ERROR - Traceback (most recent call last):
  File "/home/donkami/Sona/devnet-candelaria/Services/Devices/api_prtg.py", line 52, in get_prtg_data
    URL_PRTG_GET_ID = os.getenv("URL_PRTG_IP").format(ip=ip)
KeyError: 'username'

2024-09-17 17:37:41,536 - ERROR: Traceback (most recent call last):
  File "/home/donkami/Sona/devnet-candelaria/Services/Devices/api_prtg.py", line 52, in get_prtg_data
    URL_PRTG_GET_ID = os.getenv("URL_PRTG_IP").format(ip=ip)
KeyError: 'username'

2024-09-17 17:37:41,536 - ERROR - 'username'
2024-09-17 17:37:41,537 - ERROR - 'username'
2024-09-17 17:37:41,536 - ERROR: 'username'
2024-09-17 17:37:41,537 - ERROR - 'username'
2024-09-17 17:37:41,537 - ERROR: 'username'
2024-09-17 17:37:41,537 - ERROR - Error en la funcion get_prtg_data en el archivo api_prtg10.225.4.43
2024-09-17 17:37:41,537 - ERROR: 'username'
2024-09-17 17:37:41,537 - ERROR - Error en la funcion get_prtg_data en el archivo api_prtg10.224.21.6
2024-09-17 17:37:41,537 - ERROR: Error en la funcion get_prtg_data en el archivo api_prtg10.225.4.43
2024-09-17 17:37:41,538 - ERROR - Error en la funcion get_prtg_data en el archivo api_prtg10.231.0.97
2024-09-17 17:37:41,537 - ERROR: Error en la funcion get_prtg_data en el archivo api_prtg10.224.21.6
2024-09-17 17:37:41,538 - ERROR: Error en la funcion get_prtg_data en el archivo api_prtg10.231.0.97
2024-09-17 17:37:43,807 - ERROR - Traceback (most recent call last):
  File "/home/donkami/Sona/devnet-candelaria/Services/Devices/api_prtg.py", line 52, in get_prtg_data
    URL_PRTG_GET_ID = os.getenv("URL_PRTG_IP").format(ip=ip)
KeyError: 'username'

2024-09-17 17:37:43,807 - ERROR: Traceback (most recent call last):
  File "/home/donkami/Sona/devnet-candelaria/Services/Devices/api_prtg.py", line 52, in get_prtg_data
    URL_PRTG_GET_ID = os.getenv("URL_PRTG_IP").format(ip=ip)
KeyError: 'username'

2024-09-17 17:37:43,807 - ERROR - 'username'
2024-09-17 17:37:43,807 - ERROR: 'username'
2024-09-17 17:37:43,807 - ERROR - Error en la funcion get_prtg_data en el archivo api_prtg10.224.1.138
2024-09-17 17:37:43,807 - ERROR: Error en la funcion get_prtg_data en el archivo api_prtg10.224.1.138
2024-09-17 17:37:43,842 - ERROR - Traceback (most recent call last):
  File "/home/donkami/Sona/devnet-candelaria/Services/Devices/api_prtg.py", line 52, in get_prtg_data
    URL_PRTG_GET_ID = os.getenv("URL_PRTG_IP").format(ip=ip)
KeyError: 'username'

2024-09-17 17:37:43,842 - ERROR: Traceback (most recent call last):
  File "/home/donkami/Sona/devnet-candelaria/Services/Devices/api_prtg.py", line 52, in get_prtg_data
    URL_PRTG_GET_ID = os.getenv("URL_PRTG_IP").format(ip=ip)
KeyError: 'username'

2024-09-17 17:37:43,842 - ERROR - 'username'
2024-09-17 17:37:43,842 - ERROR: 'username'
2024-09-17 17:37:43,842 - ERROR - Error en la funcion get_prtg_data en el archivo api_prtg10.225.0.10
2024-09-17 17:37:43,842 - ERROR: Error en la funcion get_prtg_data en el archivo api_prtg10.225.0.10
2024-09-17 17:37:43,979 - ERROR - Traceback (most recent call last):
  File "/home/donkami/Sona/devnet-candelaria/Services/Devices/api_prtg.py", line 52, in get_prtg_data
    URL_PRTG_GET_ID = os.getenv("URL_PRTG_IP").format(ip=ip)
KeyError: 'username'

2024-09-17 17:37:43,979 - ERROR: Traceback (most recent call last):
  File "/home/donkami/Sona/devnet-candelaria/Services/Devices/api_prtg.py", line 52, in get_prtg_data
    URL_PRTG_GET_ID = os.getenv("URL_PRTG_IP").format(ip=ip)
KeyError: 'username'

2024-09-17 17:37:43,979 - ERROR - 'username'
2024-09-17 17:37:43,979 - ERROR: 'username'
2024-09-17 17:37:43,979 - ERROR - Error en la funcion get_prtg_data en el archivo api_prtg10.225.5.84
2024-09-17 17:37:43,979 - ERROR: Error en la funcion get_prtg_data en el archivo api_prtg10.225.5.84
2024-09-17 17:37:46,067 - ERROR - Traceback (most recent call last):
  File "/home/donkami/Sona/devnet-candelaria/Services/Devices/api_prtg.py", line 52, in get_prtg_data
    URL_PRTG_GET_ID = os.getenv("URL_PRTG_IP").format(ip=ip)
KeyError: 'username'

2024-09-17 17:37:46,067 - ERROR: Traceback (most recent call last):
  File "/home/donkami/Sona/devnet-candelaria/Services/Devices/api_prtg.py", line 52, in get_prtg_data
    URL_PRTG_GET_ID = os.getenv("URL_PRTG_IP").format(ip=ip)
KeyError: 'username'

2024-09-17 17:37:46,067 - ERROR - 'username'
2024-09-17 17:37:46,067 - ERROR: 'username'
2024-09-17 17:37:46,067 - ERROR - Error en la funcion get_prtg_data en el archivo api_prtg10.225.6.58
2024-09-17 17:37:46,067 - ERROR: Error en la funcion get_prtg_data en el archivo api_prtg10.225.6.58
2024-09-17 17:37:46,110 - ERROR - Traceback (most recent call last):
  File "/home/donkami/Sona/devnet-candelaria/Services/Devices/api_prtg.py", line 52, in get_prtg_data
    URL_PRTG_GET_ID = os.getenv("URL_PRTG_IP").format(ip=ip)
KeyError: 'username'

2024-09-17 17:37:46,110 - ERROR: Traceback (most recent call last):
  File "/home/donkami/Sona/devnet-candelaria/Services/Devices/api_prtg.py", line 52, in get_prtg_data
    URL_PRTG_GET_ID = os.getenv("URL_PRTG_IP").format(ip=ip)
KeyError: 'username'

2024-09-17 17:37:46,110 - ERROR - 'username'
2024-09-17 17:37:46,110 - ERROR: 'username'
2024-09-17 17:37:46,111 - ERROR - Error en la funcion get_prtg_data en el archivo api_prtg10.225.1.58
2024-09-17 17:37:46,111 - ERROR: Error en la funcion get_prtg_data en el archivo api_prtg10.225.1.58
2024-09-17 17:37:46,229 - ERROR - Traceback (most recent call last):
  File "/home/donkami/Sona/devnet-candelaria/Services/Devices/api_prtg.py", line 52, in get_prtg_data
    URL_PRTG_GET_ID = os.getenv("URL_PRTG_IP").format(ip=ip)
KeyError: 'username'

2024-09-17 17:37:46,229 - ERROR: Traceback (most recent call last):
  File "/home/donkami/Sona/devnet-candelaria/Services/Devices/api_prtg.py", line 52, in get_prtg_data
    URL_PRTG_GET_ID = os.getenv("URL_PRTG_IP").format(ip=ip)
KeyError: 'username'

2024-09-17 17:37:46,229 - ERROR - 'username'
2024-09-17 17:37:46,229 - ERROR: 'username'
2024-09-17 17:37:46,229 - ERROR - Error en la funcion get_prtg_data en el archivo api_prtg10.225.5.11
2024-09-17 17:37:46,229 - ERROR: Error en la funcion get_prtg_data en el archivo api_prtg10.225.5.11
2024-09-17 17:37:48,307 - ERROR - Traceback (most recent call last):
  File "/home/donkami/Sona/devnet-candelaria/Services/Devices/api_prtg.py", line 52, in get_prtg_data
    URL_PRTG_GET_ID = os.getenv("URL_PRTG_IP").format(ip=ip)
KeyError: 'username'

2024-09-17 17:37:48,307 - ERROR: Traceback (most recent call last):
  File "/home/donkami/Sona/devnet-candelaria/Services/Devices/api_prtg.py", line 52, in get_prtg_data
    URL_PRTG_GET_ID = os.getenv("URL_PRTG_IP").format(ip=ip)
KeyError: 'username'

2024-09-17 17:37:48,308 - ERROR - 'username'
2024-09-17 17:37:48,308 - ERROR: 'username'
2024-09-17 17:37:48,308 - ERROR - Error en la funcion get_prtg_data en el archivo api_prtg10.225.6.59
2024-09-17 17:37:48,308 - ERROR: Error en la funcion get_prtg_data en el archivo api_prtg10.225.6.59
2024-09-17 17:37:50,528 - ERROR - Traceback (most recent call last):
  File "/home/donkami/Sona/devnet-candelaria/Services/Devices/api_prtg.py", line 52, in get_prtg_data
    URL_PRTG_GET_ID = os.getenv("URL_PRTG_IP").format(ip=ip)
KeyError: 'username'

2024-09-17 17:37:50,528 - ERROR: Traceback (most recent call last):
  File "/home/donkami/Sona/devnet-candelaria/Services/Devices/api_prtg.py", line 52, in get_prtg_data
    URL_PRTG_GET_ID = os.getenv("URL_PRTG_IP").format(ip=ip)
KeyError: 'username'

2024-09-17 17:37:50,528 - ERROR - 'username'
2024-09-17 17:37:50,528 - ERROR: 'username'
2024-09-17 17:37:50,528 - ERROR - Error en la funcion get_prtg_data en el archivo api_prtg10.224.75.37
2024-09-17 17:37:50,528 - ERROR: Error en la funcion get_prtg_data en el archivo api_prtg10.224.75.37
2024-09-17 17:37:52,753 - ERROR - Traceback (most recent call last):
  File "/home/donkami/Sona/devnet-candelaria/Services/Devices/api_prtg.py", line 52, in get_prtg_data
    URL_PRTG_GET_ID = os.getenv("URL_PRTG_IP").format(ip=ip)
KeyError: 'username'

2024-09-17 17:37:52,753 - ERROR: Traceback (most recent call last):
  File "/home/donkami/Sona/devnet-candelaria/Services/Devices/api_prtg.py", line 52, in get_prtg_data
    URL_PRTG_GET_ID = os.getenv("URL_PRTG_IP").format(ip=ip)
KeyError: 'username'

2024-09-17 17:37:52,753 - ERROR - 'username'
2024-09-17 17:37:52,753 - ERROR: 'username'
2024-09-17 17:37:52,753 - ERROR - Error en la funcion get_prtg_data en el archivo api_prtg10.225.6.63
2024-09-17 17:37:52,753 - ERROR: Error en la funcion get_prtg_data en el archivo api_prtg10.225.6.63
2024-09-17 17:38:40,495 - ERROR - Traceback (most recent call last):
  File "/home/donkami/Sona/devnet-candelaria/Services/Devices/api_prtg.py", line 62, in get_prtg_data
    URL_PRTG_GET_DATA = os.getenv("URL_PRTG_ID").format(id_device=prtg_id)
KeyError: 'username'

2024-09-17 17:38:40,495 - ERROR: Traceback (most recent call last):
  File "/home/donkami/Sona/devnet-candelaria/Services/Devices/api_prtg.py", line 62, in get_prtg_data
    URL_PRTG_GET_DATA = os.getenv("URL_PRTG_ID").format(id_device=prtg_id)
KeyError: 'username'

2024-09-17 17:38:40,498 - ERROR - Traceback (most recent call last):
  File "/home/donkami/Sona/devnet-candelaria/Services/Devices/api_prtg.py", line 62, in get_prtg_data
    URL_PRTG_GET_DATA = os.getenv("URL_PRTG_ID").format(id_device=prtg_id)
KeyError: 'username'

2024-09-17 17:38:40,498 - ERROR: Traceback (most recent call last):
  File "/home/donkami/Sona/devnet-candelaria/Services/Devices/api_prtg.py", line 62, in get_prtg_data
    URL_PRTG_GET_DATA = os.getenv("URL_PRTG_ID").format(id_device=prtg_id)
KeyError: 'username'

2024-09-17 17:38:40,504 - ERROR - 'username'
2024-09-17 17:38:40,504 - ERROR: 'username'
2024-09-17 17:38:40,504 - ERROR - 'username'
2024-09-17 17:38:40,504 - ERROR: 'username'
2024-09-17 17:38:40,504 - ERROR - Error en la funcion get_prtg_data en el archivo api_prtg10.231.0.97
2024-09-17 17:38:40,504 - ERROR: Error en la funcion get_prtg_data en el archivo api_prtg10.231.0.97
2024-09-17 17:38:40,504 - ERROR - Error en la funcion get_prtg_data en el archivo api_prtg10.225.4.43
2024-09-17 17:38:40,504 - ERROR: Error en la funcion get_prtg_data en el archivo api_prtg10.225.4.43
2024-09-17 17:38:40,533 - ERROR - Traceback (most recent call last):
  File "/home/donkami/Sona/devnet-candelaria/Services/Devices/api_prtg.py", line 62, in get_prtg_data
    URL_PRTG_GET_DATA = os.getenv("URL_PRTG_ID").format(id_device=prtg_id)
KeyError: 'username'

2024-09-17 17:38:40,533 - ERROR: Traceback (most recent call last):
  File "/home/donkami/Sona/devnet-candelaria/Services/Devices/api_prtg.py", line 62, in get_prtg_data
    URL_PRTG_GET_DATA = os.getenv("URL_PRTG_ID").format(id_device=prtg_id)
KeyError: 'username'

2024-09-17 17:38:40,533 - ERROR - 'username'
2024-09-17 17:38:40,533 - ERROR: 'username'
2024-09-17 17:38:40,533 - ERROR - Error en la funcion get_prtg_data en el archivo api_prtg10.224.21.6
2024-09-17 17:38:40,533 - ERROR: Error en la funcion get_prtg_data en el archivo api_prtg10.224.21.6
2024-09-17 17:38:43,485 - ERROR - Traceback (most recent call last):
  File "/home/donkami/Sona/devnet-candelaria/Services/Devices/api_prtg.py", line 62, in get_prtg_data
    URL_PRTG_GET_DATA = os.getenv("URL_PRTG_ID").format(id_device=prtg_id)
KeyError: 'username'

2024-09-17 17:38:43,485 - ERROR: Traceback (most recent call last):
  File "/home/donkami/Sona/devnet-candelaria/Services/Devices/api_prtg.py", line 62, in get_prtg_data
    URL_PRTG_GET_DATA = os.getenv("URL_PRTG_ID").format(id_device=prtg_id)
KeyError: 'username'

2024-09-17 17:38:43,485 - ERROR - 'username'
2024-09-17 17:38:43,485 - ERROR: 'username'
2024-09-17 17:38:43,485 - ERROR - Error en la funcion get_prtg_data en el archivo api_prtg10.225.0.10
2024-09-17 17:38:43,485 - ERROR: Error en la funcion get_prtg_data en el archivo api_prtg10.225.0.10
2024-09-17 17:38:43,486 - ERROR - Traceback (most recent call last):
  File "/home/donkami/Sona/devnet-candelaria/Services/Devices/api_prtg.py", line 62, in get_prtg_data
    URL_PRTG_GET_DATA = os.getenv("URL_PRTG_ID").format(id_device=prtg_id)
KeyError: 'username'

2024-09-17 17:38:43,486 - ERROR: Traceback (most recent call last):
  File "/home/donkami/Sona/devnet-candelaria/Services/Devices/api_prtg.py", line 62, in get_prtg_data
    URL_PRTG_GET_DATA = os.getenv("URL_PRTG_ID").format(id_device=prtg_id)
KeyError: 'username'

2024-09-17 17:38:43,487 - ERROR - 'username'
2024-09-17 17:38:43,487 - ERROR: 'username'
2024-09-17 17:38:43,487 - ERROR - Error en la funcion get_prtg_data en el archivo api_prtg10.225.5.84
2024-09-17 17:38:43,487 - ERROR: Error en la funcion get_prtg_data en el archivo api_prtg10.225.5.84
2024-09-17 17:38:43,497 - ERROR - Traceback (most recent call last):
  File "/home/donkami/Sona/devnet-candelaria/Services/Devices/api_prtg.py", line 62, in get_prtg_data
    URL_PRTG_GET_DATA = os.getenv("URL_PRTG_ID").format(id_device=prtg_id)
KeyError: 'username'

2024-09-17 17:38:43,497 - ERROR: Traceback (most recent call last):
  File "/home/donkami/Sona/devnet-candelaria/Services/Devices/api_prtg.py", line 62, in get_prtg_data
    URL_PRTG_GET_DATA = os.getenv("URL_PRTG_ID").format(id_device=prtg_id)
KeyError: 'username'

2024-09-17 17:38:43,498 - ERROR - 'username'
2024-09-17 17:38:43,498 - ERROR: 'username'
2024-09-17 17:38:43,498 - ERROR - Error en la funcion get_prtg_data en el archivo api_prtg10.224.1.138
2024-09-17 17:38:43,498 - ERROR: Error en la funcion get_prtg_data en el archivo api_prtg10.224.1.138
2024-09-17 17:56:02,947 - ERROR - Traceback (most recent call last):
  File "/home/donkami/.local/lib/python3.10/site-packages/mysql/connector/connection_cext.py", line 291, in _open_connection
    self._cmysql.connect(**cnx_kwargs)
_mysql_connector.MySQLInterfaceError: Unknown MySQL server host 'db' (-3)

The above exception was the direct cause of the following exception:

Traceback (most recent call last):
  File "/home/donkami/Sona/devnet-candelaria/Services/FiM/db_connections.py", line 29, in devnet_connection
    db_connector = mysql.connector.connect(
  File "/home/donkami/.local/lib/python3.10/site-packages/mysql/connector/pooling.py", line 293, in connect
    return CMySQLConnection(*args, **kwargs)
  File "/home/donkami/.local/lib/python3.10/site-packages/mysql/connector/connection_cext.py", line 120, in __init__
    self.connect(**kwargs)
  File "/home/donkami/.local/lib/python3.10/site-packages/mysql/connector/abstracts.py", line 1181, in connect
    self._open_connection()
  File "/home/donkami/.local/lib/python3.10/site-packages/mysql/connector/connection_cext.py", line 296, in _open_connection
    raise get_mysql_exception(
mysql.connector.errors.DatabaseError: 2005 (HY000): Unknown MySQL server host 'db' (-3)

2024-09-17 17:56:02,947 - ERROR - Traceback (most recent call last):
  File "/home/donkami/.local/lib/python3.10/site-packages/mysql/connector/connection_cext.py", line 291, in _open_connection
    self._cmysql.connect(**cnx_kwargs)
_mysql_connector.MySQLInterfaceError: Unknown MySQL server host 'db' (-3)

The above exception was the direct cause of the following exception:

Traceback (most recent call last):
  File "/home/donkami/Sona/devnet-candelaria/Services/FiM/db_connections.py", line 29, in devnet_connection
    db_connector = mysql.connector.connect(
  File "/home/donkami/.local/lib/python3.10/site-packages/mysql/connector/pooling.py", line 293, in connect
    return CMySQLConnection(*args, **kwargs)
  File "/home/donkami/.local/lib/python3.10/site-packages/mysql/connector/connection_cext.py", line 120, in __init__
    self.connect(**kwargs)
  File "/home/donkami/.local/lib/python3.10/site-packages/mysql/connector/abstracts.py", line 1181, in connect
    self._open_connection()
  File "/home/donkami/.local/lib/python3.10/site-packages/mysql/connector/connection_cext.py", line 296, in _open_connection
    raise get_mysql_exception(
mysql.connector.errors.DatabaseError: 2005 (HY000): Unknown MySQL server host 'db' (-3)

2024-09-17 17:56:02,948 - ERROR - Error en la función `devnet_connection` en el archivo `db_connections`
2024-09-17 17:56:02,948 - ERROR - Error en la función `devnet_connection` en el archivo `db_connections`
2024-09-17 17:56:02,948 - ERROR - 2005 (HY000): Unknown MySQL server host 'db' (-3)
2024-09-17 17:56:02,948 - ERROR - 2005 (HY000): Unknown MySQL server host 'db' (-3)
2024-09-17 17:56:02,948 - ERROR - Error en la funcion principal - Base RAP11
2024-09-17 17:56:02,948 - ERROR - Error en la funcion principal - Base RAP11
2024-09-17 17:56:02,948 - ERROR - Traceback (most recent call last):
  File "/home/donkami/Sona/devnet-candelaria/Services/FiM/main.py", line 49, in check_fim
    update_status_base(base)
  File "/home/donkami/Sona/devnet-candelaria/Services/FiM/save_register.py", line 35, in update_status_base
    cursor = mydb.cursor()
AttributeError: 'NoneType' object has no attribute 'cursor'

2024-09-17 17:56:02,948 - ERROR - Traceback (most recent call last):
  File "/home/donkami/Sona/devnet-candelaria/Services/FiM/main.py", line 49, in check_fim
    update_status_base(base)
  File "/home/donkami/Sona/devnet-candelaria/Services/FiM/save_register.py", line 35, in update_status_base
    cursor = mydb.cursor()
AttributeError: 'NoneType' object has no attribute 'cursor'

2024-09-17 17:56:02,948 - ERROR - 'NoneType' object has no attribute 'cursor'
2024-09-17 17:56:02,948 - ERROR - 'NoneType' object has no attribute 'cursor'
2024-09-17 17:56:12,959 - ERROR - Traceback (most recent call last):
  File "/home/donkami/Sona/devnet-candelaria/Services/FiM/main.py", line 49, in check_fim
    update_status_base(base)
  File "/home/donkami/Sona/devnet-candelaria/Services/FiM/save_register.py", line 35, in update_status_base
    cursor = mydb.cursor()
AttributeError: 'NoneType' object has no attribute 'cursor'

During handling of the above exception, another exception occurred:

Traceback (most recent call last):
  File "/home/donkami/.local/lib/python3.10/site-packages/mysql/connector/connection_cext.py", line 291, in _open_connection
    self._cmysql.connect(**cnx_kwargs)
_mysql_connector.MySQLInterfaceError: Unknown MySQL server host 'db' (-3)

The above exception was the direct cause of the following exception:

Traceback (most recent call last):
  File "/home/donkami/Sona/devnet-candelaria/Services/FiM/db_connections.py", line 29, in devnet_connection
    db_connector = mysql.connector.connect(
  File "/home/donkami/.local/lib/python3.10/site-packages/mysql/connector/pooling.py", line 293, in connect
    return CMySQLConnection(*args, **kwargs)
  File "/home/donkami/.local/lib/python3.10/site-packages/mysql/connector/connection_cext.py", line 120, in __init__
    self.connect(**kwargs)
  File "/home/donkami/.local/lib/python3.10/site-packages/mysql/connector/abstracts.py", line 1181, in connect
    self._open_connection()
  File "/home/donkami/.local/lib/python3.10/site-packages/mysql/connector/connection_cext.py", line 296, in _open_connection
    raise get_mysql_exception(
mysql.connector.errors.DatabaseError: 2005 (HY000): Unknown MySQL server host 'db' (-3)

2024-09-17 17:56:12,959 - ERROR - Traceback (most recent call last):
  File "/home/donkami/Sona/devnet-candelaria/Services/FiM/main.py", line 49, in check_fim
    update_status_base(base)
  File "/home/donkami/Sona/devnet-candelaria/Services/FiM/save_register.py", line 35, in update_status_base
    cursor = mydb.cursor()
AttributeError: 'NoneType' object has no attribute 'cursor'

During handling of the above exception, another exception occurred:

Traceback (most recent call last):
  File "/home/donkami/.local/lib/python3.10/site-packages/mysql/connector/connection_cext.py", line 291, in _open_connection
    self._cmysql.connect(**cnx_kwargs)
_mysql_connector.MySQLInterfaceError: Unknown MySQL server host 'db' (-3)

The above exception was the direct cause of the following exception:

Traceback (most recent call last):
  File "/home/donkami/Sona/devnet-candelaria/Services/FiM/db_connections.py", line 29, in devnet_connection
    db_connector = mysql.connector.connect(
  File "/home/donkami/.local/lib/python3.10/site-packages/mysql/connector/pooling.py", line 293, in connect
    return CMySQLConnection(*args, **kwargs)
  File "/home/donkami/.local/lib/python3.10/site-packages/mysql/connector/connection_cext.py", line 120, in __init__
    self.connect(**kwargs)
  File "/home/donkami/.local/lib/python3.10/site-packages/mysql/connector/abstracts.py", line 1181, in connect
    self._open_connection()
  File "/home/donkami/.local/lib/python3.10/site-packages/mysql/connector/connection_cext.py", line 296, in _open_connection
    raise get_mysql_exception(
mysql.connector.errors.DatabaseError: 2005 (HY000): Unknown MySQL server host 'db' (-3)

2024-09-17 17:56:12,959 - ERROR - Error en la función `devnet_connection` en el archivo `db_connections`
2024-09-17 17:56:12,959 - ERROR - Error en la función `devnet_connection` en el archivo `db_connections`
2024-09-17 17:56:12,959 - ERROR - 2005 (HY000): Unknown MySQL server host 'db' (-3)
2024-09-17 17:56:12,959 - ERROR - 2005 (HY000): Unknown MySQL server host 'db' (-3)
2024-09-17 17:56:12,960 - ERROR - Traceback (most recent call last):
  File "/home/donkami/Sona/devnet-candelaria/Services/FiM/main.py", line 49, in check_fim
    update_status_base(base)
  File "/home/donkami/Sona/devnet-candelaria/Services/FiM/save_register.py", line 35, in update_status_base
    cursor = mydb.cursor()
AttributeError: 'NoneType' object has no attribute 'cursor'

During handling of the above exception, another exception occurred:

Traceback (most recent call last):
  File "/home/donkami/Sona/devnet-candelaria/Services/FiM/db_update_devnet.py", line 46, in datetime_register
    devnet_cursor = db_connector.cursor()
AttributeError: 'NoneType' object has no attribute 'cursor'

2024-09-17 17:56:12,960 - ERROR - Traceback (most recent call last):
  File "/home/donkami/Sona/devnet-candelaria/Services/FiM/main.py", line 49, in check_fim
    update_status_base(base)
  File "/home/donkami/Sona/devnet-candelaria/Services/FiM/save_register.py", line 35, in update_status_base
    cursor = mydb.cursor()
AttributeError: 'NoneType' object has no attribute 'cursor'

During handling of the above exception, another exception occurred:

Traceback (most recent call last):
  File "/home/donkami/Sona/devnet-candelaria/Services/FiM/db_update_devnet.py", line 46, in datetime_register
    devnet_cursor = db_connector.cursor()
AttributeError: 'NoneType' object has no attribute 'cursor'

2024-09-17 17:56:12,960 - ERROR - Error en la función `datetime_register` en el archivo `db_update_devnet`
2024-09-17 17:56:12,960 - ERROR - Error en la función `datetime_register` en el archivo `db_update_devnet`
2024-09-17 17:56:12,960 - ERROR - 'NoneType' object has no attribute 'cursor'
2024-09-17 17:56:12,960 - ERROR - 'NoneType' object has no attribute 'cursor'
2024-09-17 18:38:20,098 - ERROR - Traceback (most recent call last):
  File "/home/donkami/.local/lib/python3.10/site-packages/mysql/connector/connection_cext.py", line 611, in cmd_query
    self._cmysql.query(
_mysql_connector.MySQLInterfaceError: Incorrect integer value: '' for column 'clave' at row 1

The above exception was the direct cause of the following exception:

Traceback (most recent call last):
  File "/home/donkami/Sona/devnet-candelaria/Services/Switches/db_insert_historic.py", line 98, in save_historic_data
    historic_cursor.executemany(insert_query, data_tuple)
  File "/home/donkami/.local/lib/python3.10/site-packages/mysql/connector/cursor_cext.py", line 455, in executemany
    return self.execute(stmt)
  File "/home/donkami/.local/lib/python3.10/site-packages/mysql/connector/cursor_cext.py", line 330, in execute
    result = self._cnx.cmd_query(
  File "/home/donkami/.local/lib/python3.10/site-packages/mysql/connector/connection_cext.py", line 619, in cmd_query
    raise get_mysql_exception(
mysql.connector.errors.DatabaseError: 1366 (HY000): Incorrect integer value: '' for column 'clave' at row 1

2024-09-17 18:38:20,098 - ERROR - Error en la función `save_historic_data` en el archivo `db_insert_historic`
2024-09-17 18:38:20,098 - ERROR - 1366 (HY000): Incorrect integer value: '' for column 'clave' at row 1
2024-09-17 18:41:14,434 - ERROR - Traceback (most recent call last):
  File "/home/donkami/.local/lib/python3.10/site-packages/mysql/connector/connection_cext.py", line 611, in cmd_query
    self._cmysql.query(
_mysql_connector.MySQLInterfaceError: Table 'historic-devnet.candelaria_switches' doesn't exist

The above exception was the direct cause of the following exception:

Traceback (most recent call last):
  File "/home/donkami/Sona/devnet-candelaria/Services/Switches/db_insert_historic.py", line 89, in save_historic_data
    historic_cursor.execute(delete_query, (twelve_months_ago_str,))
  File "/home/donkami/.local/lib/python3.10/site-packages/mysql/connector/cursor_cext.py", line 330, in execute
    result = self._cnx.cmd_query(
  File "/home/donkami/.local/lib/python3.10/site-packages/mysql/connector/connection_cext.py", line 619, in cmd_query
    raise get_mysql_exception(
mysql.connector.errors.ProgrammingError: 1146 (42S02): Table 'historic-devnet.candelaria_switches' doesn't exist

2024-09-17 18:41:14,435 - ERROR - Error en la función `save_historic_data` en el archivo `db_insert_historic`
2024-09-17 18:41:14,435 - ERROR - 1146 (42S02): Table 'historic-devnet.candelaria_switches' doesn't exist
