2023-07-12 11:35:48,077 - ERROR: Error Controladora Device 10.117.115.111
2023-07-12 11:35:48,077 - ERROR: Error Controladora Device 10.117.115.111
2023-07-12 11:35:48,078 - ERROR: Traceback (most recent call last):
  File "/home/donkami/Sona/SistemaDCS/DCS-Candelaria/Services/Mesh/controladora.py", line 38, in get_data_controladora
    output = net_connect.send_command("sh wireless client mac-address " + data_pala.split()[0] + " detail")
IndexError: list index out of range

2023-07-12 11:35:48,078 - ERROR: Traceback (most recent call last):
  File "/home/donkami/Sona/SistemaDCS/DCS-Candelaria/Services/Mesh/controladora.py", line 38, in get_data_controladora
    output = net_connect.send_command("sh wireless client mac-address " + data_pala.split()[0] + " detail")
IndexError: list index out of range

2023-07-12 11:36:25,624 - ERROR: Error Controladora Device 10.117.115.180
2023-07-12 11:36:25,624 - ERROR: Error Controladora Device 10.117.115.180
2023-07-12 11:36:25,624 - ERROR: Traceback (most recent call last):
  File "/home/donkami/Sona/SistemaDCS/DCS-Candelaria/Services/Mesh/controladora.py", line 38, in get_data_controladora
    output = net_connect.send_command("sh wireless client mac-address " + data_pala.split()[0] + " detail")
IndexError: list index out of range

2023-07-12 11:36:25,624 - ERROR: Traceback (most recent call last):
  File "/home/donkami/Sona/SistemaDCS/DCS-Candelaria/Services/Mesh/controladora.py", line 38, in get_data_controladora
    output = net_connect.send_command("sh wireless client mac-address " + data_pala.split()[0] + " detail")
IndexError: list index out of range

2023-07-12 11:37:06,204 - ERROR: Error Controladora Device 10.117.115.121
2023-07-12 11:37:06,204 - ERROR: Error Controladora Device 10.117.115.121
2023-07-12 11:37:06,204 - ERROR: Traceback (most recent call last):
  File "/home/donkami/Sona/SistemaDCS/DCS-Candelaria/Services/Mesh/controladora.py", line 35, in get_data_controladora
    data_pala = net_connect.send_command(f"sh wireless client summary detail ipv4 | inc {device_ip}") #! Ip Pala
  File "/home/donkami/Sona/SistemaDCS/DCS-Candelaria/Services/Mesh/venv/lib/python3.10/site-packages/netmiko/utilities.py", line 592, in wrapper_decorator
    return func(self, *args, **kwargs)
  File "/home/donkami/Sona/SistemaDCS/DCS-Candelaria/Services/Mesh/venv/lib/python3.10/site-packages/netmiko/base_connection.py", line 1721, in send_command
    raise ReadTimeout(msg)
netmiko.exceptions.ReadTimeout: 
Pattern not detected: 'WLC\\-9800\\-MESH\\-CD>' in output.

Things you might try to fix this:
1. Explicitly set your pattern using the expect_string argument.
2. Increase the read_timeout to a larger value.

You can also look at the Netmiko session_log or debug log for more information.



2023-07-12 11:37:06,204 - ERROR: Traceback (most recent call last):
  File "/home/donkami/Sona/SistemaDCS/DCS-Candelaria/Services/Mesh/controladora.py", line 35, in get_data_controladora
    data_pala = net_connect.send_command(f"sh wireless client summary detail ipv4 | inc {device_ip}") #! Ip Pala
  File "/home/donkami/Sona/SistemaDCS/DCS-Candelaria/Services/Mesh/venv/lib/python3.10/site-packages/netmiko/utilities.py", line 592, in wrapper_decorator
    return func(self, *args, **kwargs)
  File "/home/donkami/Sona/SistemaDCS/DCS-Candelaria/Services/Mesh/venv/lib/python3.10/site-packages/netmiko/base_connection.py", line 1721, in send_command
    raise ReadTimeout(msg)
netmiko.exceptions.ReadTimeout: 
Pattern not detected: 'WLC\\-9800\\-MESH\\-CD>' in output.

Things you might try to fix this:
1. Explicitly set your pattern using the expect_string argument.
2. Increase the read_timeout to a larger value.

You can also look at the Netmiko session_log or debug log for more information.



2023-07-12 11:37:24,239 - ERROR: Error Controladora Device 10.117.115.122
2023-07-12 11:37:24,239 - ERROR: Error Controladora Device 10.117.115.122
2023-07-12 11:37:24,239 - ERROR: Traceback (most recent call last):
  File "/home/donkami/Sona/SistemaDCS/DCS-Candelaria/Services/Mesh/controladora.py", line 35, in get_data_controladora
    data_pala = net_connect.send_command(f"sh wireless client summary detail ipv4 | inc {device_ip}") #! Ip Pala
  File "/home/donkami/Sona/SistemaDCS/DCS-Candelaria/Services/Mesh/venv/lib/python3.10/site-packages/netmiko/utilities.py", line 592, in wrapper_decorator
    return func(self, *args, **kwargs)
  File "/home/donkami/Sona/SistemaDCS/DCS-Candelaria/Services/Mesh/venv/lib/python3.10/site-packages/netmiko/base_connection.py", line 1721, in send_command
    raise ReadTimeout(msg)
netmiko.exceptions.ReadTimeout: 
Pattern not detected: 'WLC\\-9800\\-MESH\\-CD>' in output.

Things you might try to fix this:
1. Explicitly set your pattern using the expect_string argument.
2. Increase the read_timeout to a larger value.

You can also look at the Netmiko session_log or debug log for more information.



2023-07-12 11:37:24,239 - ERROR: Traceback (most recent call last):
  File "/home/donkami/Sona/SistemaDCS/DCS-Candelaria/Services/Mesh/controladora.py", line 35, in get_data_controladora
    data_pala = net_connect.send_command(f"sh wireless client summary detail ipv4 | inc {device_ip}") #! Ip Pala
  File "/home/donkami/Sona/SistemaDCS/DCS-Candelaria/Services/Mesh/venv/lib/python3.10/site-packages/netmiko/utilities.py", line 592, in wrapper_decorator
    return func(self, *args, **kwargs)
  File "/home/donkami/Sona/SistemaDCS/DCS-Candelaria/Services/Mesh/venv/lib/python3.10/site-packages/netmiko/base_connection.py", line 1721, in send_command
    raise ReadTimeout(msg)
netmiko.exceptions.ReadTimeout: 
Pattern not detected: 'WLC\\-9800\\-MESH\\-CD>' in output.

Things you might try to fix this:
1. Explicitly set your pattern using the expect_string argument.
2. Increase the read_timeout to a larger value.

You can also look at the Netmiko session_log or debug log for more information.



2023-07-12 11:37:42,276 - ERROR: Error Controladora Device 10.117.115.182
2023-07-12 11:37:42,276 - ERROR: Error Controladora Device 10.117.115.182
2023-07-12 11:37:42,276 - ERROR: Traceback (most recent call last):
  File "/home/donkami/Sona/SistemaDCS/DCS-Candelaria/Services/Mesh/controladora.py", line 35, in get_data_controladora
    data_pala = net_connect.send_command(f"sh wireless client summary detail ipv4 | inc {device_ip}") #! Ip Pala
  File "/home/donkami/Sona/SistemaDCS/DCS-Candelaria/Services/Mesh/venv/lib/python3.10/site-packages/netmiko/utilities.py", line 592, in wrapper_decorator
    return func(self, *args, **kwargs)
  File "/home/donkami/Sona/SistemaDCS/DCS-Candelaria/Services/Mesh/venv/lib/python3.10/site-packages/netmiko/base_connection.py", line 1721, in send_command
    raise ReadTimeout(msg)
netmiko.exceptions.ReadTimeout: 
Pattern not detected: 'WLC\\-9800\\-MESH\\-CD>' in output.

Things you might try to fix this:
1. Explicitly set your pattern using the expect_string argument.
2. Increase the read_timeout to a larger value.

You can also look at the Netmiko session_log or debug log for more information.



2023-07-12 11:37:42,276 - ERROR: Traceback (most recent call last):
  File "/home/donkami/Sona/SistemaDCS/DCS-Candelaria/Services/Mesh/controladora.py", line 35, in get_data_controladora
    data_pala = net_connect.send_command(f"sh wireless client summary detail ipv4 | inc {device_ip}") #! Ip Pala
  File "/home/donkami/Sona/SistemaDCS/DCS-Candelaria/Services/Mesh/venv/lib/python3.10/site-packages/netmiko/utilities.py", line 592, in wrapper_decorator
    return func(self, *args, **kwargs)
  File "/home/donkami/Sona/SistemaDCS/DCS-Candelaria/Services/Mesh/venv/lib/python3.10/site-packages/netmiko/base_connection.py", line 1721, in send_command
    raise ReadTimeout(msg)
netmiko.exceptions.ReadTimeout: 
Pattern not detected: 'WLC\\-9800\\-MESH\\-CD>' in output.

Things you might try to fix this:
1. Explicitly set your pattern using the expect_string argument.
2. Increase the read_timeout to a larger value.

You can also look at the Netmiko session_log or debug log for more information.



2023-07-12 11:38:00,321 - ERROR: Error Controladora Device 10.117.115.183
2023-07-12 11:38:00,321 - ERROR: Error Controladora Device 10.117.115.183
2023-07-12 11:38:00,321 - ERROR: Traceback (most recent call last):
  File "/home/donkami/Sona/SistemaDCS/DCS-Candelaria/Services/Mesh/controladora.py", line 35, in get_data_controladora
    data_pala = net_connect.send_command(f"sh wireless client summary detail ipv4 | inc {device_ip}") #! Ip Pala
  File "/home/donkami/Sona/SistemaDCS/DCS-Candelaria/Services/Mesh/venv/lib/python3.10/site-packages/netmiko/utilities.py", line 592, in wrapper_decorator
    return func(self, *args, **kwargs)
  File "/home/donkami/Sona/SistemaDCS/DCS-Candelaria/Services/Mesh/venv/lib/python3.10/site-packages/netmiko/base_connection.py", line 1721, in send_command
    raise ReadTimeout(msg)
netmiko.exceptions.ReadTimeout: 
Pattern not detected: 'WLC\\-9800\\-MESH\\-CD>' in output.

Things you might try to fix this:
1. Explicitly set your pattern using the expect_string argument.
2. Increase the read_timeout to a larger value.

You can also look at the Netmiko session_log or debug log for more information.



2023-07-12 11:38:00,321 - ERROR: Traceback (most recent call last):
  File "/home/donkami/Sona/SistemaDCS/DCS-Candelaria/Services/Mesh/controladora.py", line 35, in get_data_controladora
    data_pala = net_connect.send_command(f"sh wireless client summary detail ipv4 | inc {device_ip}") #! Ip Pala
  File "/home/donkami/Sona/SistemaDCS/DCS-Candelaria/Services/Mesh/venv/lib/python3.10/site-packages/netmiko/utilities.py", line 592, in wrapper_decorator
    return func(self, *args, **kwargs)
  File "/home/donkami/Sona/SistemaDCS/DCS-Candelaria/Services/Mesh/venv/lib/python3.10/site-packages/netmiko/base_connection.py", line 1721, in send_command
    raise ReadTimeout(msg)
netmiko.exceptions.ReadTimeout: 
Pattern not detected: 'WLC\\-9800\\-MESH\\-CD>' in output.

Things you might try to fix this:
1. Explicitly set your pattern using the expect_string argument.
2. Increase the read_timeout to a larger value.

You can also look at the Netmiko session_log or debug log for more information.



2023-07-12 11:38:18,540 - ERROR: Error Controladora Device 10.117.115.184
2023-07-12 11:38:18,540 - ERROR: Error Controladora Device 10.117.115.184
2023-07-12 11:38:18,540 - ERROR: Traceback (most recent call last):
  File "/home/donkami/Sona/SistemaDCS/DCS-Candelaria/Services/Mesh/controladora.py", line 35, in get_data_controladora
    data_pala = net_connect.send_command(f"sh wireless client summary detail ipv4 | inc {device_ip}") #! Ip Pala
  File "/home/donkami/Sona/SistemaDCS/DCS-Candelaria/Services/Mesh/venv/lib/python3.10/site-packages/netmiko/utilities.py", line 592, in wrapper_decorator
    return func(self, *args, **kwargs)
  File "/home/donkami/Sona/SistemaDCS/DCS-Candelaria/Services/Mesh/venv/lib/python3.10/site-packages/netmiko/base_connection.py", line 1721, in send_command
    raise ReadTimeout(msg)
netmiko.exceptions.ReadTimeout: 
Pattern not detected: 'WLC\\-9800\\-MESH\\-CD>' in output.

Things you might try to fix this:
1. Explicitly set your pattern using the expect_string argument.
2. Increase the read_timeout to a larger value.

You can also look at the Netmiko session_log or debug log for more information.



2023-07-12 11:38:18,540 - ERROR: Traceback (most recent call last):
  File "/home/donkami/Sona/SistemaDCS/DCS-Candelaria/Services/Mesh/controladora.py", line 35, in get_data_controladora
    data_pala = net_connect.send_command(f"sh wireless client summary detail ipv4 | inc {device_ip}") #! Ip Pala
  File "/home/donkami/Sona/SistemaDCS/DCS-Candelaria/Services/Mesh/venv/lib/python3.10/site-packages/netmiko/utilities.py", line 592, in wrapper_decorator
    return func(self, *args, **kwargs)
  File "/home/donkami/Sona/SistemaDCS/DCS-Candelaria/Services/Mesh/venv/lib/python3.10/site-packages/netmiko/base_connection.py", line 1721, in send_command
    raise ReadTimeout(msg)
netmiko.exceptions.ReadTimeout: 
Pattern not detected: 'WLC\\-9800\\-MESH\\-CD>' in output.

Things you might try to fix this:
1. Explicitly set your pattern using the expect_string argument.
2. Increase the read_timeout to a larger value.

You can also look at the Netmiko session_log or debug log for more information.



2023-07-12 11:39:37,600 - ERROR: Error Controladora Device 10.117.115.110
2023-07-12 11:39:37,600 - ERROR: Error Controladora Device 10.117.115.110
2023-07-12 11:39:37,601 - ERROR: Traceback (most recent call last):
  File "/home/donkami/Sona/SistemaDCS/DCS-Candelaria/Services/Mesh/controladora.py", line 35, in get_data_controladora
    data_pala = net_connect.send_command(f"sh wireless client summary detail ipv4 | inc {device_ip}") #! Ip Pala
  File "/home/donkami/Sona/SistemaDCS/DCS-Candelaria/Services/Mesh/venv/lib/python3.10/site-packages/netmiko/utilities.py", line 592, in wrapper_decorator
    return func(self, *args, **kwargs)
  File "/home/donkami/Sona/SistemaDCS/DCS-Candelaria/Services/Mesh/venv/lib/python3.10/site-packages/netmiko/base_connection.py", line 1721, in send_command
    raise ReadTimeout(msg)
netmiko.exceptions.ReadTimeout: 
Pattern not detected: 'WLC\\-9800\\-MESH\\-CD>' in output.

Things you might try to fix this:
1. Explicitly set your pattern using the expect_string argument.
2. Increase the read_timeout to a larger value.

You can also look at the Netmiko session_log or debug log for more information.



2023-07-12 11:39:37,601 - ERROR: Traceback (most recent call last):
  File "/home/donkami/Sona/SistemaDCS/DCS-Candelaria/Services/Mesh/controladora.py", line 35, in get_data_controladora
    data_pala = net_connect.send_command(f"sh wireless client summary detail ipv4 | inc {device_ip}") #! Ip Pala
  File "/home/donkami/Sona/SistemaDCS/DCS-Candelaria/Services/Mesh/venv/lib/python3.10/site-packages/netmiko/utilities.py", line 592, in wrapper_decorator
    return func(self, *args, **kwargs)
  File "/home/donkami/Sona/SistemaDCS/DCS-Candelaria/Services/Mesh/venv/lib/python3.10/site-packages/netmiko/base_connection.py", line 1721, in send_command
    raise ReadTimeout(msg)
netmiko.exceptions.ReadTimeout: 
Pattern not detected: 'WLC\\-9800\\-MESH\\-CD>' in output.

Things you might try to fix this:
1. Explicitly set your pattern using the expect_string argument.
2. Increase the read_timeout to a larger value.

You can also look at the Netmiko session_log or debug log for more information.



2023-07-12 11:39:57,026 - ERROR: Error Controladora Device 10.117.115.111
2023-07-12 11:39:57,026 - ERROR: Error Controladora Device 10.117.115.111
2023-07-12 11:39:57,026 - ERROR: Traceback (most recent call last):
  File "/home/donkami/Sona/SistemaDCS/DCS-Candelaria/Services/Mesh/controladora.py", line 35, in get_data_controladora
    data_pala = net_connect.send_command(f"sh wireless client summary detail ipv4 | inc {device_ip}") #! Ip Pala
  File "/home/donkami/Sona/SistemaDCS/DCS-Candelaria/Services/Mesh/venv/lib/python3.10/site-packages/netmiko/utilities.py", line 592, in wrapper_decorator
    return func(self, *args, **kwargs)
  File "/home/donkami/Sona/SistemaDCS/DCS-Candelaria/Services/Mesh/venv/lib/python3.10/site-packages/netmiko/base_connection.py", line 1721, in send_command
    raise ReadTimeout(msg)
netmiko.exceptions.ReadTimeout: 
Pattern not detected: 'WLC\\-9800\\-MESH\\-CD>' in output.

Things you might try to fix this:
1. Explicitly set your pattern using the expect_string argument.
2. Increase the read_timeout to a larger value.

You can also look at the Netmiko session_log or debug log for more information.



2023-07-12 11:39:57,026 - ERROR: Traceback (most recent call last):
  File "/home/donkami/Sona/SistemaDCS/DCS-Candelaria/Services/Mesh/controladora.py", line 35, in get_data_controladora
    data_pala = net_connect.send_command(f"sh wireless client summary detail ipv4 | inc {device_ip}") #! Ip Pala
  File "/home/donkami/Sona/SistemaDCS/DCS-Candelaria/Services/Mesh/venv/lib/python3.10/site-packages/netmiko/utilities.py", line 592, in wrapper_decorator
    return func(self, *args, **kwargs)
  File "/home/donkami/Sona/SistemaDCS/DCS-Candelaria/Services/Mesh/venv/lib/python3.10/site-packages/netmiko/base_connection.py", line 1721, in send_command
    raise ReadTimeout(msg)
netmiko.exceptions.ReadTimeout: 
Pattern not detected: 'WLC\\-9800\\-MESH\\-CD>' in output.

Things you might try to fix this:
1. Explicitly set your pattern using the expect_string argument.
2. Increase the read_timeout to a larger value.

You can also look at the Netmiko session_log or debug log for more information.



2023-07-12 11:40:34,776 - ERROR: Error Controladora Device 10.117.115.180
2023-07-12 11:40:34,776 - ERROR: Error Controladora Device 10.117.115.180
2023-07-12 11:40:34,776 - ERROR: Traceback (most recent call last):
  File "/home/donkami/Sona/SistemaDCS/DCS-Candelaria/Services/Mesh/controladora.py", line 38, in get_data_controladora
    output = net_connect.send_command("sh wireless client mac-address " + data_pala.split()[0] + " detail")
IndexError: list index out of range

2023-07-12 11:40:34,776 - ERROR: Traceback (most recent call last):
  File "/home/donkami/Sona/SistemaDCS/DCS-Candelaria/Services/Mesh/controladora.py", line 38, in get_data_controladora
    output = net_connect.send_command("sh wireless client mac-address " + data_pala.split()[0] + " detail")
IndexError: list index out of range

2023-07-12 11:41:55,979 - ERROR: Error Controladora Device 10.117.115.182
2023-07-12 11:41:55,979 - ERROR: Error Controladora Device 10.117.115.182
2023-07-12 11:41:55,979 - ERROR: Traceback (most recent call last):
  File "/home/donkami/Sona/SistemaDCS/DCS-Candelaria/Services/Mesh/controladora.py", line 38, in get_data_controladora
    output = net_connect.send_command("sh wireless client mac-address " + data_pala.split()[0] + " detail")
IndexError: list index out of range

2023-07-12 11:41:55,979 - ERROR: Traceback (most recent call last):
  File "/home/donkami/Sona/SistemaDCS/DCS-Candelaria/Services/Mesh/controladora.py", line 38, in get_data_controladora
    output = net_connect.send_command("sh wireless client mac-address " + data_pala.split()[0] + " detail")
IndexError: list index out of range

2023-07-12 11:42:11,778 - ERROR: Error Controladora Device 10.117.115.183
2023-07-12 11:42:11,778 - ERROR: Error Controladora Device 10.117.115.183
2023-07-12 11:42:11,778 - ERROR: Traceback (most recent call last):
  File "/home/donkami/Sona/SistemaDCS/DCS-Candelaria/Services/Mesh/controladora.py", line 38, in get_data_controladora
    output = net_connect.send_command("sh wireless client mac-address " + data_pala.split()[0] + " detail")
IndexError: list index out of range

2023-07-12 11:42:11,778 - ERROR: Traceback (most recent call last):
  File "/home/donkami/Sona/SistemaDCS/DCS-Candelaria/Services/Mesh/controladora.py", line 38, in get_data_controladora
    output = net_connect.send_command("sh wireless client mac-address " + data_pala.split()[0] + " detail")
IndexError: list index out of range

2025-04-21 13:31:31,698 - ERROR - Traceback (most recent call last):
  File "/home/donkami/.local/lib/python3.10/site-packages/urllib3/connection.py", line 200, in _new_conn
    sock = connection.create_connection(
  File "/home/donkami/.local/lib/python3.10/site-packages/urllib3/util/connection.py", line 85, in create_connection
    raise err
  File "/home/donkami/.local/lib/python3.10/site-packages/urllib3/util/connection.py", line 73, in create_connection
    sock.connect(sa)
ConnectionRefusedError: [Errno 111] Connection refused

The above exception was the direct cause of the following exception:

Traceback (most recent call last):
  File "/home/donkami/.local/lib/python3.10/site-packages/urllib3/connectionpool.py", line 790, in urlopen
    response = self._make_request(
  File "/home/donkami/.local/lib/python3.10/site-packages/urllib3/connectionpool.py", line 496, in _make_request
    conn.request(
  File "/home/donkami/.local/lib/python3.10/site-packages/urllib3/connection.py", line 388, in request
    self.endheaders()
  File "/usr/lib/python3.10/http/client.py", line 1278, in endheaders
    self._send_output(message_body, encode_chunked=encode_chunked)
  File "/usr/lib/python3.10/http/client.py", line 1038, in _send_output
    self.send(msg)
  File "/usr/lib/python3.10/http/client.py", line 976, in send
    self.connect()
  File "/home/donkami/.local/lib/python3.10/site-packages/urllib3/connection.py", line 236, in connect
    self.sock = self._new_conn()
  File "/home/donkami/.local/lib/python3.10/site-packages/urllib3/connection.py", line 215, in _new_conn
    raise NewConnectionError(
urllib3.exceptions.NewConnectionError: <urllib3.connection.HTTPConnection object at 0x7f772e208220>: Failed to establish a new connection: [Errno 111] Connection refused

The above exception was the direct cause of the following exception:

Traceback (most recent call last):
  File "/home/donkami/.local/lib/python3.10/site-packages/requests/adapters.py", line 486, in send
    resp = conn.urlopen(
  File "/home/donkami/.local/lib/python3.10/site-packages/urllib3/connectionpool.py", line 844, in urlopen
    retries = retries.increment(
  File "/home/donkami/.local/lib/python3.10/site-packages/urllib3/util/retry.py", line 515, in increment
    raise MaxRetryError(_pool, url, reason) from reason  # type: ignore[arg-type]
urllib3.exceptions.MaxRetryError: HTTPConnectionPool(host='localhost', port=3001): Max retries exceeded with url: /api/v1/candelaria/mesh (Caused by NewConnectionError('<urllib3.connection.HTTPConnection object at 0x7f772e208220>: Failed to establish a new connection: [Errno 111] Connection refused'))

During handling of the above exception, another exception occurred:

Traceback (most recent call last):
  File "/home/donkami/Sona/devnet-candelaria/Services/Mesh_Process/status_prtg.py", line 34, in status_prtg
    response_api_candelaria = requests.get(
  File "/home/donkami/.local/lib/python3.10/site-packages/requests/api.py", line 73, in get
    return request("get", url, params=params, **kwargs)
  File "/home/donkami/.local/lib/python3.10/site-packages/requests/api.py", line 59, in request
    return session.request(method=method, url=url, **kwargs)
  File "/home/donkami/.local/lib/python3.10/site-packages/requests/sessions.py", line 589, in request
    resp = self.send(prep, **send_kwargs)
  File "/home/donkami/.local/lib/python3.10/site-packages/requests/sessions.py", line 703, in send
    r = adapter.send(request, **kwargs)
  File "/home/donkami/.local/lib/python3.10/site-packages/requests/adapters.py", line 519, in send
    raise ConnectionError(e, request=request)
requests.exceptions.ConnectionError: HTTPConnectionPool(host='localhost', port=3001): Max retries exceeded with url: /api/v1/candelaria/mesh (Caused by NewConnectionError('<urllib3.connection.HTTPConnection object at 0x7f772e208220>: Failed to establish a new connection: [Errno 111] Connection refused'))

2025-04-21 13:31:31,698 - ERROR: Traceback (most recent call last):
  File "/home/donkami/.local/lib/python3.10/site-packages/urllib3/connection.py", line 200, in _new_conn
    sock = connection.create_connection(
  File "/home/donkami/.local/lib/python3.10/site-packages/urllib3/util/connection.py", line 85, in create_connection
    raise err
  File "/home/donkami/.local/lib/python3.10/site-packages/urllib3/util/connection.py", line 73, in create_connection
    sock.connect(sa)
ConnectionRefusedError: [Errno 111] Connection refused

The above exception was the direct cause of the following exception:

Traceback (most recent call last):
  File "/home/donkami/.local/lib/python3.10/site-packages/urllib3/connectionpool.py", line 790, in urlopen
    response = self._make_request(
  File "/home/donkami/.local/lib/python3.10/site-packages/urllib3/connectionpool.py", line 496, in _make_request
    conn.request(
  File "/home/donkami/.local/lib/python3.10/site-packages/urllib3/connection.py", line 388, in request
    self.endheaders()
  File "/usr/lib/python3.10/http/client.py", line 1278, in endheaders
    self._send_output(message_body, encode_chunked=encode_chunked)
  File "/usr/lib/python3.10/http/client.py", line 1038, in _send_output
    self.send(msg)
  File "/usr/lib/python3.10/http/client.py", line 976, in send
    self.connect()
  File "/home/donkami/.local/lib/python3.10/site-packages/urllib3/connection.py", line 236, in connect
    self.sock = self._new_conn()
  File "/home/donkami/.local/lib/python3.10/site-packages/urllib3/connection.py", line 215, in _new_conn
    raise NewConnectionError(
urllib3.exceptions.NewConnectionError: <urllib3.connection.HTTPConnection object at 0x7f772e208220>: Failed to establish a new connection: [Errno 111] Connection refused

The above exception was the direct cause of the following exception:

Traceback (most recent call last):
  File "/home/donkami/.local/lib/python3.10/site-packages/requests/adapters.py", line 486, in send
    resp = conn.urlopen(
  File "/home/donkami/.local/lib/python3.10/site-packages/urllib3/connectionpool.py", line 844, in urlopen
    retries = retries.increment(
  File "/home/donkami/.local/lib/python3.10/site-packages/urllib3/util/retry.py", line 515, in increment
    raise MaxRetryError(_pool, url, reason) from reason  # type: ignore[arg-type]
urllib3.exceptions.MaxRetryError: HTTPConnectionPool(host='localhost', port=3001): Max retries exceeded with url: /api/v1/candelaria/mesh (Caused by NewConnectionError('<urllib3.connection.HTTPConnection object at 0x7f772e208220>: Failed to establish a new connection: [Errno 111] Connection refused'))

During handling of the above exception, another exception occurred:

Traceback (most recent call last):
  File "/home/donkami/Sona/devnet-candelaria/Services/Mesh_Process/status_prtg.py", line 34, in status_prtg
    response_api_candelaria = requests.get(
  File "/home/donkami/.local/lib/python3.10/site-packages/requests/api.py", line 73, in get
    return request("get", url, params=params, **kwargs)
  File "/home/donkami/.local/lib/python3.10/site-packages/requests/api.py", line 59, in request
    return session.request(method=method, url=url, **kwargs)
  File "/home/donkami/.local/lib/python3.10/site-packages/requests/sessions.py", line 589, in request
    resp = self.send(prep, **send_kwargs)
  File "/home/donkami/.local/lib/python3.10/site-packages/requests/sessions.py", line 703, in send
    r = adapter.send(request, **kwargs)
  File "/home/donkami/.local/lib/python3.10/site-packages/requests/adapters.py", line 519, in send
    raise ConnectionError(e, request=request)
requests.exceptions.ConnectionError: HTTPConnectionPool(host='localhost', port=3001): Max retries exceeded with url: /api/v1/candelaria/mesh (Caused by NewConnectionError('<urllib3.connection.HTTPConnection object at 0x7f772e208220>: Failed to establish a new connection: [Errno 111] Connection refused'))

2025-04-21 13:31:31,698 - ERROR - HTTPConnectionPool(host='localhost', port=3001): Max retries exceeded with url: /api/v1/candelaria/mesh (Caused by NewConnectionError('<urllib3.connection.HTTPConnection object at 0x7f772e208220>: Failed to establish a new connection: [Errno 111] Connection refused'))
2025-04-21 13:31:31,698 - ERROR: HTTPConnectionPool(host='localhost', port=3001): Max retries exceeded with url: /api/v1/candelaria/mesh (Caused by NewConnectionError('<urllib3.connection.HTTPConnection object at 0x7f772e208220>: Failed to establish a new connection: [Errno 111] Connection refused'))
2025-04-21 13:31:31,698 - ERROR - Error en la funcion `status_prtg` en el archivo `status_prtg`
2025-04-21 13:31:31,698 - ERROR: Error en la funcion `status_prtg` en el archivo `status_prtg`
