2024-08-26 18:42:09,679 - ERROR - Traceback (most recent call last):
  File "/home/donkami/Sona/devnet-candelaria/Services/Ups/uptime.py", line 26, in get_uptime
    uptime_url = os.getenv('URL_UPTIME_UPS').format(id_ping=id_ping, sdate=sdate, edate=edate)
KeyError: 'username'

2024-08-26 18:42:09,679 - ERROR - Error en la función `get_uptime` en el archivo `uptime`
2024-08-26 18:42:09,679 - ERROR - 'username'
2024-08-26 18:42:11,280 - ERROR - Traceback (most recent call last):
  File "/home/donkami/Sona/devnet-candelaria/Services/Ups/uptime.py", line 26, in get_uptime
    uptime_url = os.getenv('URL_UPTIME_UPS').format(id_ping=id_ping, sdate=sdate, edate=edate)
KeyError: 'username'

2024-08-26 18:42:11,280 - ERROR - Error en la función `get_uptime` en el archivo `uptime`
2024-08-26 18:42:11,280 - ERROR - 'username'
2024-08-26 18:42:13,072 - ERROR - Traceback (most recent call last):
  File "/home/donkami/Sona/devnet-candelaria/Services/Ups/uptime.py", line 26, in get_uptime
    uptime_url = os.getenv('URL_UPTIME_UPS').format(id_ping=id_ping, sdate=sdate, edate=edate)
KeyError: 'username'

2024-08-26 18:42:13,072 - ERROR - Error en la función `get_uptime` en el archivo `uptime`
2024-08-26 18:42:13,072 - ERROR - 'username'
2024-08-26 19:24:11,632 - ERROR - 'sensor'
2024-08-26 19:24:11,633 - ERROR - Traceback (most recent call last):
  File "/home/donkami/Sona/devnet-candelaria/Services/Dcs_Candelaria/api_prtg.py", line 48, in get_prtg_data
    if prtg_response['sensor'] == []:
KeyError: 'sensor'

2024-08-26 19:24:11,633 - ERROR - Error en la funcion `get_prtg_id` del archivo `main`
2024-08-26 19:25:07,688 - ERROR - 'sensor'
2024-08-26 19:25:07,688 - ERROR - Traceback (most recent call last):
  File "/home/donkami/Sona/devnet-candelaria/Services/Dcs_Candelaria/api_prtg.py", line 48, in get_prtg_data
    if prtg_response['sensor'] == []:
KeyError: 'sensor'

2024-08-26 19:25:07,688 - ERROR - Error con el Cliente 10.10.10.1
2024-08-26 19:25:07,688 - ERROR - Error en la funcion `get_prtg_id` del archivo `main`
2024-08-26 19:28:56,079 - ERROR - 'sensor'
2024-08-26 19:28:56,079 - ERROR - Traceback (most recent call last):
  File "/home/donkami/Sona/devnet-candelaria/Services/Dcs_Candelaria/api_prtg.py", line 48, in get_prtg_data
    if prtg_response['sensor'] == []:
KeyError: 'sensor'

2024-08-26 19:28:56,079 - ERROR - Error con el Cliente 10.10.10.1
2024-08-26 19:28:56,079 - ERROR - Error en la funcion `get_prtg_id` del archivo `main`
2024-08-26 19:29:47,030 - ERROR - Expecting value: line 1 column 1 (char 0)
2024-08-26 19:29:47,039 - ERROR - Traceback (most recent call last):
  File "/home/donkami/.local/lib/python3.10/site-packages/requests/models.py", line 971, in json
    return complexjson.loads(self.text, **kwargs)
  File "/usr/lib/python3.10/json/__init__.py", line 346, in loads
    return _default_decoder.decode(s)
  File "/usr/lib/python3.10/json/decoder.py", line 337, in decode
    obj, end = self.raw_decode(s, idx=_w(s, 0).end())
  File "/usr/lib/python3.10/json/decoder.py", line 355, in raw_decode
    raise JSONDecodeError("Expecting value", s, err.value) from None
json.decoder.JSONDecodeError: Expecting value: line 1 column 1 (char 0)

During handling of the above exception, another exception occurred:

Traceback (most recent call last):
  File "/home/donkami/Sona/devnet-candelaria/Services/Dcs_Candelaria/api_prtg.py", line 46, in get_prtg_data
    prtg_response = requests.get(url_prtg_id, verify=False).json()
  File "/home/donkami/.local/lib/python3.10/site-packages/requests/models.py", line 975, in json
    raise RequestsJSONDecodeError(e.msg, e.doc, e.pos)
requests.exceptions.JSONDecodeError: Expecting value: line 1 column 1 (char 0)

2024-08-26 19:29:47,039 - ERROR - Error con el Cliente 10.10.10.1
2024-08-26 19:29:47,039 - ERROR - Error en la funcion `get_prtg_id` del archivo `main`
2024-08-26 19:30:00,635 - ERROR - Expecting value: line 1 column 1 (char 0)
2024-08-26 19:30:00,636 - ERROR - Traceback (most recent call last):
  File "/home/donkami/.local/lib/python3.10/site-packages/requests/models.py", line 971, in json
    return complexjson.loads(self.text, **kwargs)
  File "/usr/lib/python3.10/json/__init__.py", line 346, in loads
    return _default_decoder.decode(s)
  File "/usr/lib/python3.10/json/decoder.py", line 337, in decode
    obj, end = self.raw_decode(s, idx=_w(s, 0).end())
  File "/usr/lib/python3.10/json/decoder.py", line 355, in raw_decode
    raise JSONDecodeError("Expecting value", s, err.value) from None
json.decoder.JSONDecodeError: Expecting value: line 1 column 1 (char 0)

During handling of the above exception, another exception occurred:

Traceback (most recent call last):
  File "/home/donkami/Sona/devnet-candelaria/Services/Dcs_Candelaria/api_prtg.py", line 46, in get_prtg_data
    prtg_response = requests.get(url_prtg_id, verify=False).json()
  File "/home/donkami/.local/lib/python3.10/site-packages/requests/models.py", line 975, in json
    raise RequestsJSONDecodeError(e.msg, e.doc, e.pos)
requests.exceptions.JSONDecodeError: Expecting value: line 1 column 1 (char 0)

2024-08-26 19:30:00,636 - ERROR - Error con el Cliente 10.10.10.1
2024-08-26 19:30:00,636 - ERROR - Error en la funcion `get_prtg_id` del archivo `main`
2024-08-26 19:30:21,143 - ERROR - Expecting value: line 1 column 1 (char 0)
2024-08-26 19:30:21,144 - ERROR - Traceback (most recent call last):
  File "/home/donkami/.local/lib/python3.10/site-packages/requests/models.py", line 971, in json
    return complexjson.loads(self.text, **kwargs)
  File "/usr/lib/python3.10/json/__init__.py", line 346, in loads
    return _default_decoder.decode(s)
  File "/usr/lib/python3.10/json/decoder.py", line 337, in decode
    obj, end = self.raw_decode(s, idx=_w(s, 0).end())
  File "/usr/lib/python3.10/json/decoder.py", line 355, in raw_decode
    raise JSONDecodeError("Expecting value", s, err.value) from None
json.decoder.JSONDecodeError: Expecting value: line 1 column 1 (char 0)

During handling of the above exception, another exception occurred:

Traceback (most recent call last):
  File "/home/donkami/Sona/devnet-candelaria/Services/Dcs_Candelaria/api_prtg.py", line 46, in get_prtg_data
    prtg_response = requests.get(url_prtg_id, verify=False).json()
  File "/home/donkami/.local/lib/python3.10/site-packages/requests/models.py", line 975, in json
    raise RequestsJSONDecodeError(e.msg, e.doc, e.pos)
requests.exceptions.JSONDecodeError: Expecting value: line 1 column 1 (char 0)

2024-08-26 19:30:21,144 - ERROR - Error con el Cliente 10.10.10.1
2024-08-26 19:30:21,144 - ERROR - Error en la funcion `get_prtg_id` del archivo `main`
2024-08-26 19:31:16,994 - ERROR - Expecting value: line 1 column 1 (char 0)
2024-08-26 19:31:16,995 - ERROR - Traceback (most recent call last):
  File "/home/donkami/.local/lib/python3.10/site-packages/requests/models.py", line 971, in json
    return complexjson.loads(self.text, **kwargs)
  File "/usr/lib/python3.10/json/__init__.py", line 346, in loads
    return _default_decoder.decode(s)
  File "/usr/lib/python3.10/json/decoder.py", line 337, in decode
    obj, end = self.raw_decode(s, idx=_w(s, 0).end())
  File "/usr/lib/python3.10/json/decoder.py", line 355, in raw_decode
    raise JSONDecodeError("Expecting value", s, err.value) from None
json.decoder.JSONDecodeError: Expecting value: line 1 column 1 (char 0)

During handling of the above exception, another exception occurred:

Traceback (most recent call last):
  File "/home/donkami/Sona/devnet-candelaria/Services/Dcs_Candelaria/api_prtg.py", line 46, in get_prtg_data
    prtg_response = requests.get(url_prtg_id, verify=False).json()
  File "/home/donkami/.local/lib/python3.10/site-packages/requests/models.py", line 975, in json
    raise RequestsJSONDecodeError(e.msg, e.doc, e.pos)
requests.exceptions.JSONDecodeError: Expecting value: line 1 column 1 (char 0)

2024-08-26 19:31:16,995 - ERROR - Error con el Cliente 10.10.10.1
2024-08-26 19:31:16,995 - ERROR - Error en la funcion `get_prtg_id` del archivo `main`
2024-08-26 22:14:23,615 - ERROR - 'queryResponse'
2024-08-26 22:14:23,625 - ERROR - Traceback (most recent call last):
  File "/home/donkami/Sona/devnet-candelaria/Services/Dcs_Candelaria/api_cisco.py", line 19, in get_cisco_id
    if cisco_response['queryResponse'] and cisco_response['queryResponse']['@count'] == 0:
KeyError: 'queryResponse'

2024-08-26 22:14:23,625 - ERROR - Error con el Cliente 10.225.196.299
2024-08-26 22:14:23,625 - ERROR - Error en la funcion `get_cisco_id` del archivo `api_cisco`
2024-08-26 22:15:21,321 - ERROR - 'queryResponse'
2024-08-26 22:15:21,322 - ERROR - Traceback (most recent call last):
  File "/home/donkami/Sona/devnet-candelaria/Services/Dcs_Candelaria/api_cisco.py", line 19, in get_cisco_id
    if cisco_response['queryResponse'] and cisco_response['queryResponse']['@count'] == 0:
KeyError: 'queryResponse'

2024-08-26 22:15:21,322 - ERROR - Error con el Cliente 10.225.196.299
2024-08-26 22:15:21,322 - ERROR - Error en la funcion `get_cisco_id` del archivo `api_cisco`
2024-08-26 22:15:34,481 - ERROR - 'queryResponse'
2024-08-26 22:15:34,481 - ERROR - Traceback (most recent call last):
  File "/home/donkami/Sona/devnet-candelaria/Services/Dcs_Candelaria/api_cisco.py", line 19, in get_cisco_id
    if cisco_response['queryResponse'] and cisco_response['queryResponse']['@count'] == 0:
KeyError: 'queryResponse'

2024-08-26 22:15:34,481 - ERROR - Error con el Cliente 10.225.196.299
2024-08-26 22:15:34,481 - ERROR - Error en la funcion `get_cisco_id` del archivo `api_cisco`
2024-08-26 22:16:09,707 - ERROR - 'queryResponse'
2024-08-26 22:16:09,708 - ERROR - Traceback (most recent call last):
  File "/home/donkami/Sona/devnet-candelaria/Services/Dcs_Candelaria/api_cisco.py", line 19, in get_cisco_id
    if cisco_response['queryResponse'] and cisco_response['queryResponse']['@count'] == 0:
KeyError: 'queryResponse'

2024-08-26 22:16:09,708 - ERROR - Error con el Cliente 10.225.196.299
2024-08-26 22:16:09,708 - ERROR - Error en la funcion `get_cisco_id` del archivo `api_cisco`
2024-08-26 22:16:25,722 - ERROR - 'queryResponse'
2024-08-26 22:16:25,722 - ERROR - Traceback (most recent call last):
  File "/home/donkami/Sona/devnet-candelaria/Services/Dcs_Candelaria/api_cisco.py", line 19, in get_cisco_id
    if cisco_response['queryResponse'] and cisco_response['queryResponse']['@count'] == 0:
KeyError: 'queryResponse'

2024-08-26 22:16:25,723 - ERROR - Error con el Cliente 10.225.196.299
2024-08-26 22:16:25,723 - ERROR - Error en la funcion `get_cisco_id` del archivo `api_cisco`
2024-08-26 22:32:47,821 - ERROR - 1064 (42000): You have an error in your SQL syntax; check the manual that corresponds to your MySQL server version for the right syntax to use near '-devnet.candelaria_clients
                WHERE ip = '10.225.196.21' AND 
     ' at line 1
2024-08-26 22:32:47,822 - ERROR - Traceback (most recent call last):
  File "/home/donkami/.local/lib/python3.10/site-packages/mysql/connector/connection_cext.py", line 611, in cmd_query
    self._cmysql.query(
_mysql_connector.MySQLInterfaceError: You have an error in your SQL syntax; check the manual that corresponds to your MySQL server version for the right syntax to use near '-devnet.candelaria_clients
                WHERE ip = '10.225.196.21' AND 
     ' at line 1

The above exception was the direct cause of the following exception:

Traceback (most recent call last):
  File "/home/donkami/Sona/devnet-candelaria/Services/Dcs_Candelaria/db_get_data.py", line 58, in get_historic_cisco_data
    historic_db_cursor.execute(query)
  File "/home/donkami/.local/lib/python3.10/site-packages/mysql/connector/cursor_cext.py", line 330, in execute
    result = self._cnx.cmd_query(
  File "/home/donkami/.local/lib/python3.10/site-packages/mysql/connector/connection_cext.py", line 619, in cmd_query
    raise get_mysql_exception(
mysql.connector.errors.ProgrammingError: 1064 (42000): You have an error in your SQL syntax; check the manual that corresponds to your MySQL server version for the right syntax to use near '-devnet.candelaria_clients
                WHERE ip = '10.225.196.21' AND 
     ' at line 1

2024-08-26 22:32:47,822 - ERROR - Error con el Cliente 10.225.196.21
2024-08-26 22:32:47,822 - ERROR - Error en la funcion `get_historic_cisco_data` del archivo `db_get_data`
2024-08-26 22:44:48,344 - ERROR - Expecting value: line 1 column 1 (char 0)
2024-08-26 22:44:56,373 - ERROR - Expecting value: line 1 column 1 (char 0)
2024-08-26 22:44:56,383 - ERROR - Traceback (most recent call last):
  File "/home/donkami/.local/lib/python3.10/site-packages/requests/models.py", line 971, in json
    return complexjson.loads(self.text, **kwargs)
  File "/usr/lib/python3.10/json/__init__.py", line 346, in loads
    return _default_decoder.decode(s)
  File "/usr/lib/python3.10/json/decoder.py", line 337, in decode
    obj, end = self.raw_decode(s, idx=_w(s, 0).end())
  File "/usr/lib/python3.10/json/decoder.py", line 355, in raw_decode
    raise JSONDecodeError("Expecting value", s, err.value) from None
json.decoder.JSONDecodeError: Expecting value: line 1 column 1 (char 0)

During handling of the above exception, another exception occurred:

Traceback (most recent call last):
  File "/home/donkami/Sona/devnet-candelaria/Services/Dcs_Candelaria/api_cisco.py", line 53, in get_cisco_data
    cisco_client_response = requests.get(url_cisco_id, verify=False).json()
  File "/home/donkami/.local/lib/python3.10/site-packages/requests/models.py", line 975, in json
    raise RequestsJSONDecodeError(e.msg, e.doc, e.pos)
requests.exceptions.JSONDecodeError: Expecting value: line 1 column 1 (char 0)

2024-08-26 22:47:15,765 - ERROR - Expecting value: line 1 column 1 (char 0)
2024-08-26 22:47:15,766 - ERROR - Traceback (most recent call last):
  File "/home/donkami/.local/lib/python3.10/site-packages/requests/models.py", line 971, in json
    return complexjson.loads(self.text, **kwargs)
  File "/usr/lib/python3.10/json/__init__.py", line 346, in loads
    return _default_decoder.decode(s)
  File "/usr/lib/python3.10/json/decoder.py", line 337, in decode
    obj, end = self.raw_decode(s, idx=_w(s, 0).end())
  File "/usr/lib/python3.10/json/decoder.py", line 355, in raw_decode
    raise JSONDecodeError("Expecting value", s, err.value) from None
json.decoder.JSONDecodeError: Expecting value: line 1 column 1 (char 0)

During handling of the above exception, another exception occurred:

Traceback (most recent call last):
  File "/home/donkami/Sona/devnet-candelaria/Services/Dcs_Candelaria/api_cisco.py", line 78, in get_cisco_data
    cisco_client_response = requests.get(url_cisco_id, verify=False).json()
  File "/home/donkami/.local/lib/python3.10/site-packages/requests/models.py", line 975, in json
    raise RequestsJSONDecodeError(e.msg, e.doc, e.pos)
requests.exceptions.JSONDecodeError: Expecting value: line 1 column 1 (char 0)

2024-08-26 22:47:29,235 - ERROR - Expecting value: line 1 column 1 (char 0)
2024-08-26 22:47:29,235 - ERROR - Traceback (most recent call last):
  File "/home/donkami/.local/lib/python3.10/site-packages/requests/models.py", line 971, in json
    return complexjson.loads(self.text, **kwargs)
  File "/usr/lib/python3.10/json/__init__.py", line 346, in loads
    return _default_decoder.decode(s)
  File "/usr/lib/python3.10/json/decoder.py", line 337, in decode
    obj, end = self.raw_decode(s, idx=_w(s, 0).end())
  File "/usr/lib/python3.10/json/decoder.py", line 355, in raw_decode
    raise JSONDecodeError("Expecting value", s, err.value) from None
json.decoder.JSONDecodeError: Expecting value: line 1 column 1 (char 0)

During handling of the above exception, another exception occurred:

Traceback (most recent call last):
  File "/home/donkami/Sona/devnet-candelaria/Services/Dcs_Candelaria/api_cisco.py", line 78, in get_cisco_data
    cisco_client_response = requests.get(url_cisco_id, verify=False).json()
  File "/home/donkami/.local/lib/python3.10/site-packages/requests/models.py", line 975, in json
    raise RequestsJSONDecodeError(e.msg, e.doc, e.pos)
requests.exceptions.JSONDecodeError: Expecting value: line 1 column 1 (char 0)

2024-08-26 22:57:13,897 - ERROR - 'username'
2024-08-26 22:57:13,906 - ERROR - Traceback (most recent call last):
  File "/home/donkami/Sona/devnet-candelaria/Services/Dcs_Candelaria/api_cisco.py", line 91, in get_cisco_data
    prtg_device_id_url = os.getenv('URL_PRTG_ID').format(id_device=prtg_device_id)
KeyError: 'username'

2024-08-27 01:04:27,825 - ERROR - Traceback (most recent call last):
  File "/home/donkami/Sona/devnet-candelaria/Services/Dcs_Candelaria/main.py", line 42, in main
    save_historic_data(client)
  File "/home/donkami/Sona/devnet-candelaria/Services/Dcs_Candelaria/db_insert_historic.py", line 40, in save_historic_data
    data_tuple = [
  File "/home/donkami/Sona/devnet-candelaria/Services/Dcs_Candelaria/db_insert_historic.py", line 42, in <listcomp>
    client.get('name', ''),
AttributeError: 'str' object has no attribute 'get'

2024-08-27 01:05:57,093 - ERROR - Traceback (most recent call last):
  File "/home/donkami/Sona/devnet-candelaria/Services/Dcs_Candelaria/db_update_devnet.py", line 48, in update_devnet_data
    devnet_cursor.executemany(query, data_tuple)
  File "/home/donkami/.local/lib/python3.10/site-packages/mysql/connector/cursor_cext.py", line 465, in executemany
    self.execute(operation, params)
  File "/home/donkami/.local/lib/python3.10/site-packages/mysql/connector/cursor_cext.py", line 323, in execute
    stmt = RE_PY_PARAM.sub(psub, stmt)
  File "/home/donkami/.local/lib/python3.10/site-packages/mysql/connector/cursor_cext.py", line 112, in __call__
    raise ProgrammingError(
mysql.connector.errors.ProgrammingError: Not enough parameters for the SQL statement

2024-08-27 01:05:57,094 - ERROR - Error en la función `update_devnet_data` en el archivo `db_update_devnet`
2024-08-27 01:05:57,094 - ERROR - Not enough parameters for the SQL statement
2024-08-27 01:07:28,136 - ERROR - Traceback (most recent call last):
  File "/home/donkami/Sona/devnet-candelaria/Services/Dcs_Candelaria/db_update_devnet.py", line 48, in update_devnet_data
    devnet_cursor.executemany(query, data_tuple)
  File "/home/donkami/.local/lib/python3.10/site-packages/mysql/connector/cursor_cext.py", line 465, in executemany
    self.execute(operation, params)
  File "/home/donkami/.local/lib/python3.10/site-packages/mysql/connector/cursor_cext.py", line 323, in execute
    stmt = RE_PY_PARAM.sub(psub, stmt)
  File "/home/donkami/.local/lib/python3.10/site-packages/mysql/connector/cursor_cext.py", line 112, in __call__
    raise ProgrammingError(
mysql.connector.errors.ProgrammingError: Not enough parameters for the SQL statement

2024-08-27 01:07:28,136 - ERROR - Error en la función `update_devnet_data` en el archivo `db_update_devnet`
2024-08-27 01:07:28,136 - ERROR - Not enough parameters for the SQL statement
2024-08-27 01:17:41,958 - ERROR - 'id_prtg'
2024-08-27 01:17:41,958 - ERROR - Traceback (most recent call last):
  File "/home/donkami/Sona/devnet-candelaria/Services/Dcs_Candelaria/api_prtg.py", line 38, in get_prtg_data
    if client["id_prtg"] == 'Error PRTG' or client["id_prtg"] == 'Not Found':
KeyError: 'id_prtg'

2024-08-27 01:17:41,959 - ERROR - Error con el Cliente 10.225.196.21, 'id_prtg': 15091
2024-08-27 01:17:41,959 - ERROR - Error en la funcion `get_prtg_data` del archivo `main`
2024-08-27 12:25:20,216 - ERROR - Traceback (most recent call last):
  File "/home/donkami/Sona/devnet-candelaria/Services/Dcs_Candelaria/main.py", line 51, in main
    update_devnet_data(clients_updated)
  File "/home/donkami/Sona/devnet-candelaria/Services/Dcs_Candelaria/db_update_devnet.py", line 25, in update_devnet_data
    data_tuple = [
  File "/home/donkami/Sona/devnet-candelaria/Services/Dcs_Candelaria/db_update_devnet.py", line 30, in <listcomp>
    client["cisco_device_ip_adrress"],
KeyError: 'cisco_device_ip_adrress'

2024-08-27 12:38:59,757 - ERROR - Traceback (most recent call last):
  File "/home/donkami/Sona/devnet-candelaria/Services/Dcs_Candelaria/main.py", line 52, in main
    datetime_register(status="ERROR")
TypeError: datetime_register() missing 1 required positional argument: 'table_name'

2024-08-27 12:38:59,767 - ERROR - Traceback (most recent call last):
  File "/home/donkami/Sona/devnet-candelaria/Services/Dcs_Candelaria/main.py", line 52, in main
    datetime_register(status="ERROR")
TypeError: datetime_register() missing 1 required positional argument: 'table_name'

During handling of the above exception, another exception occurred:

Traceback (most recent call last):
  File "/home/donkami/.local/lib/python3.10/site-packages/mysql/connector/connection_cext.py", line 611, in cmd_query
    self._cmysql.query(
_mysql_connector.MySQLInterfaceError: Unknown column 'candelaria_clients' in 'where clause'

The above exception was the direct cause of the following exception:

Traceback (most recent call last):
  File "/home/donkami/Sona/devnet-candelaria/Services/Dcs_Candelaria/db_update_devnet.py", line 102, in datetime_register
    devnet_cursor.execute(query)
  File "/home/donkami/.local/lib/python3.10/site-packages/mysql/connector/cursor_cext.py", line 330, in execute
    result = self._cnx.cmd_query(
  File "/home/donkami/.local/lib/python3.10/site-packages/mysql/connector/connection_cext.py", line 619, in cmd_query
    raise get_mysql_exception(
mysql.connector.errors.ProgrammingError: 1054 (42S22): Unknown column 'candelaria_clients' in 'where clause'

2024-08-27 12:38:59,768 - ERROR - Error en la función `datetime_register` en el archivo `db_update_devnet`
2024-08-27 12:38:59,768 - ERROR - 1054 (42S22): Unknown column 'candelaria_clients' in 'where clause'
2024-08-27 12:40:32,955 - ERROR - Traceback (most recent call last):
  File "/home/donkami/Sona/devnet-candelaria/Services/Dcs_Candelaria/main.py", line 52, in main
    datetime_register(status="ERROR")
TypeError: datetime_register() missing 1 required positional argument: 'table_name'

2024-08-27 12:40:56,721 - ERROR - Traceback (most recent call last):
  File "/home/donkami/Sona/devnet-candelaria/Services/Dcs_Candelaria/main.py", line 52, in main
    datetime_register(status="ERROR")
TypeError: datetime_register() missing 1 required positional argument: 'system_name'

2024-08-27 13:04:52,371 - ERROR - Traceback (most recent call last):
  File "/home/donkami/Sona/devnet-candelaria/Services/Dcs_Candelaria/main.py", line 52, in main
    datetime_register(status="ERROR")
TypeError: datetime_register() missing 1 required positional argument: 'system_name'

